Workbook

Sheet Ordre de passage
A1: Grille d'évaluation - "Améliorer l’efficacité de sa TPE à l’aide de l’IA" - RS7311
D3: Nom et prénom des évaluateurs | F3: Monsieur Anthony Malheiro (Président du jury)
F4: Monsieur Romain Picano Palombo (Formateur/évaluateur certificateur)
D5: Date du Jury | F5: 46036
A7: Renseigner selon l'ordre de passage, ainsi le nom et prénom est renseigné dans chaque feuille
A9: Remplir les cellules jaunes ainsi que les deux cellules grises ci-dessus (évaluateur et date)
A10: NB | B10: Heure de passage | C10: Prénom | D10: NOM | E10: Certification Acquise | F10: Commentaires évaluateur 1
A11: 1 | E11: ='Participant 1'!E30 | F11: ='Participant 1'!C35
A12: 2 | E12: ='Participant 2'!E30 | F12: ='Participant 2'!C35
A13: 3 | E13: ='Participant 3'!E30 | F13: ='Participant 3'!C35
A14: 4 | E14: ='Participant 4'!E30 | F14: ='Participant 4'!C35
A15: 5 | E15: ='Participant 5'!E30 | F15: ='Participant 5'!C35
A16: 6 | E16: ='Participant 6'!E30 | F16: ='Participant 6'!C35
A17: 7 | E17: ='Participant 7'!E30 | F17: ='Participant 7'!C35
A18: 8 | E18: ='Participant 8'!E30 | F18: ='Participant 8'!C35
A19: 9 | E19: ='Participant 9'!E30 | F19: ='Participant 9'!C35
A20: 10 | E20: ='Participant 10'!E30 | F20: ='Participant 10'!C35
A21: 11 | E21: ='Participant 11'!E30 | F21: ='Participant 11'!C35
A22: 12 | E22: ='Participant 12'!E30 | F22: ='Participant 12'!C35
A23: 13 | E23: ='Participant 13'!E30 | F23: ='Participant 13'!C35
A24: 14 | E24: ='Participant 14'!E30 | F24: ='Participant 14'!C35
A25: 15 | E25: ='Participant 15'!E30 | F25: ='Participant 15'!C35

Sheet Règles de validation
A1: Règles de validation de la Certification
A3: L’acquisition de l’ensemble des compétences est requise pour valider la certification.
A4: Pour qu’une compétence soit considérée comme acquise, le candidat devra avoir validé au minimum 50 % des critères d’évaluation associés à cette compétence.
A6: La certification ne pourra être délivrée que si toutes les compétences ont été validées individuellement.

Sheet Participant 1
A1: Grille d'évaluation
A2: Améliorer l’efficacité de sa TPE à l’aide de l’IA
A3: Prénom du candidat: | C3: ='Ordre de passage'!C11 | D3: Date de l'oral : | E3: ='Ordre de passage'!F5
A4: Nom du candidat : | C4: ='Ordre de passage'!D11 | D4: Important : Commentaire obligatoire pour les critères et/ou compétences que le candidat ne valide pas
A5: Heure du passage : | C5: ='Ordre de passage'!B11
A6: Compétence évaluée | D6: Note /5 | E6: Compétence acquise | F6: Commentaires
A7: C1. Identifier les opportunités d'application de l'intelligence artificielle au sein de sa TPE, en listant les cas d’usage dans les pratiques de l’organisation en fonction des fonctionnalités et limites des principaux outils IA adaptés, en anticipant les adaptations possibles pour les utilisateurs en situation de handicap, et en prenant en compte le cadre éthique et réglementaire de l’IA, du RGPD et le développement durable, afin d'optimiser les processus et la gestion de la structure. | D7: =D8/5 | E7: =IF(D8>=2.5,"oui","non") | F7: =IF(D7<50%,"Commentaire obligatoire"," ")
A8: Note compétence (0 non acquis --> 5 acquis) | D8: =SUM(D9:D12)/4
A9: Cr1.1. Les opportunités d’application de l’IA identifiées par le candidat permettent d’optimiser les processus et la gestion de sa TPE. Le candidat justifie les différentes optimisations concrètes attendues au regard des capacités, fonctionnalités et limites des technologies IA identifiées.
A10: Cr1.2. Le candidat détaille et justifie les adaptations réalisables dans l’utilisation et/ou le paramétrage des outils IA identifiés pour les utilisateurs en situation de handicap. Par exemple commande vocale, transcription audio des productions textuelles ou visuelles générées par l’IA, prompts intégrant des instructions de structuration ou de langage adapté…
A11: Cr1.3. Le candidat explicite les éléments du cadre éthique et réglementaire en vigueur de l’IA et du RGPD à prendre en compte dans les applications de l’IA identifiées pour sa TPE.
A12: Cr1.4. Le candidat explicite les principaux impacts négatifs de l’IA sur le développement durable (énergie, eau, matériaux rares, émissions) et formule au minimum 2 bonnes pratiques, réalistes et réalisables dans sa TPE, pour un usage responsable et durable.
A13: C2. Générer des contenus diversifiés avec l’IA (articles, visuels, vidéos, supports interactifs, emails…), en appliquant les techniques de prompt engineering (formulation, structuration, itérations) et en exploitant les outils spécifiques d’IA générative, et en intégrant des adaptations ou fonctionnalités d’accessibilité pour les publics en situation de handicap, afin d’améliorer l’efficacité de sa communication interne et externe. | D13: =D14/5 | E13: =IF(D14>=2.5,"oui","non") | F13: =IF(D13<50%,"Commentaire obligatoire"," ")
A14: Note compétence (0 non acquis --> 5 acquis) | D14: =SUM(D15:D18)/4
A15: Cr2.1. Les contenus présentés par le candidat sont diversifiés (articles, visuels, vidéos, supports interactifs, emails…), et générés avec au minimum un outil spécifique d’IA générative : le candidat le justifie en présentant les prompts qu’il a rédigés.
A16: Cr2.2. Le candidat justifie en quoi les contenus ainsi produits permettent d’améliorer l’efficacité de sa communication externe et interne (gain de temps de production, qualité de la production, visuel libre de droit…).
A17: Cr2.3. Les prompts rédigés par le candidat démontrent une application des techniques de prompt engineering : formulation et structuration des requêtes avec les arbres de pensée et la chaîne de raisonnement, amélioration progressive.
A18: Cr2.4. Au moins un des contenus produits par le candidat avec l’IA intègre une ou plusieurs adaptations ou fonctionnalités d’accessibilité pour les publics en situation de handicap. Par exemple sous-titrage, transcription textuelle ou audio, police de caractère accessible…
A19: C3. Synthétiser et analyser des données avec l’IA, en sélectionnant et en configurant les technologies IA en fonction de la typologie de données à analyser (documents, bases de données, messages, réseaux sociaux…), tout en prenant en compte les limites des résultats obtenus, afin de faciliter le traitement d’informations complexes ou volumineuses et favoriser une prise de décision éclairée au sein de sa TPE. | D19: =D20/5 | E19: =IF(D20>=2.5,"oui","non") | F19: =IF(D19<50%,"Commentaire obligatoire"," ")
A20: Note compétence (0 non acquis --> 5 acquis) | D20: =SUM(D21:D23)/3
A21: Cr3.1. La synthèse présentée par le candidat est issue de données volumineuses ou complexes (base de données, indicateurs de production, rapports, données de veille…), dont un extrait est aussi présenté au jury, et générée avec au minimum une technologie IA adaptée qu’il a sélectionnée : le candidat justifie son choix d’IA au regard de la typologie de données à analyser.
A22: Cr3.2. Le candidat explicite et justifie les configurations qu’il a appliquées au sein de l’outil IA sélectionné pour obtenir la synthèse présentée.
A23: Cr3.3. Le candidat justifie en quoi l’utilisation de l’IA facilite le traitement des données et la prise de décision au sein de sa TPE. Il explicite les limites des résultats obtenus (fiabilité des données sources, risques de biais algorithmiques ou d’interprétations abusives) et propose au moins une bonne pratique pour y remédier (par exemple : vérification humaine systématique).
A24: C4. Automatiser des tâches ou des workflows avec l’IA, en paramétrant des technologies IA dédiées de type "no-code/low-code" et en les intégrant à ses process ou outils compatibles (CRM, gestion de projet, finance, RH), afin de rationaliser les opérations courantes et d'augmenter l'efficacité opérationnelle de la TPE. | D24: =D25/5 | E24: =IF(D25>=2.5,"oui","non") | F24: =IF(D24<50%,"Commentaire obligatoire"," ")
A25: Note compétence (0 non acquis --> 5 acquis) | D25: =SUM(D26:D28)/3
A26: Cr4.1. Le paramétrage présenté par le candidat permet d’automatiser une tâche ou un workflow issu des processus courants de sa TPE et est réalisé via une plateforme IA dédiée de type "no-code / low-code" (de type Make, Zapier, Notion AI...).
A27: Cr4.2. Le candidat explicite et justifie les configurations qu’il a appliquées au sein de la plateforme IA dédiée pour automatiser la tâche ou le workflow cible et l’intégrer à ses process ou outils compatibles. Par exemple classification automatique des leads dans un CRM, émission automatique de factures depuis un logiciel comptable, traitement automatique des demandes ou de données dans un outil RH, extraction automatique d’informations issues de réunions ou d’emails vers un outil de gestion de projet ou un planning…
A28: Cr4.3. Le candidat explicite et justifie les tâches et/ou workflows automatisables avec l’IA au sein de sa TPE et les gains attendus en termes d’efficacité opérationnelle.
A30: Total sur 100% | D30: =SUM(D8,D14,D20,D25)/20 | E30: =IF(AND(E7="oui", E13="oui", E19="oui", E24="oui"), "Certification validée","Certification non validée")
A32: Nom des membres du Jury | C32: Date et signature | D32: Date nom et signature du responsable de l'organisation des épreuves
A33: ='Ordre de passage'!F3 | C33: Date et signature | D33: Date + nom + signature du responsable de l'organisation des épreuves
A34: ='Ordre de passage'!F4
A35: Appréciation générale du Jury

Sheet Participant 2
A1: Grille d'évaluation
A2: Améliorer l’efficacité de sa TPE à l’aide de l’IA
A3: Prénom du candidat: | C3: ='Ordre de passage'!C12 | D3: Date de l'oral : | E3: ='Ordre de passage'!F5
A4: Nom du candidat : | C4: ='Ordre de passage'!D12 | D4: Important : Commentaire obligatoire pour les critères et/ou compétences que le candidat ne valide pas
A5: Heure du passage : | C5: ='Ordre de passage'!B12
A6: Compétence évaluée | D6: Note /5 | E6: Compétence acquise | F6: Commentaires
A7: C1. Identifier les opportunités d'application de l'intelligence artificielle au sein de sa TPE, en listant les cas d’usage dans les pratiques de l’organisation en fonction des fonctionnalités et limites des principaux outils IA adaptés, en anticipant les adaptations possibles pour les utilisateurs en situation de handicap, et en prenant en compte le cadre éthique et réglementaire de l’IA, du RGPD et le développement durable, afin d'optimiser les processus et la gestion de la structure. | D7: =D8/5 | E7: =IF(D8>=2.5,"oui","non") | F7: =IF(D7<50%,"Commentaire obligatoire"," ")
A8: Note compétence (0 non acquis --> 5 acquis) | D8: =SUM(D9:D12)/4
A9: Cr1.1. Les opportunités d’application de l’IA identifiées par le candidat permettent d’optimiser les processus et la gestion de sa TPE. Le candidat justifie les différentes optimisations concrètes attendues au regard des capacités, fonctionnalités et limites des technologies IA identifiées. | D9: 0
A10: Cr1.2. Le candidat détaille et justifie les adaptations réalisables dans l’utilisation et/ou le paramétrage des outils IA identifiés pour les utilisateurs en situation de handicap. Par exemple commande vocale, transcription audio des productions textuelles ou visuelles générées par l’IA, prompts intégrant des instructions de structuration ou de langage adapté… | D10: 0
A11: Cr1.3. Le candidat explicite les éléments du cadre éthique et réglementaire en vigueur de l’IA et du RGPD à prendre en compte dans les applications de l’IA identifiées pour sa TPE. | D11: 0
A12: Cr1.4. Le candidat explicite les principaux impacts négatifs de l’IA sur le développement durable (énergie, eau, matériaux rares, émissions) et formule au minimum 2 bonnes pratiques, réalistes et réalisables dans sa TPE, pour un usage responsable et durable. | D12: 0
A13: C2. Générer des contenus diversifiés avec l’IA (articles, visuels, vidéos, supports interactifs, emails…), en appliquant les techniques de prompt engineering (formulation, structuration, itérations) et en exploitant les outils spécifiques d’IA générative, et en intégrant des adaptations ou fonctionnalités d’accessibilité pour les publics en situation de handicap, afin d’améliorer l’efficacité de sa communication interne et externe. | D13: =D14/5 | E13: =IF(D14>=2.5,"oui","non") | F13: =IF(D13<50%,"Commentaire obligatoire"," ")
A14: Note compétence (0 non acquis --> 5 acquis) | D14: =SUM(D15:D18)/4
A15: Cr2.1. Les contenus présentés par le candidat sont diversifiés (articles, visuels, vidéos, supports interactifs, emails…), et générés avec au minimum un outil spécifique d’IA générative : le candidat le justifie en présentant les prompts qu’il a rédigés.
A16: Cr2.2. Le candidat justifie en quoi les contenus ainsi produits permettent d’améliorer l’efficacité de sa communication externe et interne (gain de temps de production, qualité de la production, visuel libre de droit…).
A17: Cr2.3. Les prompts rédigés par le candidat démontrent une application des techniques de prompt engineering : formulation et structuration des requêtes avec les arbres de pensée et la chaîne de raisonnement, amélioration progressive.
A18: Cr2.4. Au moins un des contenus produits par le candidat avec l’IA intègre une ou plusieurs adaptations ou fonctionnalités d’accessibilité pour les publics en situation de handicap. Par exemple sous-titrage, transcription textuelle ou audio, police de caractère accessible…
A19: C3. Synthétiser et analyser des données avec l’IA, en sélectionnant et en configurant les technologies IA en fonction de la typologie de données à analyser (documents, bases de données, messages, réseaux sociaux…), tout en prenant en compte les limites des résultats obtenus, afin de faciliter le traitement d’informations complexes ou volumineuses et favoriser une prise de décision éclairée au sein de sa TPE. | D19: =D20/5 | E19: =IF(D20>=2.5,"oui","non") | F19: =IF(D19<50%,"Commentaire obligatoire"," ")
A20: Note compétence (0 non acquis --> 5 acquis) | D20: =SUM(D21:D23)/3
A21: Cr3.1. La synthèse présentée par le candidat est issue de données volumineuses ou complexes (base de données, indicateurs de production, rapports, données de veille…), dont un extrait est aussi présenté au jury, et générée avec au minimum une technologie IA adaptée qu’il a sélectionnée : le candidat justifie son choix d’IA au regard de la typologie de données à analyser.
A22: Cr3.2. Le candidat explicite et justifie les configurations qu’il a appliquées au sein de l’outil IA sélectionné pour obtenir la synthèse présentée.
A23: Cr3.3. Le candidat justifie en quoi l’utilisation de l’IA facilite le traitement des données et la prise de décision au sein de sa TPE. Il explicite les limites des résultats obtenus (fiabilité des données sources, risques de biais algorithmiques ou d’interprétations abusives) et propose au moins une bonne pratique pour y remédier (par exemple : vérification humaine systématique).
A24: C4. Automatiser des tâches ou des workflows avec l’IA, en paramétrant des technologies IA dédiées de type "no-code/low-code" et en les intégrant à ses process ou outils compatibles (CRM, gestion de projet, finance, RH), afin de rationaliser les opérations courantes et d'augmenter l'efficacité opérationnelle de la TPE. | D24: =D25/5 | E24: =IF(D25>=2.5,"oui","non") | F24: =IF(D24<50%,"Commentaire obligatoire"," ")
A25: Note compétence (0 non acquis --> 5 acquis) | D25: =SUM(D26:D28)/3
A26: Cr4.1. Le paramétrage présenté par le candidat permet d’automatiser une tâche ou un workflow issu des processus courants de sa TPE et est réalisé via une plateforme IA dédiée de type "no-code / low-code" (de type Make, Zapier, Notion AI...).
A27: Cr4.2. Le candidat explicite et justifie les configurations qu’il a appliquées au sein de la plateforme IA dédiée pour automatiser la tâche ou le workflow cible et l’intégrer à ses process ou outils compatibles. Par exemple classification automatique des leads dans un CRM, émission automatique de factures depuis un logiciel comptable, traitement automatique des demandes ou de données dans un outil RH, extraction automatique d’informations issues de réunions ou d’emails vers un outil de gestion de projet ou un planning…
A28: Cr4.3. Le candidat explicite et justifie les tâches et/ou workflows automatisables avec l’IA au sein de sa TPE et les gains attendus en termes d’efficacité opérationnelle.
A30: Total sur 100% | D30: =SUM(D8,D14,D20,D25)/20 | E30: =IF(AND(E7="oui", E13="oui", E19="oui", E24="oui"), "Certification validée","Certification non validée")
A32: Nom des membres du Jury | C32: Date et signature | D32: Date nom et signature du responsable de l'organisation des épreuves
A33: ='Ordre de passage'!F3 | C33: Date et signature | D33: Date + nom + signature du responsable de l'organisation des épreuves
A34: ='Ordre de passage'!F4
A35: Appréciation générale du Jury

Sheet Participant 3
A1: Grille d'évaluation
A2: Améliorer l’efficacité de sa TPE à l’aide de l’IA
A3: Prénom du candidat: | C3: ='Ordre de passage'!C13 | D3: Date de l'oral : | E3: ='Ordre de passage'!F5
A4: Nom du candidat : | C4: ='Ordre de passage'!D13 | D4: Important : Commentaire obligatoire pour les critères et/ou compétences que le candidat ne valide pas
A5: Heure du passage : | C5: ='Ordre de passage'!B13
A6: Compétence évaluée | D6: Note /5 | E6: Compétence acquise | F6: Commentaires
A7: C1. Identifier les opportunités d'application de l'intelligence artificielle au sein de sa TPE, en listant les cas d’usage dans les pratiques de l’organisation en fonction des fonctionnalités et limites des principaux outils IA adaptés, en anticipant les adaptations possibles pour les utilisateurs en situation de handicap, et en prenant en compte le cadre éthique et réglementaire de l’IA, du RGPD et le développement durable, afin d'optimiser les processus et la gestion de la structure. | D7: =D8/5 | E7: =IF(D8>=2.5,"oui","non") | F7: =IF(D7<50%,"Commentaire obligatoire"," ")
A8: Note compétence (0 non acquis --> 5 acquis) | D8: =SUM(D9:D12)/4
A9: Cr1.1. Les opportunités d’application de l’IA identifiées par le candidat permettent d’optimiser les processus et la gestion de sa TPE. Le candidat justifie les différentes optimisations concrètes attendues au regard des capacités, fonctionnalités et limites des technologies IA identifiées.
A10: Cr1.2. Le candidat détaille et justifie les adaptations réalisables dans l’utilisation et/ou le paramétrage des outils IA identifiés pour les utilisateurs en situation de handicap. Par exemple commande vocale, transcription audio des productions textuelles ou visuelles générées par l’IA, prompts intégrant des instructions de structuration ou de langage adapté…
A11: Cr1.3. Le candidat explicite les éléments du cadre éthique et réglementaire en vigueur de l’IA et du RGPD à prendre en compte dans les applications de l’IA identifiées pour sa TPE.
A12: Cr1.4. Le candidat explicite les principaux impacts négatifs de l’IA sur le développement durable (énergie, eau, matériaux rares, émissions) et formule au minimum 2 bonnes pratiques, réalistes et réalisables dans sa TPE, pour un usage responsable et durable.
A13: C2. Générer des contenus diversifiés avec l’IA (articles, visuels, vidéos, supports interactifs, emails…), en appliquant les techniques de prompt engineering (formulation, structuration, itérations) et en exploitant les outils spécifiques d’IA générative, et en intégrant des adaptations ou fonctionnalités d’accessibilité pour les publics en situation de handicap, afin d’améliorer l’efficacité de sa communication interne et externe. | D13: =D14/5 | E13: =IF(D14>=2.5,"oui","non") | F13: =IF(D13<50%,"Commentaire obligatoire"," ")
A14: Note compétence (0 non acquis --> 5 acquis) | D14: =SUM(D15:D18)/4
A15: Cr2.1. Les contenus présentés par le candidat sont diversifiés (articles, visuels, vidéos, supports interactifs, emails…), et générés avec au minimum un outil spécifique d’IA générative : le candidat le justifie en présentant les prompts qu’il a rédigés.
A16: Cr2.2. Le candidat justifie en quoi les contenus ainsi produits permettent d’améliorer l’efficacité de sa communication externe et interne (gain de temps de production, qualité de la production, visuel libre de droit…).
A17: Cr2.3. Les prompts rédigés par le candidat démontrent une application des techniques de prompt engineering : formulation et structuration des requêtes avec les arbres de pensée et la chaîne de raisonnement, amélioration progressive.
A18: Cr2.4. Au moins un des contenus produits par le candidat avec l’IA intègre une ou plusieurs adaptations ou fonctionnalités d’accessibilité pour les publics en situation de handicap. Par exemple sous-titrage, transcription textuelle ou audio, police de caractère accessible…
A19: C3. Synthétiser et analyser des données avec l’IA, en sélectionnant et en configurant les technologies IA en fonction de la typologie de données à analyser (documents, bases de données, messages, réseaux sociaux…), tout en prenant en compte les limites des résultats obtenus, afin de faciliter le traitement d’informations complexes ou volumineuses et favoriser une prise de décision éclairée au sein de sa TPE. | D19: =D20/5 | E19: =IF(D20>=2.5,"oui","non") | F19: =IF(D19<50%,"Commentaire obligatoire"," ")
A20: Note compétence (0 non acquis --> 5 acquis) | D20: =SUM(D21:D23)/3
A21: Cr3.1. La synthèse présentée par le candidat est issue de données volumineuses ou complexes (base de données, indicateurs de production, rapports, données de veille…), dont un extrait est aussi présenté au jury, et générée avec au minimum une technologie IA adaptée qu’il a sélectionnée : le candidat justifie son choix d’IA au regard de la typologie de données à analyser.
A22: Cr3.2. Le candidat explicite et justifie les configurations qu’il a appliquées au sein de l’outil IA sélectionné pour obtenir la synthèse présentée.
A23: Cr3.3. Le candidat justifie en quoi l’utilisation de l’IA facilite le traitement des données et la prise de décision au sein de sa TPE. Il explicite les limites des résultats obtenus (fiabilité des données sources, risques de biais algorithmiques ou d’interprétations abusives) et propose au moins une bonne pratique pour y remédier (par exemple : vérification humaine systématique).
A24: C4. Automatiser des tâches ou des workflows avec l’IA, en paramétrant des technologies IA dédiées de type "no-code/low-code" et en les intégrant à ses process ou outils compatibles (CRM, gestion de projet, finance, RH), afin de rationaliser les opérations courantes et d'augmenter l'efficacité opérationnelle de la TPE. | D24: =D25/5 | E24: =IF(D25>=2.5,"oui","non") | F24: =IF(D24<50%,"Commentaire obligatoire"," ")
A25: Note compétence (0 non acquis --> 5 acquis) | D25: =SUM(D26:D28)/3
A26: Cr4.1. Le paramétrage présenté par le candidat permet d’automatiser une tâche ou un workflow issu des processus courants de sa TPE et est réalisé via une plateforme IA dédiée de type "no-code / low-code" (de type Make, Zapier, Notion AI...).
A27: Cr4.2. Le candidat explicite et justifie les configurations qu’il a appliquées au sein de la plateforme IA dédiée pour automatiser la tâche ou le workflow cible et l’intégrer à ses process ou outils compatibles. Par exemple classification automatique des leads dans un CRM, émission automatique de factures depuis un logiciel comptable, traitement automatique des demandes ou de données dans un outil RH, extraction automatique d’informations issues de réunions ou d’emails vers un outil de gestion de projet ou un planning…
A28: Cr4.3. Le candidat explicite et justifie les tâches et/ou workflows automatisables avec l’IA au sein de sa TPE et les gains attendus en termes d’efficacité opérationnelle.
A30: Total sur 100% | D30: =SUM(D8,D14,D20,D25)/20 | E30: =IF(AND(E7="oui", E13="oui", E19="oui", E24="oui"), "Certification validée","Certification non validée")
A32: Nom des membres du Jury | C32: Date et signature | D32: Date nom et signature du responsable de l'organisation des épreuves
A33: ='Ordre de passage'!F3 | C33: Date et signature | D33: Date + nom + signature du responsable de l'organisation des épreuves
A34: ='Ordre de passage'!F4
A35: Appréciation générale du Jury

Sheet Participant 4
A1: Grille d'évaluation
A2: Améliorer l’efficacité de sa TPE à l’aide de l’IA
A3: Prénom du candidat: | C3: ='Ordre de passage'!C14 | D3: Date de l'oral : | E3: ='Ordre de passage'!F5
A4: Nom du candidat : | C4: ='Ordre de passage'!D14 | D4: Important : Commentaire obligatoire pour les critères et/ou compétences que le candidat ne valide pas
A5: Heure du passage : | C5: ='Ordre de passage'!B14
A6: Compétence évaluée | D6: Note /5 | E6: Compétence acquise | F6: Commentaires
A7: C1. Identifier les opportunités d'application de l'intelligence artificielle au sein de sa TPE, en listant les cas d’usage dans les pratiques de l’organisation en fonction des fonctionnalités et limites des principaux outils IA adaptés, en anticipant les adaptations possibles pour les utilisateurs en situation de handicap, et en prenant en compte le cadre éthique et réglementaire de l’IA, du RGPD et le développement durable, afin d'optimiser les processus et la gestion de la structure. | D7: =D8/5 | E7: =IF(D8>=2.5,"oui","non") | F7: =IF(D7<50%,"Commentaire obligatoire"," ")
A8: Note compétence (0 non acquis --> 5 acquis) | D8: =SUM(D9:D12)/4
A9: Cr1.1. Les opportunités d’application de l’IA identifiées par le candidat permettent d’optimiser les processus et la gestion de sa TPE. Le candidat justifie les différentes optimisations concrètes attendues au regard des capacités, fonctionnalités et limites des technologies IA identifiées.
A10: Cr1.2. Le candidat détaille et justifie les adaptations réalisables dans l’utilisation et/ou le paramétrage des outils IA identifiés pour les utilisateurs en situation de handicap. Par exemple commande vocale, transcription audio des productions textuelles ou visuelles générées par l’IA, prompts intégrant des instructions de structuration ou de langage adapté…
A11: Cr1.3. Le candidat explicite les éléments du cadre éthique et réglementaire en vigueur de l’IA et du RGPD à prendre en compte dans les applications de l’IA identifiées pour sa TPE.
A12: Cr1.4. Le candidat explicite les principaux impacts négatifs de l’IA sur le développement durable (énergie, eau, matériaux rares, émissions) et formule au minimum 2 bonnes pratiques, réalistes et réalisables dans sa TPE, pour un usage responsable et durable.
A13: C2. Générer des contenus diversifiés avec l’IA (articles, visuels, vidéos, supports interactifs, emails…), en appliquant les techniques de prompt engineering (formulation, structuration, itérations) et en exploitant les outils spécifiques d’IA générative, et en intégrant des adaptations ou fonctionnalités d’accessibilité pour les publics en situation de handicap, afin d’améliorer l’efficacité de sa communication interne et externe. | D13: =D14/5 | E13: =IF(D14>=2.5,"oui","non") | F13: =IF(D13<50%,"Commentaire obligatoire"," ")
A14: Note compétence (0 non acquis --> 5 acquis) | D14: =SUM(D15:D18)/4
A15: Cr2.1. Les contenus présentés par le candidat sont diversifiés (articles, visuels, vidéos, supports interactifs, emails…), et générés avec au minimum un outil spécifique d’IA générative : le candidat le justifie en présentant les prompts qu’il a rédigés.
A16: Cr2.2. Le candidat justifie en quoi les contenus ainsi produits permettent d’améliorer l’efficacité de sa communication externe et interne (gain de temps de production, qualité de la production, visuel libre de droit…).
A17: Cr2.3. Les prompts rédigés par le candidat démontrent une application des techniques de prompt engineering : formulation et structuration des requêtes avec les arbres de pensée et la chaîne de raisonnement, amélioration progressive.
A18: Cr2.4. Au moins un des contenus produits par le candidat avec l’IA intègre une ou plusieurs adaptations ou fonctionnalités d’accessibilité pour les publics en situation de handicap. Par exemple sous-titrage, transcription textuelle ou audio, police de caractère accessible…
A19: C3. Synthétiser et analyser des données avec l’IA, en sélectionnant et en configurant les technologies IA en fonction de la typologie de données à analyser (documents, bases de données, messages, réseaux sociaux…), tout en prenant en compte les limites des résultats obtenus, afin de faciliter le traitement d’informations complexes ou volumineuses et favoriser une prise de décision éclairée au sein de sa TPE. | D19: =D20/5 | E19: =IF(D20>=2.5,"oui","non") | F19: =IF(D19<50%,"Commentaire obligatoire"," ")
A20: Note compétence (0 non acquis --> 5 acquis) | D20: =SUM(D21:D23)/3
A21: Cr3.1. La synthèse présentée par le candidat est issue de données volumineuses ou complexes (base de données, indicateurs de production, rapports, données de veille…), dont un extrait est aussi présenté au jury, et générée avec au minimum une technologie IA adaptée qu’il a sélectionnée : le candidat justifie son choix d’IA au regard de la typologie de données à analyser.
A22: Cr3.2. Le candidat explicite et justifie les configurations qu’il a appliquées au sein de l’outil IA sélectionné pour obtenir la synthèse présentée.
A23: Cr3.3. Le candidat justifie en quoi l’utilisation de l’IA facilite le traitement des données et la prise de décision au sein de sa TPE. Il explicite les limites des résultats obtenus (fiabilité des données sources, risques de biais algorithmiques ou d’interprétations abusives) et propose au moins une bonne pratique pour y remédier (par exemple : vérification humaine systématique).
A24: C4. Automatiser des tâches ou des workflows avec l’IA, en paramétrant des technologies IA dédiées de type "no-code/low-code" et en les intégrant à ses process ou outils compatibles (CRM, gestion de projet, finance, RH), afin de rationaliser les opérations courantes et d'augmenter l'efficacité opérationnelle de la TPE. | D24: =D25/5 | E24: =IF(D25>=2.5,"oui","non") | F24: =IF(D24<50%,"Commentaire obligatoire"," ")
A25: Note compétence (0 non acquis --> 5 acquis) | D25: =SUM(D26:D28)/3
A26: Cr4.1. Le paramétrage présenté par le candidat permet d’automatiser une tâche ou un workflow issu des processus courants de sa TPE et est réalisé via une plateforme IA dédiée de type "no-code / low-code" (de type Make, Zapier, Notion AI...).
A27: Cr4.2. Le candidat explicite et justifie les configurations qu’il a appliquées au sein de la plateforme IA dédiée pour automatiser la tâche ou le workflow cible et l’intégrer à ses process ou outils compatibles. Par exemple classification automatique des leads dans un CRM, émission automatique de factures depuis un logiciel comptable, traitement automatique des demandes ou de données dans un outil RH, extraction automatique d’informations issues de réunions ou d’emails vers un outil de gestion de projet ou un planning…
A28: Cr4.3. Le candidat explicite et justifie les tâches et/ou workflows automatisables avec l’IA au sein de sa TPE et les gains attendus en termes d’efficacité opérationnelle.
A30: Total sur 100% | D30: =SUM(D8,D14,D20,D25)/20 | E30: =IF(AND(E7="oui", E13="oui", E19="oui", E24="oui"), "Certification validée","Certification non validée")
A32: Nom des membres du Jury | C32: Date et signature | D32: Date nom et signature du responsable de l'organisation des épreuves
A33: ='Ordre de passage'!F3 | C33: Date et signature | D33: Date + nom + signature du responsable de l'organisation des épreuves
A34: ='Ordre de passage'!F4
A35: Appréciation générale du Jury

Sheet Participant 5
A1: Grille d'évaluation
A2: Améliorer l’efficacité de sa TPE à l’aide de l’IA
A3: Prénom du candidat: | C3: ='Ordre de passage'!C15 | D3: Date de l'oral : | E3: ='Ordre de passage'!F5
A4: Nom du candidat : | C4: ='Ordre de passage'!D15 | D4: Important : Commentaire obligatoire pour les critères et/ou compétences que le candidat ne valide pas
A5: Heure du passage : | C5: ='Ordre de passage'!B15
A6: Compétence évaluée | D6: Note /5 | E6: Compétence acquise | F6: Commentaires
A7: C1. Identifier les opportunités d'application de l'intelligence artificielle au sein de sa TPE, en listant les cas d’usage dans les pratiques de l’organisation en fonction des fonctionnalités et limites des principaux outils IA adaptés, en anticipant les adaptations possibles pour les utilisateurs en situation de handicap, et en prenant en compte le cadre éthique et réglementaire de l’IA, du RGPD et le développement durable, afin d'optimiser les processus et la gestion de la structure. | D7: =D8/5 | E7: =IF(D8>=2.5,"oui","non") | F7: =IF(D7<50%,"Commentaire obligatoire"," ")
A8: Note compétence (0 non acquis --> 5 acquis) | D8: =SUM(D9:D12)/4
A9: Cr1.1. Les opportunités d’application de l’IA identifiées par le candidat permettent d’optimiser les processus et la gestion de sa TPE. Le candidat justifie les différentes optimisations concrètes attendues au regard des capacités, fonctionnalités et limites des technologies IA identifiées.
A10: Cr1.2. Le candidat détaille et justifie les adaptations réalisables dans l’utilisation et/ou le paramétrage des outils IA identifiés pour les utilisateurs en situation de handicap. Par exemple commande vocale, transcription audio des productions textuelles ou visuelles générées par l’IA, prompts intégrant des instructions de structuration ou de langage adapté…
A11: Cr1.3. Le candidat explicite les éléments du cadre éthique et réglementaire en vigueur de l’IA et du RGPD à prendre en compte dans les applications de l’IA identifiées pour sa TPE.
A12: Cr1.4. Le candidat explicite les principaux impacts négatifs de l’IA sur le développement durable (énergie, eau, matériaux rares, émissions) et formule au minimum 2 bonnes pratiques, réalistes et réalisables dans sa TPE, pour un usage responsable et durable.
A13: C2. Générer des contenus diversifiés avec l’IA (articles, visuels, vidéos, supports interactifs, emails…), en appliquant les techniques de prompt engineering (formulation, structuration, itérations) et en exploitant les outils spécifiques d’IA générative, et en intégrant des adaptations ou fonctionnalités d’accessibilité pour les publics en situation de handicap, afin d’améliorer l’efficacité de sa communication interne et externe. | D13: =D14/5 | E13: =IF(D14>=2.5,"oui","non") | F13: =IF(D13<50%,"Commentaire obligatoire"," ")
A14: Note compétence (0 non acquis --> 5 acquis) | D14: =SUM(D15:D18)/4
A15: Cr2.1. Les contenus présentés par le candidat sont diversifiés (articles, visuels, vidéos, supports interactifs, emails…), et générés avec au minimum un outil spécifique d’IA générative : le candidat le justifie en présentant les prompts qu’il a rédigés.
A16: Cr2.2. Le candidat justifie en quoi les contenus ainsi produits permettent d’améliorer l’efficacité de sa communication externe et interne (gain de temps de production, qualité de la production, visuel libre de droit…).
A17: Cr2.3. Les prompts rédigés par le candidat démontrent une application des techniques de prompt engineering : formulation et structuration des requêtes avec les arbres de pensée et la chaîne de raisonnement, amélioration progressive.
A18: Cr2.4. Au moins un des contenus produits par le candidat avec l’IA intègre une ou plusieurs adaptations ou fonctionnalités d’accessibilité pour les publics en situation de handicap. Par exemple sous-titrage, transcription textuelle ou audio, police de caractère accessible…
A19: C3. Synthétiser et analyser des données avec l’IA, en sélectionnant et en configurant les technologies IA en fonction de la typologie de données à analyser (documents, bases de données, messages, réseaux sociaux…), tout en prenant en compte les limites des résultats obtenus, afin de faciliter le traitement d’informations complexes ou volumineuses et favoriser une prise de décision éclairée au sein de sa TPE. | D19: =D20/5 | E19: =IF(D20>=2.5,"oui","non") | F19: =IF(D19<50%,"Commentaire obligatoire"," ")
A20: Note compétence (0 non acquis --> 5 acquis) | D20: =SUM(D21:D23)/3
A21: Cr3.1. La synthèse présentée par le candidat est issue de données volumineuses ou complexes (base de données, indicateurs de production, rapports, données de veille…), dont un extrait est aussi présenté au jury, et générée avec au minimum une technologie IA adaptée qu’il a sélectionnée : le candidat justifie son choix d’IA au regard de la typologie de données à analyser.
A22: Cr3.2. Le candidat explicite et justifie les configurations qu’il a appliquées au sein de l’outil IA sélectionné pour obtenir la synthèse présentée.
A23: Cr3.3. Le candidat justifie en quoi l’utilisation de l’IA facilite le traitement des données et la prise de décision au sein de sa TPE. Il explicite les limites des résultats obtenus (fiabilité des données sources, risques de biais algorithmiques ou d’interprétations abusives) et propose au moins une bonne pratique pour y remédier (par exemple : vérification humaine systématique).
A24: C4. Automatiser des tâches ou des workflows avec l’IA, en paramétrant des technologies IA dédiées de type "no-code/low-code" et en les intégrant à ses process ou outils compatibles (CRM, gestion de projet, finance, RH), afin de rationaliser les opérations courantes et d'augmenter l'efficacité opérationnelle de la TPE. | D24: =D25/5 | E24: =IF(D25>=2.5,"oui","non") | F24: =IF(D24<50%,"Commentaire obligatoire"," ")
A25: Note compétence (0 non acquis --> 5 acquis) | D25: =SUM(D26:D28)/3
A26: Cr4.1. Le paramétrage présenté par le candidat permet d’automatiser une tâche ou un workflow issu des processus courants de sa TPE et est réalisé via une plateforme IA dédiée de type "no-code / low-code" (de type Make, Zapier, Notion AI...).
A27: Cr4.2. Le candidat explicite et justifie les configurations qu’il a appliquées au sein de la plateforme IA dédiée pour automatiser la tâche ou le workflow cible et l’intégrer à ses process ou outils compatibles. Par exemple classification automatique des leads dans un CRM, émission automatique de factures depuis un logiciel comptable, traitement automatique des demandes ou de données dans un outil RH, extraction automatique d’informations issues de réunions ou d’emails vers un outil de gestion de projet ou un planning…
A28: Cr4.3. Le candidat explicite et justifie les tâches et/ou workflows automatisables avec l’IA au sein de sa TPE et les gains attendus en termes d’efficacité opérationnelle.
A30: Total sur 100% | D30: =SUM(D8,D14,D20,D25)/20 | E30: =IF(AND(E7="oui", E13="oui", E19="oui", E24="oui"), "Certification validée","Certification non validée")
A32: Nom des membres du Jury | C32: Date et signature | D32: Date nom et signature du responsable de l'organisation des épreuves
A33: ='Ordre de passage'!F3 | C33: Date et signature | D33: Date + nom + signature du responsable de l'organisation des épreuves
A34: ='Ordre de passage'!F4
A35: Appréciation générale du Jury

Sheet Participant 6
A1: Grille d'évaluation
A2: Améliorer l’efficacité de sa TPE à l’aide de l’IA
A3: Prénom du candidat: | C3: ='Ordre de passage'!C16 | D3: Date de l'oral : | E3: ='Ordre de passage'!F5
A4: Nom du candidat : | C4: ='Ordre de passage'!D16 | D4: Important : Commentaire obligatoire pour les critères et/ou compétences que le candidat ne valide pas
A5: Heure du passage : | C5: ='Ordre de passage'!B16
A6: Compétence évaluée | D6: Note /5 | E6: Compétence acquise | F6: Commentaires
A7: C1. Identifier les opportunités d'application de l'intelligence artificielle au sein de sa TPE, en listant les cas d’usage dans les pratiques de l’organisation en fonction des fonctionnalités et limites des principaux outils IA adaptés, en anticipant les adaptations possibles pour les utilisateurs en situation de handicap, et en prenant en compte le cadre éthique et réglementaire de l’IA, du RGPD et le développement durable, afin d'optimiser les processus et la gestion de la structure. | D7: =D8/5 | E7: =IF(D8>=2.5,"oui","non") | F7: =IF(D7<50%,"Commentaire obligatoire"," ")
A8: Note compétence (0 non acquis --> 5 acquis) | D8: =SUM(D9:D12)/4
A9: Cr1.1. Les opportunités d’application de l’IA identifiées par le candidat permettent d’optimiser les processus et la gestion de sa TPE. Le candidat justifie les différentes optimisations concrètes attendues au regard des capacités, fonctionnalités et limites des technologies IA identifiées.
A10: Cr1.2. Le candidat détaille et justifie les adaptations réalisables dans l’utilisation et/ou le paramétrage des outils IA identifiés pour les utilisateurs en situation de handicap. Par exemple commande vocale, transcription audio des productions textuelles ou visuelles générées par l’IA, prompts intégrant des instructions de structuration ou de langage adapté…
A11: Cr1.3. Le candidat explicite les éléments du cadre éthique et réglementaire en vigueur de l’IA et du RGPD à prendre en compte dans les applications de l’IA identifiées pour sa TPE.
A12: Cr1.4. Le candidat explicite les principaux impacts négatifs de l’IA sur le développement durable (énergie, eau, matériaux rares, émissions) et formule au minimum 2 bonnes pratiques, réalistes et réalisables dans sa TPE, pour un usage responsable et durable.
A13: C2. Générer des contenus diversifiés avec l’IA (articles, visuels, vidéos, supports interactifs, emails…), en appliquant les techniques de prompt engineering (formulation, structuration, itérations) et en exploitant les outils spécifiques d’IA générative, et en intégrant des adaptations ou fonctionnalités d’accessibilité pour les publics en situation de handicap, afin d’améliorer l’efficacité de sa communication interne et externe. | D13: =D14/5 | E13: =IF(D14>=2.5,"oui","non") | F13: =IF(D13<50%,"Commentaire obligatoire"," ")
A14: Note compétence (0 non acquis --> 5 acquis) | D14: =SUM(D15:D18)/4
A15: Cr2.1. Les contenus présentés par le candidat sont diversifiés (articles, visuels, vidéos, supports interactifs, emails…), et générés avec au minimum un outil spécifique d’IA générative : le candidat le justifie en présentant les prompts qu’il a rédigés.
A16: Cr2.2. Le candidat justifie en quoi les contenus ainsi produits permettent d’améliorer l’efficacité de sa communication externe et interne (gain de temps de production, qualité de la production, visuel libre de droit…).
A17: Cr2.3. Les prompts rédigés par le candidat démontrent une application des techniques de prompt engineering : formulation et structuration des requêtes avec les arbres de pensée et la chaîne de raisonnement, amélioration progressive.
A18: Cr2.4. Au moins un des contenus produits par le candidat avec l’IA intègre une ou plusieurs adaptations ou fonctionnalités d’accessibilité pour les publics en situation de handicap. Par exemple sous-titrage, transcription textuelle ou audio, police de caractère accessible…
A19: C3. Synthétiser et analyser des données avec l’IA, en sélectionnant et en configurant les technologies IA en fonction de la typologie de données à analyser (documents, bases de données, messages, réseaux sociaux…), tout en prenant en compte les limites des résultats obtenus, afin de faciliter le traitement d’informations complexes ou volumineuses et favoriser une prise de décision éclairée au sein de sa TPE. | D19: =D20/5 | E19: =IF(D20>=2.5,"oui","non") | F19: =IF(D19<50%,"Commentaire obligatoire"," ")
A20: Note compétence (0 non acquis --> 5 acquis) | D20: =SUM(D21:D23)/3
A21: Cr3.1. La synthèse présentée par le candidat est issue de données volumineuses ou complexes (base de données, indicateurs de production, rapports, données de veille…), dont un extrait est aussi présenté au jury, et générée avec au minimum une technologie IA adaptée qu’il a sélectionnée : le candidat justifie son choix d’IA au regard de la typologie de données à analyser.
A22: Cr3.2. Le candidat explicite et justifie les configurations qu’il a appliquées au sein de l’outil IA sélectionné pour obtenir la synthèse présentée.
A23: Cr3.3. Le candidat justifie en quoi l’utilisation de l’IA facilite le traitement des données et la prise de décision au sein de sa TPE. Il explicite les limites des résultats obtenus (fiabilité des données sources, risques de biais algorithmiques ou d’interprétations abusives) et propose au moins une bonne pratique pour y remédier (par exemple : vérification humaine systématique).
A24: C4. Automatiser des tâches ou des workflows avec l’IA, en paramétrant des technologies IA dédiées de type "no-code/low-code" et en les intégrant à ses process ou outils compatibles (CRM, gestion de projet, finance, RH), afin de rationaliser les opérations courantes et d'augmenter l'efficacité opérationnelle de la TPE. | D24: =D25/5 | E24: =IF(D25>=2.5,"oui","non") | F24: =IF(D24<50%,"Commentaire obligatoire"," ")
A25: Note compétence (0 non acquis --> 5 acquis) | D25: =SUM(D26:D28)/3
A26: Cr4.1. Le paramétrage présenté par le candidat permet d’automatiser une tâche ou un workflow issu des processus courants de sa TPE et est réalisé via une plateforme IA dédiée de type "no-code / low-code" (de type Make, Zapier, Notion AI...).
A27: Cr4.2. Le candidat explicite et justifie les configurations qu’il a appliquées au sein de la plateforme IA dédiée pour automatiser la tâche ou le workflow cible et l’intégrer à ses process ou outils compatibles. Par exemple classification automatique des leads dans un CRM, émission automatique de factures depuis un logiciel comptable, traitement automatique des demandes ou de données dans un outil RH, extraction automatique d’informations issues de réunions ou d’emails vers un outil de gestion de projet ou un planning…
A28: Cr4.3. Le candidat explicite et justifie les tâches et/ou workflows automatisables avec l’IA au sein de sa TPE et les gains attendus en termes d’efficacité opérationnelle.
A30: Total sur 100% | D30: =SUM(D8,D14,D20,D25)/20 | E30: =IF(AND(E7="oui", E13="oui", E19="oui", E24="oui"), "Certification validée","Certification non validée")
A32: Nom des membres du Jury | C32: Date et signature | D32: Date nom et signature du responsable de l'organisation des épreuves
A33: ='Ordre de passage'!F3 | C33: Date et signature | D33: Date + nom + signature du responsable de l'organisation des épreuves
A34: ='Ordre de passage'!F4
A35: Appréciation générale du Jury

Sheet Participant 7
A1: Grille d'évaluation
A2: Améliorer l’efficacité de sa TPE à l’aide de l’IA
A3: Prénom du candidat: | C3: ='Ordre de passage'!C17 | D3: Date de l'oral : | E3: ='Ordre de passage'!F5
A4: Nom du candidat : | C4: ='Ordre de passage'!D17 | D4: Important : Commentaire obligatoire pour les critères et/ou compétences que le candidat ne valide pas
A5: Heure du passage : | C5: ='Ordre de passage'!B17
A6: Compétence évaluée | D6: Note /5 | E6: Compétence acquise | F6: Commentaires
A7: C1. Identifier les opportunités d'application de l'intelligence artificielle au sein de sa TPE, en listant les cas d’usage dans les pratiques de l’organisation en fonction des fonctionnalités et limites des principaux outils IA adaptés, en anticipant les adaptations possibles pour les utilisateurs en situation de handicap, et en prenant en compte le cadre éthique et réglementaire de l’IA, du RGPD et le développement durable, afin d'optimiser les processus et la gestion de la structure. | D7: =D8/5 | E7: =IF(D8>=2.5,"oui","non") | F7: =IF(D7<50%,"Commentaire obligatoire"," ")
A8: Note compétence (0 non acquis --> 5 acquis) | D8: =SUM(D9:D12)/4
A9: Cr1.1. Les opportunités d’application de l’IA identifiées par le candidat permettent d’optimiser les processus et la gestion de sa TPE. Le candidat justifie les différentes optimisations concrètes attendues au regard des capacités, fonctionnalités et limites des technologies IA identifiées.
A10: Cr1.2. Le candidat détaille et justifie les adaptations réalisables dans l’utilisation et/ou le paramétrage des outils IA identifiés pour les utilisateurs en situation de handicap. Par exemple commande vocale, transcription audio des productions textuelles ou visuelles générées par l’IA, prompts intégrant des instructions de structuration ou de langage adapté…
A11: Cr1.3. Le candidat explicite les éléments du cadre éthique et réglementaire en vigueur de l’IA et du RGPD à prendre en compte dans les applications de l’IA identifiées pour sa TPE.
A12: Cr1.4. Le candidat explicite les principaux impacts négatifs de l’IA sur le développement durable (énergie, eau, matériaux rares, émissions) et formule au minimum 2 bonnes pratiques, réalistes et réalisables dans sa TPE, pour un usage responsable et durable.
A13: C2. Générer des contenus diversifiés avec l’IA (articles, visuels, vidéos, supports interactifs, emails…), en appliquant les techniques de prompt engineering (formulation, structuration, itérations) et en exploitant les outils spécifiques d’IA générative, et en intégrant des adaptations ou fonctionnalités d’accessibilité pour les publics en situation de handicap, afin d’améliorer l’efficacité de sa communication interne et externe. | D13: =D14/5 | E13: =IF(D14>=2.5,"oui","non") | F13: =IF(D13<50%,"Commentaire obligatoire"," ")
A14: Note compétence (0 non acquis --> 5 acquis) | D14: =SUM(D15:D18)/4
A15: Cr2.1. Les contenus présentés par le candidat sont diversifiés (articles, visuels, vidéos, supports interactifs, emails…), et générés avec au minimum un outil spécifique d’IA générative : le candidat le justifie en présentant les prompts qu’il a rédigés.
A16: Cr2.2. Le candidat justifie en quoi les contenus ainsi produits permettent d’améliorer l’efficacité de sa communication externe et interne (gain de temps de production, qualité de la production, visuel libre de droit…).
A17: Cr2.3. Les prompts rédigés par le candidat démontrent une application des techniques de prompt engineering : formulation et structuration des requêtes avec les arbres de pensée et la chaîne de raisonnement, amélioration progressive.
A18: Cr2.4. Au moins un des contenus produits par le candidat avec l’IA intègre une ou plusieurs adaptations ou fonctionnalités d’accessibilité pour les publics en situation de handicap. Par exemple sous-titrage, transcription textuelle ou audio, police de caractère accessible…
A19: C3. Synthétiser et analyser des données avec l’IA, en sélectionnant et en configurant les technologies IA en fonction de la typologie de données à analyser (documents, bases de données, messages, réseaux sociaux…), tout en prenant en compte les limites des résultats obtenus, afin de faciliter le traitement d’informations complexes ou volumineuses et favoriser une prise de décision éclairée au sein de sa TPE. | D19: =D20/5 | E19: =IF(D20>=2.5,"oui","non") | F19: =IF(D19<50%,"Commentaire obligatoire"," ")
A20: Note compétence (0 non acquis --> 5 acquis) | D20: =SUM(D21:D23)/3
A21: Cr3.1. La synthèse présentée par le candidat est issue de données volumineuses ou complexes (base de données, indicateurs de production, rapports, données de veille…), dont un extrait est aussi présenté au jury, et générée avec au minimum une technologie IA adaptée qu’il a sélectionnée : le candidat justifie son choix d’IA au regard de la typologie de données à analyser.
A22: Cr3.2. Le candidat explicite et justifie les configurations qu’il a appliquées au sein de l’outil IA sélectionné pour obtenir la synthèse présentée.
A23: Cr3.3. Le candidat justifie en quoi l’utilisation de l’IA facilite le traitement des données et la prise de décision au sein de sa TPE. Il explicite les limites des résultats obtenus (fiabilité des données sources, risques de biais algorithmiques ou d’interprétations abusives) et propose au moins une bonne pratique pour y remédier (par exemple : vérification humaine systématique).
A24: C4. Automatiser des tâches ou des workflows avec l’IA, en paramétrant des technologies IA dédiées de type "no-code/low-code" et en les intégrant à ses process ou outils compatibles (CRM, gestion de projet, finance, RH), afin de rationaliser les opérations courantes et d'augmenter l'efficacité opérationnelle de la TPE. | D24: =D25/5 | E24: =IF(D25>=2.5,"oui","non") | F24: =IF(D24<50%,"Commentaire obligatoire"," ")
A25: Note compétence (0 non acquis --> 5 acquis) | D25: =SUM(D26:D28)/3
A26: Cr4.1. Le paramétrage présenté par le candidat permet d’automatiser une tâche ou un workflow issu des processus courants de sa TPE et est réalisé via une plateforme IA dédiée de type "no-code / low-code" (de type Make, Zapier, Notion AI...).
A27: Cr4.2. Le candidat explicite et justifie les configurations qu’il a appliquées au sein de la plateforme IA dédiée pour automatiser la tâche ou le workflow cible et l’intégrer à ses process ou outils compatibles. Par exemple classification automatique des leads dans un CRM, émission automatique de factures depuis un logiciel comptable, traitement automatique des demandes ou de données dans un outil RH, extraction automatique d’informations issues de réunions ou d’emails vers un outil de gestion de projet ou un planning…
A28: Cr4.3. Le candidat explicite et justifie les tâches et/ou workflows automatisables avec l’IA au sein de sa TPE et les gains attendus en termes d’efficacité opérationnelle.
A30: Total sur 100% | D30: =SUM(D8,D14,D20,D25)/20 | E30: =IF(AND(E7="oui", E13="oui", E19="oui", E24="oui"), "Certification validée","Certification non validée")
A32: Nom des membres du Jury | C32: Date et signature | D32: Date nom et signature du responsable de l'organisation des épreuves
A33: ='Ordre de passage'!F3 | C33: Date et signature | D33: Date + nom + signature du responsable de l'organisation des épreuves
A34: ='Ordre de passage'!F4
A35: Appréciation générale du Jury

Sheet Participant 8
A1: Grille d'évaluation
A2: Améliorer l’efficacité de sa TPE à l’aide de l’IA
A3: Prénom du candidat: | C3: ='Ordre de passage'!C18 | D3: Date de l'oral : | E3: ='Ordre de passage'!F5
A4: Nom du candidat : | C4: ='Ordre de passage'!D18 | D4: Important : Commentaire obligatoire pour les critères et/ou compétences que le candidat ne valide pas
A5: Heure du passage : | C5: ='Ordre de passage'!B18
A6: Compétence évaluée | D6: Note /5 | E6: Compétence acquise | F6: Commentaires
A7: C1. Identifier les opportunités d'application de l'intelligence artificielle au sein de sa TPE, en listant les cas d’usage dans les pratiques de l’organisation en fonction des fonctionnalités et limites des principaux outils IA adaptés, en anticipant les adaptations possibles pour les utilisateurs en situation de handicap, et en prenant en compte le cadre éthique et réglementaire de l’IA, du RGPD et le développement durable, afin d'optimiser les processus et la gestion de la structure. | D7: =D8/5 | E7: =IF(D8>=2.5,"oui","non") | F7: =IF(D7<50%,"Commentaire obligatoire"," ")
A8: Note compétence (0 non acquis --> 5 acquis) | D8: =SUM(D9:D12)/4
A9: Cr1.1. Les opportunités d’application de l’IA identifiées par le candidat permettent d’optimiser les processus et la gestion de sa TPE. Le candidat justifie les différentes optimisations concrètes attendues au regard des capacités, fonctionnalités et limites des technologies IA identifiées.
A10: Cr1.2. Le candidat détaille et justifie les adaptations réalisables dans l’utilisation et/ou le paramétrage des outils IA identifiés pour les utilisateurs en situation de handicap. Par exemple commande vocale, transcription audio des productions textuelles ou visuelles générées par l’IA, prompts intégrant des instructions de structuration ou de langage adapté…
A11: Cr1.3. Le candidat explicite les éléments du cadre éthique et réglementaire en vigueur de l’IA et du RGPD à prendre en compte dans les applications de l’IA identifiées pour sa TPE.
A12: Cr1.4. Le candidat explicite les principaux impacts négatifs de l’IA sur le développement durable (énergie, eau, matériaux rares, émissions) et formule au minimum 2 bonnes pratiques, réalistes et réalisables dans sa TPE, pour un usage responsable et durable.
A13: C2. Générer des contenus diversifiés avec l’IA (articles, visuels, vidéos, supports interactifs, emails…), en appliquant les techniques de prompt engineering (formulation, structuration, itérations) et en exploitant les outils spécifiques d’IA générative, et en intégrant des adaptations ou fonctionnalités d’accessibilité pour les publics en situation de handicap, afin d’améliorer l’efficacité de sa communication interne et externe. | D13: =D14/5 | E13: =IF(D14>=2.5,"oui","non") | F13: =IF(D13<50%,"Commentaire obligatoire"," ")
A14: Note compétence (0 non acquis --> 5 acquis) | D14: =SUM(D15:D18)/4
A15: Cr2.1. Les contenus présentés par le candidat sont diversifiés (articles, visuels, vidéos, supports interactifs, emails…), et générés avec au minimum un outil spécifique d’IA générative : le candidat le justifie en présentant les prompts qu’il a rédigés.
A16: Cr2.2. Le candidat justifie en quoi les contenus ainsi produits permettent d’améliorer l’efficacité de sa communication externe et interne (gain de temps de production, qualité de la production, visuel libre de droit…).
A17: Cr2.3. Les prompts rédigés par le candidat démontrent une application des techniques de prompt engineering : formulation et structuration des requêtes avec les arbres de pensée et la chaîne de raisonnement, amélioration progressive.
A18: Cr2.4. Au moins un des contenus produits par le candidat avec l’IA intègre une ou plusieurs adaptations ou fonctionnalités d’accessibilité pour les publics en situation de handicap. Par exemple sous-titrage, transcription textuelle ou audio, police de caractère accessible…
A19: C3. Synthétiser et analyser des données avec l’IA, en sélectionnant et en configurant les technologies IA en fonction de la typologie de données à analyser (documents, bases de données, messages, réseaux sociaux…), tout en prenant en compte les limites des résultats obtenus, afin de faciliter le traitement d’informations complexes ou volumineuses et favoriser une prise de décision éclairée au sein de sa TPE. | D19: =D20/5 | E19: =IF(D20>=2.5,"oui","non") | F19: =IF(D19<50%,"Commentaire obligatoire"," ")
A20: Note compétence (0 non acquis --> 5 acquis) | D20: =SUM(D21:D23)/3
A21: Cr3.1. La synthèse présentée par le candidat est issue de données volumineuses ou complexes (base de données, indicateurs de production, rapports, données de veille…), dont un extrait est aussi présenté au jury, et générée avec au minimum une technologie IA adaptée qu’il a sélectionnée : le candidat justifie son choix d’IA au regard de la typologie de données à analyser.
A22: Cr3.2. Le candidat explicite et justifie les configurations qu’il a appliquées au sein de l’outil IA sélectionné pour obtenir la synthèse présentée.
A23: Cr3.3. Le candidat justifie en quoi l’utilisation de l’IA facilite le traitement des données et la prise de décision au sein de sa TPE. Il explicite les limites des résultats obtenus (fiabilité des données sources, risques de biais algorithmiques ou d’interprétations abusives) et propose au moins une bonne pratique pour y remédier (par exemple : vérification humaine systématique).
A24: C4. Automatiser des tâches ou des workflows avec l’IA, en paramétrant des technologies IA dédiées de type "no-code/low-code" et en les intégrant à ses process ou outils compatibles (CRM, gestion de projet, finance, RH), afin de rationaliser les opérations courantes et d'augmenter l'efficacité opérationnelle de la TPE. | D24: =D25/5 | E24: =IF(D25>=2.5,"oui","non") | F24: =IF(D24<50%,"Commentaire obligatoire"," ")
A25: Note compétence (0 non acquis --> 5 acquis) | D25: =SUM(D26:D28)/3
A26: Cr4.1. Le paramétrage présenté par le candidat permet d’automatiser une tâche ou un workflow issu des processus courants de sa TPE et est réalisé via une plateforme IA dédiée de type "no-code / low-code" (de type Make, Zapier, Notion AI...).
A27: Cr4.2. Le candidat explicite et justifie les configurations qu’il a appliquées au sein de la plateforme IA dédiée pour automatiser la tâche ou le workflow cible et l’intégrer à ses process ou outils compatibles. Par exemple classification automatique des leads dans un CRM, émission automatique de factures depuis un logiciel comptable, traitement automatique des demandes ou de données dans un outil RH, extraction automatique d’informations issues de réunions ou d’emails vers un outil de gestion de projet ou un planning…
