Workbook

Sheet TABLEAU DE BORD
B2: TABLEAU DE BORD - SUIVI DES APPRENANTS
B3: APPRENANTS est la table maitre : WEDOF - EXAMEN FINAL, PAIEMENTS & COMMISSIONS et AUTOMATISATION se remplissent automatiquement a partir d'elle (meme ordre de lignes).
B6: INDICATEURS CLES
B7: Total apprenants suivis | D7: =COUNTIF(APPRENANTS!$B$2:$B$153,"?*") -> 152
B8: Dossiers avec documents en attente | D8: =COUNTIF(APPRENANTS!$U$2:$U$153,"?*") -> 152
B9: Dossiers a relancer (J+1 fin formation) | D9: =COUNTIF(APPRENANTS!$W$2:$W$153,"?*") -> 106
B10: Doublons Organisme a verifier | D10: =COUNTIF(APPRENANTS!$X$2:$X$153,"?*") -> 0
B11: Dossiers examen Wedof en attente | D11: =COUNTIF('WEDOF - EXAMEN FINAL'!$M$2:$M$153,"?*") -> 143
B12: Commissions en retard de versement | D12: =COUNTIF('PAIEMENTS & COMMISSIONS'!$L$2:$L$153,"En retard - a verser") -> 57
B13: CA total previsionnel (dossiers confirmes uniquement) | D13: =SUM('PAIEMENTS & COMMISSIONS'!$O$2:$O$153) -> 216000
B14: Commission totale due aux apporteurs (dossiers confirmes uniquement) | D14: =SUM('PAIEMENTS & COMMISSIONS'!$P$2:$P$153) -> 109875
B15: Dossiers prets pour generation (classique) | D15: =COUNTIF(AUTOMATISATION!$T$13:$T$164,TRUE()) -> 139
B16: Dossiers prets pour generation (wedof) | D16: =COUNTIF(AUTOMATISATION!$U$13:$U$164,TRUE()) -> 19
B17: Dossiers avec inscription NON confirmee/payee | D17: =COUNTIF(APPRENANTS!$Y$2:$Y$153,"Non") -> 8
B19: SUIVI COMPLET PAR APPRENANT
B20: Organisme | C20: Nom | D20: Apporteur | E20: Missions documents a faire | F20: % Avancement | G20: Missions examen Wedof a faire | H20: Alerte relance | I20: Alerte doublon | J20: Statut commission | K20: Inscription confirmee
B21: =APPRENANTS!A2 -> Proforma Institut | C21: =APPRENANTS!B2 -> Mohamed Ait Baha | D21: =APPRENANTS!C2 -> Djody | E21: =APPRENANTS!U2 -> Analyse du besoin, CV | F21: =APPRENANTS!V2 -> 0.77777778 | G21: ='WEDOF - EXAMEN FINAL'!M2 -> CV, CIN, 6 dossiers admin | H21: =APPRENANTS!W2 -> A RELANCER : Analyse du besoin, CV | I21: =APPRENANTS!X2 | J21: ='PAIEMENTS & COMMISSIONS'!L2 -> En retard - a verser | K21: =APPRENANTS!Y2 -> Oui
B22: =APPRENANTS!A3 -> Proforma Institut | C22: =APPRENANTS!B3 -> Frederic Roche | D22: =APPRENANTS!C3 -> Nedjma | E22: =APPRENANTS!U3 -> Analyse du besoin | F22: =APPRENANTS!V3 -> 0.88888889 | G22: ='WEDOF - EXAMEN FINAL'!M3 -> CIN | H22: =APPRENANTS!W3 -> A RELANCER : Analyse du besoin | I22: =APPRENANTS!X3 | J22: ='PAIEMENTS & COMMISSIONS'!L3 -> En retard - a verser | K22: =APPRENANTS!Y3 -> Oui
B23: =APPRENANTS!A4 -> Proforma Institut | C23: =APPRENANTS!B4 -> SIAF Kamla | D23: =APPRENANTS!C4 -> Nedjma | E23: =APPRENANTS!U4 -> Analyse du besoin, CV | F23: =APPRENANTS!V4 -> 0.77777778 | G23: ='WEDOF - EXAMEN FINAL'!M4 -> CV, CIN, 6 dossiers admin | H23: =APPRENANTS!W4 -> A RELANCER : Analyse du besoin, CV | I23: =APPRENANTS!X4 | J23: ='PAIEMENTS & COMMISSIONS'!L4 -> En retard - a verser | K23: =APPRENANTS!Y4 -> Oui
B24: =APPRENANTS!A5 -> Proforma Institut | C24: =APPRENANTS!B5 -> HAFIDHOU Mansouri | D24: =APPRENANTS!C5 -> Nedjma | E24: =APPRENANTS!U5 -> Analyse du besoin | F24: =APPRENANTS!V5 -> 0.88888889 | G24: ='WEDOF - EXAMEN FINAL'!M5 | H24: =APPRENANTS!W5 -> A RELANCER : Analyse du besoin | I24: =APPRENANTS!X5 | J24: ='PAIEMENTS & COMMISSIONS'!L5 -> En retard - a verser | K24: =APPRENANTS!Y5 -> Oui
B25: =APPRENANTS!A6 -> Proforma Institut | C25: =APPRENANTS!B6 -> DELGADO DA CRUZ Francisco | D25: =APPRENANTS!C6 -> Nedjma | E25: =APPRENANTS!U6 -> Analyse du besoin | F25: =APPRENANTS!V6 -> 0.88888889 | G25: ='WEDOF - EXAMEN FINAL'!M6 | H25: =APPRENANTS!W6 -> A RELANCER : Analyse du besoin | I25: =APPRENANTS!X6 | J25: ='PAIEMENTS & COMMISSIONS'!L6 -> En retard - a verser | K25: =APPRENANTS!Y6 -> Oui
B26: =APPRENANTS!A7 -> Proforma Institut | C26: =APPRENANTS!B7 -> DOUMENC Christophe | D26: =APPRENANTS!C7 -> Nedjma | E26: =APPRENANTS!U7 -> Analyse du besoin | F26: =APPRENANTS!V7 -> 0.88888889 | G26: ='WEDOF - EXAMEN FINAL'!M7 | H26: =APPRENANTS!W7 -> A RELANCER : Analyse du besoin | I26: =APPRENANTS!X7 | J26: ='PAIEMENTS & COMMISSIONS'!L7 -> En retard - a verser | K26: =APPRENANTS!Y7 -> Oui
B27: =APPRENANTS!A8 -> Proforma Institut | C27: =APPRENANTS!B8 -> AHAMADA BOURHANE Soilihi | D27: =APPRENANTS!C8 -> Nedjma | E27: =APPRENANTS!U8 -> Analyse du besoin, Document de fin | F27: =APPRENANTS!V8 -> 0.77777778 | G27: ='WEDOF - EXAMEN FINAL'!M8 | H27: =APPRENANTS!W8 -> A RELANCER : Analyse du besoin, Document de fin | I27: =APPRENANTS!X8 | J27: ='PAIEMENTS & COMMISSIONS'!L8 -> En retard - a verser | K27: =APPRENANTS!Y8 -> Oui
B28: =APPRENANTS!A9 -> Proforma Institut | C28: =APPRENANTS!B9 -> BENGUEDIH Kader | D28: =APPRENANTS!C9 -> Nedjma | E28: =APPRENANTS!U9 -> Analyse du besoin, Document de fin | F28: =APPRENANTS!V9 -> 0.77777778 | G28: ='WEDOF - EXAMEN FINAL'!M9 -> CIN | H28: =APPRENANTS!W9 -> A RELANCER : Analyse du besoin, Document de fin | I28: =APPRENANTS!X9 | J28: ='PAIEMENTS & COMMISSIONS'!L9 -> En retard - a verser | K28: =APPRENANTS!Y9 -> Oui
B29: =APPRENANTS!A10 -> Proforma Institut | C29: =APPRENANTS!B10 -> Julie Scotto D Aniello | D29: =APPRENANTS!C10 -> Sabri | E29: =APPRENANTS!U10 -> Analyse du besoin | F29: =APPRENANTS!V10 -> 0.88888889 | G29: ='WEDOF - EXAMEN FINAL'!M10 | H29: =APPRENANTS!W10 -> A RELANCER : Analyse du besoin | I29: =APPRENANTS!X10 | J29: ='PAIEMENTS & COMMISSIONS'!L10 -> En retard - a verser | K29: =APPRENANTS!Y10 -> Oui
B30: =APPRENANTS!A11 -> Proforma Institut | C30: =APPRENANTS!B11 -> Malik Benameur | D30: =APPRENANTS!C11 -> Sabri | E30: =APPRENANTS!U11 -> Analyse du besoin | F30: =APPRENANTS!V11 -> 0.88888889 | G30: ='WEDOF - EXAMEN FINAL'!M11 | H30: =APPRENANTS!W11 -> A RELANCER : Analyse du besoin | I30: =APPRENANTS!X11 | J30: ='PAIEMENTS & COMMISSIONS'!L11 -> En retard - a verser | K30: =APPRENANTS!Y11 -> Oui
B31: =APPRENANTS!A12 -> Proforma Institut | C31: =APPRENANTS!B12 -> LEROY Aurelie | D31: =APPRENANTS!C12 -> Sabri | E31: =APPRENANTS!U12 -> Analyse du besoin | F31: =APPRENANTS!V12 -> 0.88888889 | G31: ='WEDOF - EXAMEN FINAL'!M12 | H31: =APPRENANTS!W12 -> A RELANCER : Analyse du besoin | I31: =APPRENANTS!X12 | J31: ='PAIEMENTS & COMMISSIONS'!L12 -> En retard - a verser | K31: =APPRENANTS!Y12 -> Oui
B32: =APPRENANTS!A13 -> Proforma Institut | C32: =APPRENANTS!B13 -> SANIGOU Livan | D32: =APPRENANTS!C13 -> Sabri | E32: =APPRENANTS!U13 -> Analyse du besoin | F32: =APPRENANTS!V13 -> 0.88888889 | G32: ='WEDOF - EXAMEN FINAL'!M13 | H32: =APPRENANTS!W13 -> A RELANCER : Analyse du besoin | I32: =APPRENANTS!X13 | J32: ='PAIEMENTS & COMMISSIONS'!L13 -> En retard - a verser | K32: =APPRENANTS!Y13 -> Oui
... B172: =APPRENANTS!A153 -> Proskills Institut | C172: =APPRENANTS!B153 -> BOGGIO Andre | D172: =APPRENANTS!C153 -> Sabri | E172: =APPRENANTS!U153 -> Analyse du besoin, CV, Questionnaire/Test, Contrat, Convocation, Eval intermediaire, Eval finale, Questionnaire satisfaction, Document de fin | F172: =APPRENANTS!V153 -> 0 | G172: ='WEDOF - EXAMEN FINAL'!M153 -> CV, CIN, 6 dossiers admin, Convocation examen | H172: =APPRENANTS!W153 | I172: =APPRENANTS!X153 | J172: ='PAIEMENTS & COMMISSIONS'!L153 -> Inscription non confirmee | K172: =APPRENANTS!Y153 -> Non

Sheet APPRENANTS
A1: Organisme | B1: Nom | C1: Apporteur | D1: Formation | E1: Date debut session | F1: Date fin session | G1: Statut EDOF | H1: Adresse | I1: Email | J1: Telephone | K1: Date de naissance | L1: Analyse du besoin | M1: CV | N1: Questionnaire/Test | O1: Contrat | P1: Convocation | Q1: Eval intermediaire | R1: Eval finale | S1: Questionnaire satisfaction | T1: Document de fin | U1: Missions a faire | V1: % Avancement | W1: Alerte relance | X1: Alerte doublon | Y1: Inscription confirmee/payee (E)
A2: Proforma Institut | B2: Mohamed Ait Baha | C2: Djody | D2: Réaliser les opérations comptables courantes d'une TPE | E2: 2026-02-18 | F2: 2026-03-06 | G2: Payé | H2: 141 BD Maréchal Juin, 62110 HENIN BEAUMONT | I2: mohamed.aitbaha@hotmail.fr | J2: 782270615 | K2: 1982-09-04 | L2: A faire | M2: ='WEDOF - EXAMEN FINAL'!D2 -> A faire | N2: Fait | O2: Fait | P2: Fait | Q2: Fait | R2: Fait | S2: Fait | T2: Fait | U2: =TEXTJOIN(", ",TRUE(),IF($L2="A faire","Analyse du besoin",""),IF($M2="A faire","CV",""),IF($N2="A faire","Questionnaire/Test",""),IF($O2="A faire","Contrat",""),IF($P2="A faire","Convocation",""),IF($Q2="A faire","Eval intermediaire",""),IF($R2="A faire","Eval finale",""),IF($S2="A faire","Questionnaire satisfaction",""),IF($T2="A faire","Document de fin","")) -> Analyse du besoin, CV | V2: =COUNTIF(L2:T2,"Fait")/9 -> 0.77777778 | W2: =IF($F2="","",IF(AND(TODAY()>=(DATEVALUE($F2)+1),$U2<>""),"A RELANCER : "&$U2,"")) -> A RELANCER : Analyse du besoin, CV | X2: =IF(SUMPRODUCT(($B$2:$B$153=$B2)*($D$2:$D$153=$D2)*($E$2:$E$153=$E2)*($A$2:$A$153<>$A2))>0,"DOUBLON A VERIFIER","") | Y2: Oui
A3: Proforma Institut | B3: Frederic Roche | C3: Nedjma | D3: Réaliser les opérations comptables courantes d'une TPE | E3: 2026-02-18 | F3: 2026-03-06 | G3: Payé | H3: 10 AV Des mimosas, 13015 MARSEILLE | I3: fred_mars13@hotmail.fr | J3: 613637315 | K3: 18/02/1981 | L3: A faire | M3: ='WEDOF - EXAMEN FINAL'!D3 -> Fait | N3: Fait | O3: Fait | P3: Fait | Q3: Fait | R3: Fait | S3: Fait | T3: Fait | U3: =TEXTJOIN(", ",TRUE(),IF($L3="A faire","Analyse du besoin",""),IF($M3="A faire","CV",""),IF($N3="A faire","Questionnaire/Test",""),IF($O3="A faire","Contrat",""),IF($P3="A faire","Convocation",""),IF($Q3="A faire","Eval intermediaire",""),IF($R3="A faire","Eval finale",""),IF($S3="A faire","Questionnaire satisfaction",""),IF($T3="A faire","Document de fin","")) -> Analyse du besoin | V3: =COUNTIF(L3:T3,"Fait")/9 -> 0.88888889 | W3: =IF($F3="","",IF(AND(TODAY()>=(DATEVALUE($F3)+1),$U3<>""),"A RELANCER : "&$U3,"")) -> A RELANCER : Analyse du besoin | X3: =IF(SUMPRODUCT(($B$2:$B$153=$B3)*($D$2:$D$153=$D3)*($E$2:$E$153=$E3)*($A$2:$A$153<>$A3))>0,"DOUBLON A VERIFIER","") | Y3: Oui
A4: Proforma Institut | B4: SIAF Kamla | C4: Nedjma | D4: Réaliser les opérations comptables courantes d'une TPE | E4: 2026-03-09 | F4: 2026-03-27 | G4: Payé | H4: 171 AV du Merlan, 13014 MARSEILLE | I4: mimisiaf@gmail.com | J4: 629924780 | K4: 13/08/1965 | L4: A faire | M4: ='WEDOF - EXAMEN FINAL'!D4 -> A faire | N4: Fait | O4: Fait | P4: Fait | Q4: Fait | R4: Fait | S4: Fait | T4: Fait | U4: =TEXTJOIN(", ",TRUE(),IF($L4="A faire","Analyse du besoin",""),IF($M4="A faire","CV",""),IF($N4="A faire","Questionnaire/Test",""),IF($O4="A faire","Contrat",""),IF($P4="A faire","Convocation",""),IF($Q4="A faire","Eval intermediaire",""),IF($R4="A faire","Eval finale",""),IF($S4="A faire","Questionnaire satisfaction",""),IF($T4="A faire","Document de fin","")) -> Analyse du besoin, CV | V4: =COUNTIF(L4:T4,"Fait")/9 -> 0.77777778 | W4: =IF($F4="","",IF(AND(TODAY()>=(DATEVALUE($F4)+1),$U4<>""),"A RELANCER : "&$U4,"")) -> A RELANCER : Analyse du besoin, CV | X4: =IF(SUMPRODUCT(($B$2:$B$153=$B4)*($D$2:$D$153=$D4)*($E$2:$E$153=$E4)*($A$2:$A$153<>$A4))>0,"DOUBLON A VERIFIER","") | Y4: Oui
A5: Proforma Institut | B5: HAFIDHOU Mansouri | C5: Nedjma | D5: Réaliser les opérations comptables courantes d'une TPE | E5: 2026-03-09 | F5: 2026-03-27 | G5: Payé | H5: 178 AV Des chutes lavie, 13013 MARSEILLE | I5: mansourihafidou@gmail.com | J5: 763179407 | K5: 1990-07-05 | L5: A faire | M5: ='WEDOF - EXAMEN FINAL'!D5 -> Fait | N5: Fait | O5: Fait | P5: Fait | Q5: Fait | R5: Fait | S5: Fait | T5: Fait | U5: =TEXTJOIN(", ",TRUE(),IF($L5="A faire","Analyse du besoin",""),IF($M5="A faire","CV",""),IF($N5="A faire","Questionnaire/Test",""),IF($O5="A faire","Contrat",""),IF($P5="A faire","Convocation",""),IF($Q5="A faire","Eval intermediaire",""),IF($R5="A faire","Eval finale",""),IF($S5="A faire","Questionnaire satisfaction",""),IF($T5="A faire","Document de fin","")) -> Analyse du besoin | V5: =COUNTIF(L5:T5,"Fait")/9 -> 0.88888889 | W5: =IF($F5="","",IF(AND(TODAY()>=(DATEVALUE($F5)+1),$U5<>""),"A RELANCER : "&$U5,"")) -> A RELANCER : Analyse du besoin | X5: =IF(SUMPRODUCT(($B$2:$B$153=$B5)*($D$2:$D$153=$D5)*($E$2:$E$153=$E5)*($A$2:$A$153<>$A5))>0,"DOUBLON A VERIFIER","") | Y5: Oui
A6: Proforma Institut | B6: DELGADO DA CRUZ Francisco | C6: Nedjma | D6: Réaliser les opérations comptables courantes d'une TPE | E6: 2026-03-09 | F6: 2026-03-27 | G6: Payé | H6: 29 PTR Sainte victoire, 13006 MARSEILLE | I6: chicodelgado72@gmail.com | J6: 783823367 | K6: 1972-11-07 | L6: A faire | M6: ='WEDOF - EXAMEN FINAL'!D6 -> Fait | N6: Fait | O6: Fait | P6: Fait | Q6: Fait | R6: Fait | S6: Fait | T6: Fait | U6: =TEXTJOIN(", ",TRUE(),IF($L6="A faire","Analyse du besoin",""),IF($M6="A faire","CV",""),IF($N6="A faire","Questionnaire/Test",""),IF($O6="A faire","Contrat",""),IF($P6="A faire","Convocation",""),IF($Q6="A faire","Eval intermediaire",""),IF($R6="A faire","Eval finale",""),IF($S6="A faire","Questionnaire satisfaction",""),IF($T6="A faire","Document de fin","")) -> Analyse du besoin | V6: =COUNTIF(L6:T6,"Fait")/9 -> 0.88888889 | W6: =IF($F6="","",IF(AND(TODAY()>=(DATEVALUE($F6)+1),$U6<>""),"A RELANCER : "&$U6,"")) -> A RELANCER : Analyse du besoin | X6: =IF(SUMPRODUCT(($B$2:$B$153=$B6)*($D$2:$D$153=$D6)*($E$2:$E$153=$E6)*($A$2:$A$153<>$A6))>0,"DOUBLON A VERIFIER","") | Y6: Oui
A7: Proforma Institut | B7: DOUMENC Christophe | C7: Nedjma | D7: Réaliser les opérations comptables courantes d'une TPE | E7: 2026-03-09 | F7: 2026-03-27 | G7: Payé | H7: 16 RUE Nicolas copernic, 13013 MARSEILLE | I7: christophedoumenc13@gmail.com | J7: 681540974 | K7: 30/12/1972 | L7: A faire | M7: ='WEDOF - EXAMEN FINAL'!D7 -> Fait | N7: Fait | O7: Fait | P7: Fait | Q7: Fait | R7: Fait | S7: Fait | T7: Fait | U7: =TEXTJOIN(", ",TRUE(),IF($L7="A faire","Analyse du besoin",""),IF($M7="A faire","CV",""),IF($N7="A faire","Questionnaire/Test",""),IF($O7="A faire","Contrat",""),IF($P7="A faire","Convocation",""),IF($Q7="A faire","Eval intermediaire",""),IF($R7="A faire","Eval finale",""),IF($S7="A faire","Questionnaire satisfaction",""),IF($T7="A faire","Document de fin","")) -> Analyse du besoin | V7: =COUNTIF(L7:T7,"Fait")/9 -> 0.88888889 | W7: =IF($F7="","",IF(AND(TODAY()>=(DATEVALUE($F7)+1),$U7<>""),"A RELANCER : "&$U7,"")) -> A RELANCER : Analyse du besoin | X7: =IF(SUMPRODUCT(($B$2:$B$153=$B7)*($D$2:$D$153=$D7)*($E$2:$E$153=$E7)*($A$2:$A$153<>$A7))>0,"DOUBLON A VERIFIER","") | Y7: Oui
A8: Proforma Institut | B8: AHAMADA BOURHANE Soilihi | C8: Nedjma | D8: Réaliser les opérations comptables courantes d'une TPE | E8: 2026-03-30 | F8: 2026-04-17 | G8: FACTURE | H8: 257 AV Saint antoine, 13015 MARSEILLE | I8: ahamada.s@live.fr | J8: 652632912 | K8: 22/06/1991 | L8: A faire | M8: ='WEDOF - EXAMEN FINAL'!D8 -> Fait | N8: Fait | O8: Fait | P8: Fait | Q8: Fait | R8: Fait | S8: Fait | T8: A faire | U8: =TEXTJOIN(", ",TRUE(),IF($L8="A faire","Analyse du besoin",""),IF($M8="A faire","CV",""),IF($N8="A faire","Questionnaire/Test",""),IF($O8="A faire","Contrat",""),IF($P8="A faire","Convocation",""),IF($Q8="A faire","Eval intermediaire",""),IF($R8="A faire","Eval finale",""),IF($S8="A faire","Questionnaire satisfaction",""),IF($T8="A faire","Document de fin","")) -> Analyse du besoin, Document de fin | V8: =COUNTIF(L8:T8,"Fait")/9 -> 0.77777778 | W8: =IF($F8="","",IF(AND(TODAY()>=(DATEVALUE($F8)+1),$U8<>""),"A RELANCER : "&$U8,"")) -> A RELANCER : Analyse du besoin, Document de fin | X8: =IF(SUMPRODUCT(($B$2:$B$153=$B8)*($D$2:$D$153=$D8)*($E$2:$E$153=$E8)*($A$2:$A$153<>$A8))>0,"DOUBLON A VERIFIER","") | Y8: Oui
A9: Proforma Institut | B9: BENGUEDIH Kader | C9: Nedjma | D9: Réaliser les opérations comptables courantes d'une TPE | E9: 2026-03-30 | F9: 2026-04-17 | G9: FACTURE | H9: 130 CHE Château gombert, 13013 MARSEILLE | I9: Benguedihk@yahoo.fr | J9: 617440902 | K9: 19/08/1987 | L9: A faire | M9: ='WEDOF - EXAMEN FINAL'!D9 -> Fait | N9: Fait | O9: Fait | P9: Fait | Q9: Fait | R9: Fait | S9: Fait | T9: A faire | U9: =TEXTJOIN(", ",TRUE(),IF($L9="A faire","Analyse du besoin",""),IF($M9="A faire","CV",""),IF($N9="A faire","Questionnaire/Test",""),IF($O9="A faire","Contrat",""),IF($P9="A faire","Convocation",""),IF($Q9="A faire","Eval intermediaire",""),IF($R9="A faire","Eval finale",""),IF($S9="A faire","Questionnaire satisfaction",""),IF($T9="A faire","Document de fin","")) -> Analyse du besoin, Document de fin | V9: =COUNTIF(L9:T9,"Fait")/9 -> 0.77777778 | W9: =IF($F9="","",IF(AND(TODAY()>=(DATEVALUE($F9)+1),$U9<>""),"A RELANCER : "&$U9,"")) -> A RELANCER : Analyse du besoin, Document de fin | X9: =IF(SUMPRODUCT(($B$2:$B$153=$B9)*($D$2:$D$153=$D9)*($E$2:$E$153=$E9)*($A$2:$A$153<>$A9))>0,"DOUBLON A VERIFIER","") | Y9: Oui
A10: Proforma Institut | B10: Julie Scotto D Aniello | C10: Sabri | D10: Réaliser les opérations comptables courantes d'une TPE | E10: 2026-02-18 | F10: 2026-03-04 | G10: Payé | H10: 23 BD Boulevard Georges Clemenceau, 13700 MARIGNANE | I10: 13julie@free.fr | J10: 643092268 | K10: 1994-05-09 | L10: A faire | M10: ='WEDOF - EXAMEN FINAL'!D10 -> Fait | N10: Fait | O10: Fait | P10: Fait | Q10: Fait | R10: Fait | S10: Fait | T10: Fait | U10: =TEXTJOIN(", ",TRUE(),IF($L10="A faire","Analyse du besoin",""),IF($M10="A faire","CV",""),IF($N10="A faire","Questionnaire/Test",""),IF($O10="A faire","Contrat",""),IF($P10="A faire","Convocation",""),IF($Q10="A faire","Eval intermediaire",""),IF($R10="A faire","Eval finale",""),IF($S10="A faire","Questionnaire satisfaction",""),IF($T10="A faire","Document de fin","")) -> Analyse du besoin | V10: =COUNTIF(L10:T10,"Fait")/9 -> 0.88888889 | W10: =IF($F10="","",IF(AND(TODAY()>=(DATEVALUE($F10)+1),$U10<>""),"A RELANCER : "&$U10,"")) -> A RELANCER : Analyse du besoin | X10: =IF(SUMPRODUCT(($B$2:$B$153=$B10)*($D$2:$D$153=$D10)*($E$2:$E$153=$E10)*($A$2:$A$153<>$A10))>0,"DOUBLON A VERIFIER","") | Y10: Oui
A11: Proforma Institut | B11: Malik Benameur | C11: Sabri | D11: Réaliser les opérations comptables courantes d'une TPE | E11: 2026-02-20 | F11: 2026-03-11 | G11: Payé | H11: 12 RUE Pour la paix, 13120 GARDANNE | I11: Malik13950@gmail.com | J11: 608544404 | K11: 24/06/1994 | L11: A faire | M11: ='WEDOF - EXAMEN FINAL'!D11 -> Fait | N11: Fait | O11: Fait | P11: Fait | Q11: Fait | R11: Fait | S11: Fait | T11: Fait | U11: =TEXTJOIN(", ",TRUE(),IF($L11="A faire","Analyse du besoin",""),IF($M11="A faire","CV",""),IF($N11="A faire","Questionnaire/Test",""),IF($O11="A faire","Contrat",""),IF($P11="A faire","Convocation",""),IF($Q11="A faire","Eval intermediaire",""),IF($R11="A faire","Eval finale",""),IF($S11="A faire","Questionnaire satisfaction",""),IF($T11="A faire","Document de fin","")) -> Analyse du besoin | V11: =COUNTIF(L11:T11,"Fait")/9 -> 0.88888889 | W11: =IF($F11="","",IF(AND(TODAY()>=(DATEVALUE($F11)+1),$U11<>""),"A RELANCER : "&$U11,"")) -> A RELANCER : Analyse du besoin | X11: =IF(SUMPRODUCT(($B$2:$B$153=$B11)*($D$2:$D$153=$D11)*($E$2:$E$153=$E11)*($A$2:$A$153<>$A11))>0,"DOUBLON A VERIFIER","") | Y11: Oui
A12: Proforma Institut | B12: LEROY Aurelie | C12: Sabri | D12: Réaliser les opérations comptables courantes d'une TPE | E12: 2026-03-09 | F12: 2026-03-27 | G12: Payé | H12: 335 CHE Chemin des romarins, 13820 ENSUES LA REDONNE | I12: aurelie542@hotmail.fr | J12: 631344712 | K12: 1986-04-07 | L12: A faire | M12: ='WEDOF - EXAMEN FINAL'!D12 -> Fait | N12: Fait | O12: Fait | P12: Fait | Q12: Fait | R12: Fait | S12: Fait | T12: Fait | U12: =TEXTJOIN(", ",TRUE(),IF($L12="A faire","Analyse du besoin",""),IF($M12="A faire","CV",""),IF($N12="A faire","Questionnaire/Test",""),IF($O12="A faire","Contrat",""),IF($P12="A faire","Convocation",""),IF($Q12="A faire","Eval intermediaire",""),IF($R12="A faire","Eval finale",""),IF($S12="A faire","Questionnaire satisfaction",""),IF($T12="A faire","Document de fin","")) -> Analyse du besoin | V12: =COUNTIF(L12:T12,"Fait")/9 -> 0.88888889 | W12: =IF($F12="","",IF(AND(TODAY()>=(DATEVALUE($F12)+1),$U12<>""),"A RELANCER : "&$U12,"")) -> A RELANCER : Analyse du besoin | X12: =IF(SUMPRODUCT(($B$2:$B$153=$B12)*($D$2:$D$153=$D12)*($E$2:$E$153=$E12)*($A$2:$A$153<>$A12))>0,"DOUBLON A VERIFIER","") | Y12: Oui
A13: Proforma Institut | B13: SANIGOU Livan | C13: Sabri | D13: Réaliser les opérations comptables courantes d'une TPE | E13: 2026-03-09 | F13: 2026-03-27 | G13: Payé | H13: 1 IMP Du stade, 13080 AIX EN PROVENCE | I13: livansanigou@yahoo.fr | J13: 775959572 | K13: 19/10/1983 | L13: A faire | M13: ='WEDOF - EXAMEN FINAL'!D13 -> Fait | N13: Fait | O13: Fait | P13: Fait | Q13: Fait | R13: Fait | S13: Fait | T13: Fait | U13: =TEXTJOIN(", ",TRUE(),IF($L13="A faire","Analyse du besoin",""),IF($M13="A faire","CV",""),IF($N13="A faire","Questionnaire/Test",""),IF($O13="A faire","Contrat",""),IF($P13="A faire","Convocation",""),IF($Q13="A faire","Eval intermediaire",""),IF($R13="A faire","Eval finale",""),IF($S13="A faire","Questionnaire satisfaction",""),IF($T13="A faire","Document de fin","")) -> Analyse du besoin | V13: =COUNTIF(L13:T13,"Fait")/9 -> 0.88888889 | W13: =IF($F13="","",IF(AND(TODAY()>=(DATEVALUE($F13)+1),$U13<>""),"A RELANCER : "&$U13,"")) -> A RELANCER : Analyse du besoin | X13: =IF(SUMPRODUCT(($B$2:$B$153=$B13)*($D$2:$D$153=$D13)*($E$2:$E$153=$E13)*($A$2:$A$153<>$A13))>0,"DOUBLON A VERIFIER","") | Y13: Oui
... A29: Proforma Institut | B29: Alexandre Schmerber | C29: Sabri | D29: Développer son activité avec l’intelligence artificielle | E29: 2026-05-18 | F29: 2026-05-29 | G29: Payé | H29: 24 MTE De le belle france, 13015 MARSEILLE | I29: alexandre.schmerber@hotmail.com | J29: 699574950 | K29: 24/05/1993 | L29: A faire | M29: ='WEDOF - EXAMEN FINAL'!D29 -> A faire | N29: Fait | O29: A faire | P29: A faire | Q29: Fait | R29: Fait | S29: Fait | T29: A faire | U29: =TEXTJOIN(", ",TRUE(),IF($L29="A faire","Analyse du besoin",""),IF($M29="A faire","CV",""),IF($N29="A faire","Questionnaire/Test",""),IF($O29="A faire","Contrat",""),IF($P29="A faire","Convocation",""),IF($Q29="A faire","Eval intermediaire",""),IF($R29="A faire","Eval finale",""),IF($S29="A faire","Questionnaire satisfaction",""),IF($T29="A faire","Document de fin","")) -> Analyse du besoin, CV, Contrat, Convocation, Document de fin | V29: =COUNTIF(L29:T29,"Fait")/9 -> 0.44444444 | W29: =IF($F29="","",IF(AND(TODAY()>=(DATEVALUE($F29)+1),$U29<>""),"A RELANCER : "&$U29,"")) -> A RELANCER : Analyse du besoin, CV, Contrat, Convocation, Document de fin | X29: =IF(SUMPRODUCT(($B$2:$B$153=$B29)*($D$2:$D$153=$D29)*($E$2:$E$153=$E29)*($A$2:$A$153<>$A29))>0,"DOUBLON A VERIFIER","") | Y29: Oui
A30: Proforma Institut | B30: CHAFIL Amine | D30: Développer son activité avec l’intelligence artificielle | E30: 2026-06-08 | F30: 2026-06-13 | G30: Accepté | H30: 23 RUE Professeur marcel Arnaud, 13013 MARSEILLE | I30: amine_du_13010@hotmail.fr | J30: 624685745 | K30: 1990-11-07 | L30: A faire | M30: ='WEDOF - EXAMEN FINAL'!D30 -> A faire | N30: Fait | O30: A faire | P30: A faire | Q30: Fait | R30: Fait | S30: Fait | T30: A faire | U30: =TEXTJOIN(", ",TRUE(),IF($L30="A faire","Analyse du besoin",""),IF($M30="A faire","CV",""),IF($N30="A faire","Questionnaire/Test",""),IF($O30="A faire","Contrat",""),IF($P30="A faire","Convocation",""),IF($Q30="A faire","Eval intermediaire",""),IF($R30="A faire","Eval finale",""),IF($S30="A faire","Questionnaire satisfaction",""),IF($T30="A faire","Document de fin","")) -> Analyse du besoin, CV, Contrat, Convocation, Document de fin | V30: =COUNTIF(L30:T30,"Fait")/9 -> 0.44444444 | W30: =IF($F30="","",IF(AND(TODAY()>=(DATEVALUE($F30)+1),$U30<>""),"A RELANCER : "&$U30,"")) -> A RELANCER : Analyse du besoin, CV, Contrat, Convocation, Document de fin | X30: =IF(SUMPRODUCT(($B$2:$B$153=$B30)*($D$2:$D$153=$D30)*($E$2:$E$153=$E30)*($A$2:$A$153<>$A30))>0,"DOUBLON A VERIFIER","") | Y30: Oui
A31: Proforma Institut | B31: MARIOTTI Regis | C31: Sabri | D31: Développer son activité avec l’intelligence artificielle | E31: 2026-06-08 | F31: 2026-06-13 | G31: Accepté | H31: 11 TRA de la dominique, 13011 MARSEILLE | I31: regismariotti@hotmail.fr | J31: 612877388 | K31: 27/08/1977 | L31: A faire | M31: ='WEDOF - EXAMEN FINAL'!D31 -> A faire | N31: Fait | O31: A faire | P31: A faire | Q31: Fait | R31: Fait | S31: Fait | T31: A faire | U31: =TEXTJOIN(", ",TRUE(),IF($L31="A faire","Analyse du besoin",""),IF($M31="A faire","CV",""),IF($N31="A faire","Questionnaire/Test",""),IF($O31="A faire","Contrat",""),IF($P31="A faire","Convocation",""),IF($Q31="A faire","Eval intermediaire",""),IF($R31="A faire","Eval finale",""),IF($S31="A faire","Questionnaire satisfaction",""),IF($T31="A faire","Document de fin","")) -> Analyse du besoin, CV, Contrat, Convocation, Document de fin | V31: =COUNTIF(L31:T31,"Fait")/9 -> 0.44444444 | W31: =IF($F31="","",IF(AND(TODAY()>=(DATEVALUE($F31)+1),$U31<>""),"A RELANCER : "&$U31,"")) -> A RELANCER : Analyse du besoin, CV, Contrat, Convocation, Document de fin | X31: =IF(SUMPRODUCT(($B$2:$B$153=$B31)*($D$2:$D$153=$D31)*($E$2:$E$153=$E31)*($A$2:$A$153<>$A31))>0,"DOUBLON A VERIFIER","") | Y31: Oui
A32: Proforma Institut | B32: GAUTHEROT Pascal | C32: GRAS | D32: Améliorer l'efficacité de sa TPE à l'aide de l'IA | E32: 2026-06-15 | F32: 2026-06-20 | G32: Accepté | H32: 192 CHE du tour de l'étang, 13800 ISTRES | I32: pascal-gautherot@wanadoo.fr | J32: 689407179 | K32: 22/04/1966 | L32: A faire | M32: ='WEDOF - EXAMEN FINAL'!D32 -> A faire | N32: A faire | O32: A faire | P32: A faire | Q32: A faire | R32: A faire | S32: A faire | T32: A faire | U32: =TEXTJOIN(", ",TRUE(),IF($L32="A faire","Analyse du besoin",""),IF($M32="A faire","CV",""),IF($N32="A faire","Questionnaire/Test",""),IF($O32="A faire","Contrat",""),IF($P32="A faire","Convocation",""),IF($Q32="A faire","Eval intermediaire",""),IF($R32="A faire","Eval finale",""),IF($S32="A faire","Questionnaire satisfaction",""),IF($T32="A faire","Document de fin","")) -> Analyse du besoin, CV, Questionnaire/Test, Contrat, Convocation, Eval intermediaire, Eval finale, Questionnaire satisfaction, Document de fin | V32: =COUNTIF(L32:T32,"Fait")/9 -> 0 | W32: =IF($F32="","",IF(AND(TODAY()>=(DATEVALUE($F32)+1),$U32<>""),"A RELANCER : "&$U32,"")) -> A RELANCER : Analyse du besoin, CV, Questionnaire/Test, Contrat, Convocation, Eval intermediaire, Eval finale, Questionnaire satisfaction, Document de fin | X32: =IF(SUMPRODUCT(($B$2:$B$153=$B32)*($D$2:$D$153=$D32)*($E$2:$E$153=$E32)*($A$2:$A$153<>$A32))>0,"DOUBLON A VERIFIER","") | Y32: Oui
A33: Proforma Institut | B33: GAUTHEROT Pascal | C33: GRAS | D33: Communiquer sur les réseaux sociaux pour promouvoir sa TPE | E33: 2026-06-22 | F33: 2026-06-27 | G33: Accepté | H33: 192 CHE du tour de l'étang, 13800 ISTRES | I33: pascal-gautherot@wanadoo.fr | J33: 689407179 | K33: 22/04/1966 | L33: A faire | M33: ='WEDOF - EXAMEN FINAL'!D33 -> A faire | N33: A faire | O33: A faire | P33: A faire | Q33: A faire | R33: A faire | S33: A faire | T33: A faire | U33: =TEXTJOIN(", ",TRUE(),IF($L33="A faire","Analyse du besoin",""),IF($M33="A faire","CV",""),IF($N33="A faire","Questionnaire/Test",""),IF($O33="A faire","Contrat",""),IF($P33="A faire","Convocation",""),IF($Q33="A faire","Eval intermediaire",""),IF($R33="A faire","Eval finale",""),IF($S33="A faire","Questionnaire satisfaction",""),IF($T33="A faire","Document de fin","")) -> Analyse du besoin, CV, Questionnaire/Test, Contrat, Convocation, Eval intermediaire, Eval finale, Questionnaire satisfaction, Document de fin | V33: =COUNTIF(L33:T33,"Fait")/9 -> 0 | W33: =IF($F33="","",IF(AND(TODAY()>=(DATEVALUE($F33)+1),$U33<>""),"A RELANCER : "&$U33,"")) -> A RELANCER : Analyse du besoin, CV, Questionnaire/Test, Contrat, Convocation, Eval intermediaire, Eval finale, Questionnaire satisfaction, Document de fin | X33: =IF(SUMPRODUCT(($B$2:$B$153=$B33)*($D$2:$D$153=$D33)*($E$2:$E$153=$E33)*($A$2:$A$153<>$A33))>0,"DOUBLON A VERIFIER","") | Y33: Oui
A34: Proforma Institut | B34: GAUTHEROT Pascal | C34: GRAS | D34: Réaliser les opérations comptables courantes d'une TPE | E34: 2026-06-29 | F34: 2026-07-04 | G34: Accepté | H34: 192 CHE du tour de l'étang, 13800 ISTRES | I34: pascal-gautherot@wanadoo.fr | J34: 689407179 | K34: 22/04/1966 | L34: A faire | M34: ='WEDOF - EXAMEN FINAL'!D34 -> A faire | N34: A faire | O34: A faire | P34: A faire | Q34: A faire | R34: A faire | S34: A faire | T34: A faire | U34: =TEXTJOIN(", ",TRUE(),IF($L34="A faire","Analyse du besoin",""),IF($M34="A faire","CV",""),IF($N34="A faire","Questionnaire/Test",""),IF($O34="A faire","Contrat",""),IF($P34="A faire","Convocation",""),IF($Q34="A faire","Eval intermediaire",""),IF($R34="A faire","Eval finale",""),IF($S34="A faire","Questionnaire satisfaction",""),IF($T34="A faire","Document de fin","")) -> Analyse du besoin, CV, Questionnaire/Test, Contrat, Convocation, Eval intermediaire, Eval finale, Questionnaire satisfaction, Document de fin | V34: =COUNTIF(L34:T34,"Fait")/9 -> 0 | W34: =IF($F34="","",IF(AND(TODAY()>=(DATEVALUE($F34)+1),$U34<>""),"A RELANCER : "&$U34,"")) -> A RELANCER : Analyse du besoin, CV, Questionnaire/Test, Contrat, Convocation, Eval intermediaire, Eval finale, Questionnaire satisfaction, Document de fin | X34: =IF(SUMPRODUCT(($B$2:$B$153=$B34)*($D$2:$D$153=$D34)*($E$2:$E$153=$E34)*($A$2:$A$153<>$A34))>0,"DOUBLON A VERIFIER","") | Y34: Oui
A35: Proforma Institut | B35: VIRAPHONG Thuy | C35: jules | D35: Développer son activité avec l’intelligence artificielle | E35: 2026-06-15 | F35: 2026-06-20 | G35: Accepté | H35: 81 CHE De figuerolles, 13180 GIGNAC LA NERTHE | I35: johana131@gmail.com | J35: 769874867 | K35: 15/10/1989 | L35: A faire | M35: ='WEDOF - EXAMEN FINAL'!D35 -> A faire | N35: Fait | O35: A faire | P35: A faire | Q35: Fait | R35: Fait | S35: Fait | T35: A faire | U35: =TEXTJOIN(", ",TRUE(),IF($L35="A faire","Analyse du besoin",""),IF($M35="A faire","CV",""),IF($N35="A faire","Questionnaire/Test",""),IF($O35="A faire","Contrat",""),IF($P35="A faire","Convocation",""),IF($Q35="A faire","Eval intermediaire",""),IF($R35="A faire","Eval finale",""),IF($S35="A faire","Questionnaire satisfaction",""),IF($T35="A faire","Document de fin","")) -> Analyse du besoin, CV, Contrat, Convocation, Document de fin | V35: =COUNTIF(L35:T35,"Fait")/9 -> 0.44444444 | W35: =IF($F35="","",IF(AND(TODAY()>=(DATEVALUE($F35)+1),$U35<>""),"A RELANCER : "&$U35,"")) -> A RELANCER : Analyse du besoin, CV, Contrat, Convocation, Document de fin | X35: =IF(SUMPRODUCT(($B$2:$B$153=$B35)*($D$2:$D$153=$D35)*($E$2:$E$153=$E35)*($A$2:$A$153<>$A35))>0,"DOUBLON A VERIFIER","") | Y35: Oui
A36: Proforma Institut | B36: POGGI Eric | C36: Sabri | E36: 2026-06-15 | F36: 2026-06-20 | G36: Accepté | L36: A faire | M36: ='WEDOF - EXAMEN FINAL'!D36 -> A faire | N36: Fait | O36: A faire | P36: A faire | Q36: A faire | R36: A faire | S36: A faire | T36: A faire | U36: =TEXTJOIN(", ",TRUE(),IF($L36="A faire","Analyse du besoin",""),IF($M36="A faire","CV",""),IF($N36="A faire","Questionnaire/Test",""),IF($O36="A faire","Contrat",""),IF($P36="A faire","Convocation",""),IF($Q36="A faire","Eval intermediaire",""),IF($R36="A faire","Eval finale",""),IF($S36="A faire","Questionnaire satisfaction",""),IF($T36="A faire","Document de fin","")) -> Analyse du besoin, CV, Contrat, Convocation, Eval intermediaire, Eval finale, Questionnaire satisfaction, Document de fin | V36: =COUNTIF(L36:T36,"Fait")/9 -> 0.11111111 | W36: =IF($F36="","",IF(AND(TODAY()>=(DATEVALUE($F36)+1),$U36<>""),"A RELANCER : "&$U36,"")) -> A RELANCER : Analyse du besoin, CV, Contrat, Convocation, Eval intermediaire, Eval finale, Questionnaire satisfaction, Document de fin | X36: =IF(SUMPRODUCT(($B$2:$B$153=$B36)*($D$2:$D$153=$D36)*($E$2:$E$153=$E36)*($A$2:$A$153<>$A36))>0,"DOUBLON A VERIFIER","") | Y36: Oui
A37: Proforma Institut | B37: POGGI Eric | C37: Sabri | D37: Communiquer sur les réseaux sociaux pour promouvoir sa TPE | E37: 2026-06-22 | F37: 2026-06-27 | G37: Accepté | L37: A faire | M37: ='WEDOF - EXAMEN FINAL'!D37 -> A faire | N37: Fait | O37: A faire | P37: A faire | Q37: A faire | R37: A faire | S37: A faire | T37: A faire | U37: =TEXTJOIN(", ",TRUE(),IF($L37="A faire","Analyse du besoin",""),IF($M37="A faire","CV",""),IF($N37="A faire","Questionnaire/Test",""),IF($O37="A faire","Contrat",""),IF($P37="A faire","Convocation",""),IF($Q37="A faire","Eval intermediaire",""),IF($R37="A faire","Eval finale",""),IF($S37="A faire","Questionnaire satisfaction",""),IF($T37="A faire","Document de fin","")) -> Analyse du besoin, CV, Contrat, Convocation, Eval intermediaire, Eval finale, Questionnaire satisfaction, Document de fin | V37: =COUNTIF(L37:T37,"Fait")/9 -> 0.11111111 | W37: =IF($F37="","",IF(AND(TODAY()>=(DATEVALUE($F37)+1),$U37<>""),"A RELANCER : "&$U37,"")) -> A RELANCER : Analyse du besoin, CV, Contrat, Convocation, Eval intermediaire, Eval finale, Questionnaire satisfaction, Document de fin | X37: =IF(SUMPRODUCT(($B$2:$B$153=$B37)*($D$2:$D$153=$D37)*($E$2:$E$153=$E37)*($A$2:$A$153<>$A37))>0,"DOUBLON A VERIFIER","") | Y37: Oui
A38: Proforma Institut | B38: MENDY Jean | C38: jean | D38: Développer son activité avec l’intelligence artificielle | E38: 2026-06-15 | F38: 2026-06-20 | G38: Accepté | H38: 11 CDEP Chemin des broutieres, 13015 MARSEILLE | I38: mendyjean1207@gmail.com | J38: 784862602 | K38: 1987-12-07 | L38: A faire | M38: ='WEDOF - EXAMEN FINAL'!D38 -> A faire | N38: Fait | O38: A faire | P38: A faire | Q38: Fait | R38: Fait | S38: Fait | T38: A faire | U38: =TEXTJOIN(", ",TRUE(),IF($L38="A faire","Analyse du besoin",""),IF($M38="A faire","CV",""),IF($N38="A faire","Questionnaire/Test",""),IF($O38="A faire","Contrat",""),IF($P38="A faire","Convocation",""),IF($Q38="A faire","Eval intermediaire",""),IF($R38="A faire","Eval finale",""),IF($S38="A faire","Questionnaire satisfaction",""),IF($T38="A faire","Document de fin","")) -> Analyse du besoin, CV, Contrat, Convocation, Document de fin | V38: =COUNTIF(L38:T38,"Fait")/9 -> 0.44444444 | W38: =IF($F38="","",IF(AND(TODAY()>=(DATEVALUE($F38)+1),$U38<>""),"A RELANCER : "&$U38,"")) -> A RELANCER : Analyse du besoin, CV, Contrat, Convocation, Document de fin | X38: =IF(SUMPRODUCT(($B$2:$B$153=$B38)*($D$2:$D$153=$D38)*($E$2:$E$153=$E38)*($A$2:$A$153<>$A38))>0,"DOUBLON A VERIFIER","") | Y38: Oui
A39: Proforma Institut | B39: BOUASRIA Najwa | C39: frere karim | D39: Développer son activité avec l’intelligence artificielle | E39: 2026-06-15 | F39: 2026-06-20 | G39: Accepté | H39: AV Marius Ruinat, 13700 MARIGNANE | I39: najwa.bouasria@gmail.com | J39: 761272644 | K39: 1997-06-09 | L39: A faire | M39: ='WEDOF - EXAMEN FINAL'!D39 -> A faire | N39: Fait | O39: A faire | P39: A faire | Q39: Fait | R39: Fait | S39: Fait | T39: A faire | U39: =TEXTJOIN(", ",TRUE(),IF($L39="A faire","Analyse du besoin",""),IF($M39="A faire","CV",""),IF($N39="A faire","Questionnaire/Test",""),IF($O39="A faire","Contrat",""),IF($P39="A faire","Convocation",""),IF($Q39="A faire","Eval intermediaire",""),IF($R39="A faire","Eval finale",""),IF($S39="A faire","Questionnaire satisfaction",""),IF($T39="A faire","Document de fin","")) -> Analyse du besoin, CV, Contrat, Convocation, Document de fin | V39: =COUNTIF(L39:T39,"Fait")/9 -> 0.44444444 | W39: =IF($F39="","",IF(AND(TODAY()>=(DATEVALUE($F39)+1),$U39<>""),"A RELANCER : "&$U39,"")) -> A RELANCER : Analyse du besoin, CV, Contrat, Convocation, Document de fin | X39: =IF(SUMPRODUCT(($B$2:$B$153=$B39)*($D$2:$D$153=$D39)*($E$2:$E$153=$E39)*($A$2:$A$153<>$A39))>0,"DOUBLON A VERIFIER","") | Y39: Oui
A40: Proforma Institut | B40: JAVAZZO Jerome | C40: hak | D40: Améliorer l'efficacité de sa TPE à l'aide de l'IA | E40: 2026-06-29 | F40: 2026-07-04 | G40: Accepté | L40: A faire | M40: ='WEDOF - EXAMEN FINAL'!D40 -> A faire | N40: A faire | O40: A faire | P40: A faire | Q40: A faire | R40: A faire | S40: A faire | T40: A faire | U40: =TEXTJOIN(", ",TRUE(),IF($L40="A faire","Analyse du besoin",""),IF($M40="A faire","CV",""),IF($N40="A faire","Questionnaire/Test",""),IF($O40="A faire","Contrat",""),IF($P40="A faire","Convocation",""),IF($Q40="A faire","Eval intermediaire",""),IF($R40="A faire","Eval finale",""),IF($S40="A faire","Questionnaire satisfaction",""),IF($T40="A faire","Document de fin","")) -> Analyse du besoin, CV, Questionnaire/Test, Contrat, Convocation, Eval intermediaire, Eval finale, Questionnaire satisfaction, Document de fin | V40: =COUNTIF(L40:T40,"Fait")/9 -> 0 | W40: =IF($F40="","",IF(AND(TODAY()>=(DATEVALUE($F40)+1),$U40<>""),"A RELANCER : "&$U40,"")) -> A RELANCER : Analyse du besoin, CV, Questionnaire/Test, Contrat, Convocation, Eval intermediaire, Eval finale, Questionnaire satisfaction, Document de fin | X40: =IF(SUMPRODUCT(($B$2:$B$153=$B40)*($D$2:$D$153=$D40)*($E$2:$E$153=$E40)*($A$2:$A$153<>$A40))>0,"DOUBLON A VERIFIER","") | Y40: Oui
A41: Proforma Institut | B41: JAVAZZO Jerome | C41: hak | D41: Communiquer sur les réseaux sociaux pour promouvoir sa TPE | E41: 2026-06-22 | F41: 2026-06-27 | G41: Accepté | L41: A faire | M41: ='WEDOF - EXAMEN FINAL'!D41 -> A faire | N41: A faire | O41: A faire | P41: A faire | Q41: A faire | R41: A faire | S41: A faire | T41: A faire | U41: =TEXTJOIN(", ",TRUE(),IF($L41="A faire","Analyse du besoin",""),IF($M41="A faire","CV",""),IF($N41="A faire","Questionnaire/Test",""),IF($O41="A faire","Contrat",""),IF($P41="A faire","Convocation",""),IF($Q41="A faire","Eval intermediaire",""),IF($R41="A faire","Eval finale",""),IF($S41="A faire","Questionnaire satisfaction",""),IF($T41="A faire","Document de fin","")) -> Analyse du besoin, CV, Questionnaire/Test, Contrat, Convocation, Eval intermediaire, Eval finale, Questionnaire satisfaction, Document de fin | V41: =COUNTIF(L41:T41,"Fait")/9 -> 0 | W41: =IF($F41="","",IF(AND(TODAY()>=(DATEVALUE($F41)+1),$U41<>""),"A RELANCER : "&$U41,"")) -> A RELANCER : Analyse du besoin, CV, Questionnaire/Test, Contrat, Convocation, Eval intermediaire, Eval finale, Questionnaire satisfaction, Document de fin | X41: =IF(SUMPRODUCT(($B$2:$B$153=$B41)*($D$2:$D$153=$D41)*($E$2:$E$153=$E41)*($A$2:$A$153<>$A41))>0,"DOUBLON A VERIFIER","") | Y41: Oui
A42: Proforma Institut | B42: KECHIOUCHE Younes | C42: hak | D42: Développer son activité avec l’intelligence artificielle | E42: 2026-06-22 | F42: 2026-06-27 | G42: Accepté | L42: A faire | M42: ='WEDOF - EXAMEN FINAL'!D42 -> A faire | N42: A faire | O42: A faire | P42: A faire | Q42: Fait | R42: Fait | S42: Fait | T42: A faire | U42: =TEXTJOIN(", ",TRUE(),IF($L42="A faire","Analyse du besoin",""),IF($M42="A faire","CV",""),IF($N42="A faire","Questionnaire/Test",""),IF($O42="A faire","Contrat",""),IF($P42="A faire","Convocation",""),IF($Q42="A faire","Eval intermediaire",""),IF($R42="A faire","Eval finale",""),IF($S42="A faire","Questionnaire satisfaction",""),IF($T42="A faire","Document de fin","")) -> Analyse du besoin, CV, Questionnaire/Test, Contrat, Convocation, Document de fin | V42: =COUNTIF(L42:T42,"Fait")/9 -> 0.33333333 | W42: =IF($F42="","",IF(AND(TODAY()>=(DATEVALUE($F42)+1),$U42<>""),"A RELANCER : "&$U42,"")) -> A RELANCER : Analyse du besoin, CV, Questionnaire/Test, Contrat, Convocation, Document de fin | X42: =IF(SUMPRODUCT(($B$2:$B$153=$B42)*($D$2:$D$153=$D42)*($E$2:$E$153=$E42)*($A$2:$A$153<>$A42))>0,"DOUBLON A VERIFIER","") | Y42: Oui
A43: Proforma Institut | B43: LAHRAOUI Amir | C43: GRAS | D43: Améliorer l'efficacité de sa TPE à l'aide de l'IA | E43: 2026-06-29 | F43: 2026-07-04 | G43: Accepté | L43: A faire | M43: ='WEDOF - EXAMEN FINAL'!D43 -> A faire | N43: A faire | O43: A faire | P43: A faire | Q43: A faire | R43: A faire | S43: A faire | T43: A faire | U43: =TEXTJOIN(", ",TRUE(),IF($L43="A faire","Analyse du besoin",""),IF($M43="A faire","CV",""),IF($N43="A faire","Questionnaire/Test",""),IF($O43="A faire","Contrat",""),IF($P43="A faire","Convocation",""),IF($Q43="A faire","Eval intermediaire",""),IF($R43="A faire","Eval finale",""),IF($S43="A faire","Questionnaire satisfaction",""),IF($T43="A faire","Document de fin","")) -> Analyse du besoin, CV, Questionnaire/Test, Contrat, Convocation, Eval intermediaire, Eval finale, Questionnaire satisfaction, Document de fin | V43: =COUNTIF(L43:T43,"Fait")/9 -> 0 | W43: =IF($F43="","",IF(AND(TODAY()>=(DATEVALUE($F43)+1),$U43<>""),"A RELANCER : "&$U43,"")) -> A RELANCER : Analyse du besoin, CV, Questionnaire/Test, Contrat, Convocation, Eval intermediaire, Eval finale, Questionnaire satisfaction, Document de fin | X43: =IF(SUMPRODUCT(($B$2:$B$153=$B43)*($D$2:$D$153=$D43)*($E$2:$E$153=$E43)*($A$2:$A$153<>$A43))>0,"DOUBLON A VERIFIER","") | Y43: Oui
A44: Proforma Institut | B44: LAHRAOUI Amir | C44: GRAS | D44: Communiquer sur les réseaux sociaux pour promouvoir sa TPE | E44: 2026-07-06 | F44: 2026-07-11 | G44: Accepté | L44: A faire | M44: ='WEDOF - EXAMEN FINAL'!D44 -> A faire | N44: A faire | O44: A faire | P44: A faire | Q44: A faire | R44: A faire | S44: A faire | T44: A faire | U44: =TEXTJOIN(", ",TRUE(),IF($L44="A faire","Analyse du besoin",""),IF($M44="A faire","CV",""),IF($N44="A faire","Questionnaire/Test",""),IF($O44="A faire","Contrat",""),IF($P44="A faire","Convocation",""),IF($Q44="A faire","Eval intermediaire",""),IF($R44="A faire","Eval finale",""),IF($S44="A faire","Questionnaire satisfaction",""),IF($T44="A faire","Document de fin","")) -> Analyse du besoin, CV, Questionnaire/Test, Contrat, Convocation, Eval intermediaire, Eval finale, Questionnaire satisfaction, Document de fin | V44: =COUNTIF(L44:T44,"Fait")/9 -> 0 | W44: =IF($F44="","",IF(AND(TODAY()>=(DATEVALUE($F44)+1),$U44<>""),"A RELANCER : "&$U44,"")) -> A RELANCER : Analyse du besoin, CV, Questionnaire/Test, Contrat, Convocation, Eval intermediaire, Eval finale, Questionnaire satisfaction, Document de fin | X44: =IF(SUMPRODUCT(($B$2:$B$153=$B44)*($D$2:$D$153=$D44)*($E$2:$E$153=$E44)*($A$2:$A$153<>$A44))>0,"DOUBLON A VERIFIER","") | Y44: Oui
A45: Proforma Institut | B45: LAHRAOUI Amir | C45: GRAS | D45: Réaliser les opérations comptables courantes d'une TPE | E45: 2026-07-13 | F45: 2026-07-18 | G45: Accepté | L45: A faire | M45: ='WEDOF - EXAMEN FINAL'!D45 -> A faire | N45: A faire | O45: A faire | P45: A faire | Q45: A faire | R45: A faire | S45: A faire | T45: A faire | U45: =TEXTJOIN(", ",TRUE(),IF($L45="A faire","Analyse du besoin",""),IF($M45="A faire","CV",""),IF($N45="A faire","Questionnaire/Test",""),IF($O45="A faire","Contrat",""),IF($P45="A faire","Convocation",""),IF($Q45="A faire","Eval intermediaire",""),IF($R45="A faire","Eval finale",""),IF($S45="A faire","Questionnaire satisfaction",""),IF($T45="A faire","Document de fin","")) -> Analyse du besoin, CV, Questionnaire/Test, Contrat, Convocation, Eval intermediaire, Eval finale, Questionnaire satisfaction, Document de fin | V45: =COUNTIF(L45:T45,"Fait")/9 -> 0 | W45: =IF($F45="","",IF(AND(TODAY()>=(DATEVALUE($F45)+1),$U45<>""),"A RELANCER : "&$U45,"")) -> A RELANCER : Analyse du besoin, CV, Questionnaire/Test, Contrat, Convocation, Eval intermediaire, Eval finale, Questionnaire satisfaction, Document de fin | X45: =IF(SUMPRODUCT(($B$2:$B$153=$B45)*($D$2:$D$153=$D45)*($E$2:$E$153=$E45)*($A$2:$A$153<>$A45))>0,"DOUBLON A VERIFIER","") | Y45: Oui
A46: Proforma Institut | B46: blot valerie | C46: Djody | D46: Réaliser les opérations comptables courantes d'une TPE | E46: 2026-06-24 | F46: 2026-07-24 | G46: Accepté | L46: A faire | M46: ='WEDOF - EXAMEN FINAL'!D46 -> A faire | N46: A faire | O46: A faire | P46: A faire | Q46: A faire | R46: A faire | S46: A faire | T46: A faire | U46: =TEXTJOIN(", ",TRUE(),IF($L46="A faire","Analyse du besoin",""),IF($M46="A faire","CV",""),IF($N46="A faire","Questionnaire/Test",""),IF($O46="A faire","Contrat",""),IF($P46="A faire","Convocation",""),IF($Q46="A faire","Eval intermediaire",""),IF($R46="A faire","Eval finale",""),IF($S46="A faire","Questionnaire satisfaction",""),IF($T46="A faire","Document de fin","")) -> Analyse du besoin, CV, Questionnaire/Test, Contrat, Convocation, Eval intermediaire, Eval finale, Questionnaire satisfaction, Document de fin | V46: =COUNTIF(L46:T46,"Fait")/9 -> 0 | W46: =IF($F46="","",IF(AND(TODAY()>=(DATEVALUE($F46)+1),$U46<>""),"A RELANCER : "&$U46,"")) | X46: =IF(SUMPRODUCT(($B$2:$B$153=$B46)*($D$2:$D$153=$D46)*($E$2:$E$153=$E46)*($A$2:$A$153<>$A46))>0,"DOUBLON A VERIFIER","") | Y46: Oui
A47: Proforma Institut | B47: CARRETTA Capucine | C47: jules | D47: Développer son activité avec l’intelligence artificielle | E47: 2026-06-29 | F47: 2026-07-04 | G47: Accepté | L47: A faire | M47: ='WEDOF - EXAMEN FINAL'!D47 -> A faire | N47: A faire | O47: A faire | P47: A faire | Q47: Fait | R47: Fait | S47: Fait | T47: A faire | U47: =TEXTJOIN(", ",TRUE(),IF($L47="A faire","Analyse du besoin",""),IF($M47="A faire","CV",""),IF($N47="A faire","Questionnaire/Test",""),IF($O47="A faire","Contrat",""),IF($P47="A faire","Convocation",""),IF($Q47="A faire","Eval intermediaire",""),IF($R47="A faire","Eval finale",""),IF($S47="A faire","Questionnaire satisfaction",""),IF($T47="A faire","Document de fin","")) -> Analyse du besoin, CV, Questionnaire/Test, Contrat, Convocation, Document de fin | V47: =COUNTIF(L47:T47,"Fait")/9 -> 0.33333333 | W47: =IF($F47="","",IF(AND(TODAY()>=(DATEVALUE($F47)+1),$U47<>""),"A RELANCER : "&$U47,"")) -> A RELANCER : Analyse du besoin, CV, Questionnaire/Test, Contrat, Convocation, Document de fin | X47: =IF(SUMPRODUCT(($B$2:$B$153=$B47)*($D$2:$D$153=$D47)*($E$2:$E$153=$E47)*($A$2:$A$153<>$A47))>0,"DOUBLON A VERIFIER","") | Y47: Oui
A48: Proforma Institut | B48: OUAHAB Yanis | C48: priscot | D48: Améliorer l'efficacité de sa TPE à l'aide de l'IA | E48: 2026-06-29 | F48: 2026-07-04 | G48: Accepté | L48: A faire | M48: ='WEDOF - EXAMEN FINAL'!D48 -> A faire | N48: A faire | O48: A faire | P48: A faire | Q48: A faire | R48: A faire | S48: A faire | T48: A faire | U48: =TEXTJOIN(", ",TRUE(),IF($L48="A faire","Analyse du besoin",""),IF($M48="A faire","CV",""),IF($N48="A faire","Questionnaire/Test",""),IF($O48="A faire","Contrat",""),IF($P48="A faire","Convocation",""),IF($Q48="A faire","Eval intermediaire",""),IF($R48="A faire","Eval finale",""),IF($S48="A faire","Questionnaire satisfaction",""),IF($T48="A faire","Document de fin","")) -> Analyse du besoin, CV, Questionnaire/Test, Contrat, Convocation, Eval intermediaire, Eval finale, Questionnaire satisfaction, Document de fin | V48: =COUNTIF(L48:T48,"Fait")/9 -> 0 | W48: =IF($F48="","",IF(AND(TODAY()>=(DATEVALUE($F48)+1),$U48<>""),"A RELANCER : "&$U48,"")) -> A RELANCER : Analyse du besoin, CV, Questionnaire/Test, Contrat, Convocation, Eval intermediaire, Eval finale, Questionnaire satisfaction, Document de fin | X48: =IF(SUMPRODUCT(($B$2:$B$153=$B48)*($D$2:$D$153=$D48)*($E$2:$E$153=$E48)*($A$2:$A$153<>$A48))>0,"DOUBLON A VERIFIER","") | Y48: Oui
A49: Proforma Institut | B49: OUAHAB Yanis | C49: priscot | D49: Communiquer sur les réseaux sociaux pour promouvoir sa TPE | E49: 2026-07-06 | F49: 2026-07-11 | G49: Accepté | L49: A faire | M49: ='WEDOF - EXAMEN FINAL'!D49 -> A faire | N49: A faire | O49: A faire | P49: A faire | Q49: A faire | R49: A faire | S49: A faire | T49: A faire | U49: =TEXTJOIN(", ",TRUE(),IF($L49="A faire","Analyse du besoin",""),IF($M49="A faire","CV",""),IF($N49="A faire","Questionnaire/Test",""),IF($O49="A faire","Contrat",""),IF($P49="A faire","Convocation",""),IF($Q49="A faire","Eval intermediaire",""),IF($R49="A faire","Eval finale",""),IF($S49="A faire","Questionnaire satisfaction",""),IF($T49="A faire","Document de fin","")) -> Analyse du besoin, CV, Questionnaire/Test, Contrat, Convocation, Eval intermediaire, Eval finale, Questionnaire satisfaction, Document de fin | V49: =COUNTIF(L49:T49,"Fait")/9 -> 0 | W49: =IF($F49="","",IF(AND(TODAY()>=(DATEVALUE($F49)+1),$U49<>""),"A RELANCER : "&$U49,"")) -> A RELANCER : Analyse du besoin, CV, Questionnaire/Test, Contrat, Convocation, Eval intermediaire, Eval finale, Questionnaire satisfaction, Document de fin | X49: =IF(SUMPRODUCT(($B$2:$B$153=$B49)*($D$2:$D$153=$D49)*($E$2:$E$153=$E49)*($A$2:$A$153<>$A49))>0,"DOUBLON A VERIFIER","") | Y49: Oui
A50: Proforma Institut | B50: DJIBILIAN Yoann | C50: Nedjma | D50: Améliorer l'efficacité de sa TPE à l'aide de l'IA | E50: 2026-06-29 | F50: 2026-07-04 | G50: Accepté | H50: 18 PL place d'Amont, 13390 AURIOL | I50: yoann.djibilian@laposte.net | J50: 645742336 | K50: 26/09/1999 | L50: A faire | M50: ='WEDOF - EXAMEN FINAL'!D50 -> A faire | N50: A faire | O50: A faire | P50: A faire | Q50: A faire | R50: A faire | S50: A faire | T50: A faire | U50: =TEXTJOIN(", ",TRUE(),IF($L50="A faire","Analyse du besoin",""),IF($M50="A faire","CV",""),IF($N50="A faire","Questionnaire/Test",""),IF($O50="A faire","Contrat",""),IF($P50="A faire","Convocation",""),IF($Q50="A faire","Eval intermediaire",""),IF($R50="A faire","Eval finale",""),IF($S50="A faire","Questionnaire satisfaction",""),IF($T50="A faire","Document de fin","")) -> Analyse du besoin, CV, Questionnaire/Test, Contrat, Convocation, Eval intermediaire, Eval finale, Questionnaire satisfaction, Document de fin | V50: =COUNTIF(L50:T50,"Fait")/9 -> 0 | W50: =IF($F50="","",IF(AND(TODAY()>=(DATEVALUE($F50)+1),$U50<>""),"A RELANCER : "&$U50,"")) -> A RELANCER : Analyse du besoin, CV, Questionnaire/Test, Contrat, Convocation, Eval intermediaire, Eval finale, Questionnaire satisfaction, Document de fin | X50: =IF(SUMPRODUCT(($B$2:$B$153=$B50)*($D$2:$D$153=$D50)*($E$2:$E$153=$E50)*($A$2:$A$153<>$A50))>0,"DOUBLON A VERIFIER","") | Y50: Oui
A51: Proforma Institut | B51: DJIBILIAN Yoann | C51: Nedjma | D51: Communiquer sur les réseaux sociaux pour promouvoir sa TPE | E51: 2026-07-06 | F51: 2026-07-11 | G51: Accepté | H51: 18 PL place d'Amont, 13390 AURIOL | I51: yoann.djibilian@laposte.net | J51: 645742336 | K51: 26/09/1999 | L51: A faire | M51: ='WEDOF - EXAMEN FINAL'!D51 -> A faire | N51: A faire | O51: A faire | P51: A faire | Q51: A faire | R51: A faire | S51: A faire | T51: A faire | U51: =TEXTJOIN(", ",TRUE(),IF($L51="A faire","Analyse du besoin",""),IF($M51="A faire","CV",""),IF($N51="A faire","Questionnaire/Test",""),IF($O51="A faire","Contrat",""),IF($P51="A faire","Convocation",""),IF($Q51="A faire","Eval intermediaire",""),IF($R51="A faire","Eval finale",""),IF($S51="A faire","Questionnaire satisfaction",""),IF($T51="A faire","Document de fin","")) -> Analyse du besoin, CV, Questionnaire/Test, Contrat, Convocation, Eval intermediaire, Eval finale, Questionnaire satisfaction, Document de fin | V51: =COUNTIF(L51:T51,"Fait")/9 -> 0 | W51: =IF($F51="","",IF(AND(TODAY()>=(DATEVALUE($F51)+1),$U51<>""),"A RELANCER : "&$U51,"")) -> A RELANCER : Analyse du besoin, CV, Questionnaire/Test, Contrat, Convocation, Eval intermediaire, Eval finale, Questionnaire satisfaction, Document de fin | X51: =IF(SUMPRODUCT(($B$2:$B$153=$B51)*($D$2:$D$153=$D51)*($E$2:$E$153=$E51)*($A$2:$A$153<>$A51))>0,"DOUBLON A VERIFIER","") | Y51: Oui
A52: Proforma Institut | B52: FRANGIAN Vazguen | C52: GRAS | D52: Améliorer l'efficacité de sa TPE à l'aide de l'IA | E52: 2026-07-13 | F52: 2026-07-18 | G52: Accepté | L52: A faire | M52: ='WEDOF - EXAMEN FINAL'!D52 -> A faire | N52: A faire | O52: A faire | P52: A faire | Q52: A faire | R52: A faire | S52: A faire | T52: A faire | U52: =TEXTJOIN(", ",TRUE(),IF($L52="A faire","Analyse du besoin",""),IF($M52="A faire","CV",""),IF($N52="A faire","Questionnaire/Test",""),IF($O52="A faire","Contrat",""),IF($P52="A faire","Convocation",""),IF($Q52="A faire","Eval intermediaire",""),IF($R52="A faire","Eval finale",""),IF($S52="A faire","Questionnaire satisfaction",""),IF($T52="A faire","Document de fin","")) -> Analyse du besoin, CV, Questionnaire/Test, Contrat, Convocation, Eval intermediaire, Eval finale, Questionnaire satisfaction, Document de fin | V52: =COUNTIF(L52:T52,"Fait")/9 -> 0 | W52: =IF($F52="","",IF(AND(TODAY()>=(DATEVALUE($F52)+1),$U52<>""),"A RELANCER : "&$U52,"")) -> A RELANCER : Analyse du besoin, CV, Questionnaire/Test, Contrat, Convocation, Eval intermediaire, Eval finale, Questionnaire satisfaction, Document de fin | X52: =IF(SUMPRODUCT(($B$2:$B$153=$B52)*($D$2:$D$153=$D52)*($E$2:$E$153=$E52)*($A$2:$A$153<>$A52))>0,"DOUBLON A VERIFIER","") | Y52: Oui
A53: Proforma Institut | B53: FRANGIAN Vazguen | C53: GRAS | D53: Communiquer sur les réseaux sociaux pour promouvoir sa TPE | E53: 2026-07-20 | F53: 2026-07-25 | G53: Accepté | L53: A faire | M53: ='WEDOF - EXAMEN FINAL'!D53 -> A faire | N53: A faire | O53: A faire | P53: A faire | Q53: A faire | R53: A faire | S53: A faire | T53: A faire | U53: =TEXTJOIN(", ",TRUE(),IF($L53="A faire","Analyse du besoin",""),IF($M53="A faire","CV",""),IF($N53="A faire","Questionnaire/Test",""),IF($O53="A faire","Contrat",""),IF($P53="A faire","Convocation",""),IF($Q53="A faire","Eval intermediaire",""),IF($R53="A faire","Eval finale",""),IF($S53="A faire","Questionnaire satisfaction",""),IF($T53="A faire","Document de fin","")) -> Analyse du besoin, CV, Questionnaire/Test, Contrat, Convocation, Eval intermediaire, Eval finale, Questionnaire satisfaction, Document de fin | V53: =COUNTIF(L53:T53,"Fait")/9 -> 0 | W53: =IF($F53="","",IF(AND(TODAY()>=(DATEVALUE($F53)+1),$U53<>""),"A RELANCER : "&$U53,"")) | X53: =IF(SUMPRODUCT(($B$2:$B$153=$B53)*($D$2:$D$153=$D53)*($E$2:$E$153=$E53)*($A$2:$A$153<>$A53))>0,"DOUBLON A VERIFIER","") | Y53: Oui
A54: Proforma Institut | B54: FRANGIAN Vazguen | C54: GRAS | D54: Réaliser les opérations comptables courantes d'une TPE | E54: 2026-07-27 | F54: 2026-08-01 | G54: Accepté | L54: A faire | M54: ='WEDOF - EXAMEN FINAL'!D54 -> A faire | N54: A faire | O54: A faire | P54: A faire | Q54: A faire | R54: A faire | S54: A faire | T54: A faire | U54: =TEXTJOIN(", ",TRUE(),IF($L54="A faire","Analyse du besoin",""),IF($M54="A faire","CV",""),IF($N54="A faire","Questionnaire/Test",""),IF($O54="A faire","Contrat",""),IF($P54="A faire","Convocation",""),IF($Q54="A faire","Eval intermediaire",""),IF($R54="A faire","Eval finale",""),IF($S54="A faire","Questionnaire satisfaction",""),IF($T54="A faire","Document de fin","")) -> Analyse du besoin, CV, Questionnaire/Test, Contrat, Convocation, Eval intermediaire, Eval finale, Questionnaire satisfaction, Document de fin | V54: =COUNTIF(L54:T54,"Fait")/9 -> 0 | W54: =IF($F54="","",IF(AND(TODAY()>=(DATEVALUE($F54)+1),$U54<>""),"A RELANCER : "&$U54,"")) | X54: =IF(SUMPRODUCT(($B$2:$B$153=$B54)*($D$2:$D$153=$D54)*($E$2:$E$153=$E54)*($A$2:$A$153<>$A54))>0,"DOUBLON A VERIFIER","") | Y54: Oui
A55: Proforma Institut | B55: MELIKSETIAN Suren | C55: Sabri | D55: Développer son activité avec l’intelligence artificielle | E55: 2026-07-06 | F55: 2026-07-11 | G55: Accepté | L55: A faire | M55: ='WEDOF - EXAMEN FINAL'!D55 -> A faire | N55: A faire | O55: A faire | P55: A faire | Q55: Fait | R55: Fait | S55: Fait | T55: A faire | U55: =TEXTJOIN(", ",TRUE(),IF($L55="A faire","Analyse du besoin",""),IF($M55="A faire","CV",""),IF($N55="A faire","Questionnaire/Test",""),IF($O55="A faire","Contrat",""),IF($P55="A faire","Convocation",""),IF($Q55="A faire","Eval intermediaire",""),IF($R55="A faire","Eval finale",""),IF($S55="A faire","Questionnaire satisfaction",""),IF($T55="A faire","Document de fin","")) -> Analyse du besoin, CV, Questionnaire/Test, Contrat, Convocation, Document de fin | V55: =COUNTIF(L55:T55,"Fait")/9 -> 0.33333333 | W55: =IF($F55="","",IF(AND(TODAY()>=(DATEVALUE($F55)+1),$U55<>""),"A RELANCER : "&$U55,"")) -> A RELANCER : Analyse du besoin, CV, Questionnaire/Test, Contrat, Convocation, Document de fin | X55: =IF(SUMPRODUCT(($B$2:$B$153=$B55)*($D$2:$D$153=$D55)*($E$2:$E$153=$E55)*($A$2:$A$153<>$A55))>0,"DOUBLON A VERIFIER","") | Y55: Oui
...

Sheet WEDOF - EXAMEN FINAL
A1: Organisme | B1: Nom | C1: Apporteur | D1: CV | E1: CIN | F1: 6 dossiers admin | G1: Convocation examen | H1: Experience | I1: Adresse | J1: Email | K1: Mobile | L1: Date de naissance | M1: Missions a faire
A2: =APPRENANTS!A2 -> Proforma Institut | B2: =APPRENANTS!B2 -> Mohamed Ait Baha | C2: =APPRENANTS!C2 -> Djody | D2: A faire | E2: A faire | F2: A faire | G2: Fait | I2: =APPRENANTS!H2 -> 141 BD Maréchal Juin, 62110 HENIN BEAUMONT | J2: =APPRENANTS!I2 -> mohamed.aitbaha@hotmail.fr | K2: =APPRENANTS!J2 -> 782270615 | L2: =APPRENANTS!K2 -> 1982-09-04 | M2: =TEXTJOIN(", ",TRUE(),IF($D2="A faire","CV",""),IF($E2="A faire","CIN",""),IF($F2="A faire","6 dossiers admin",""),IF($G2="A faire","Convocation examen","")) -> CV, CIN, 6 dossiers admin
A3: =APPRENANTS!A3 -> Proforma Institut | B3: =APPRENANTS!B3 -> Frederic Roche | C3: =APPRENANTS!C3 -> Nedjma | D3: Fait | E3: A faire | F3: Fait | G3: Fait | H3: depuis 2004 effage construction ( 7 rue du devoir effage construction sud est ) manoeuvre, 3 AN 2008 AIDE COFFREUR 210 ET DEPUII 2015 230 | I3: =APPRENANTS!H3 -> 10 AV Des mimosas, 13015 MARSEILLE | J3: =APPRENANTS!I3 -> fred_mars13@hotmail.fr | K3: =APPRENANTS!J3 -> 613637315 | L3: =APPRENANTS!K3 -> 18/02/1981 | M3: =TEXTJOIN(", ",TRUE(),IF($D3="A faire","CV",""),IF($E3="A faire","CIN",""),IF($F3="A faire","6 dossiers admin",""),IF($G3="A faire","Convocation examen","")) -> CIN
A4: =APPRENANTS!A4 -> Proforma Institut | B4: =APPRENANTS!B4 -> SIAF Kamla | C4: =APPRENANTS!C4 -> Nedjma | D4: A faire | E4: A faire | F4: A faire | G4: Fait | I4: =APPRENANTS!H4 -> 171 AV du Merlan, 13014 MARSEILLE | J4: =APPRENANTS!I4 -> mimisiaf@gmail.com | K4: =APPRENANTS!J4 -> 629924780 | L4: =APPRENANTS!K4 -> 13/08/1965 | M4: =TEXTJOIN(", ",TRUE(),IF($D4="A faire","CV",""),IF($E4="A faire","CIN",""),IF($F4="A faire","6 dossiers admin",""),IF($G4="A faire","Convocation examen","")) -> CV, CIN, 6 dossiers admin
A5: =APPRENANTS!A5 -> Proforma Institut | B5: =APPRENANTS!B5 -> HAFIDHOU Mansouri | C5: =APPRENANTS!C5 -> Nedjma | D5: Fait | E5: Fait | F5: Fait | G5: Fait | H5: 10 ans eiffage coffreur depuis 3ans chef d equipe 10 ans eiffage coffreur depuis 3ans chef d equipe | I5: =APPRENANTS!H5 -> 178 AV Des chutes lavie, 13013 MARSEILLE | J5: =APPRENANTS!I5 -> mansourihafidou@gmail.com | K5: =APPRENANTS!J5 -> 763179407 | L5: =APPRENANTS!K5 -> 1990-07-05 | M5: =TEXTJOIN(", ",TRUE(),IF($D5="A faire","CV",""),IF($E5="A faire","CIN",""),IF($F5="A faire","6 dossiers admin",""),IF($G5="A faire","Convocation examen",""))
A6: =APPRENANTS!A6 -> Proforma Institut | B6: =APPRENANTS!B6 -> DELGADO DA CRUZ Francisco | C6: =APPRENANTS!C6 -> Nedjma | D6: Fait | E6: Fait | F6: Fait | G6: Fait | H6: 20 ans effage manoeuvre PUIS aide coffreur qualif 210 | I6: =APPRENANTS!H6 -> 29 PTR Sainte victoire, 13006 MARSEILLE | J6: =APPRENANTS!I6 -> chicodelgado72@gmail.com | K6: =APPRENANTS!J6 -> 783823367 | L6: =APPRENANTS!K6 -> 1972-11-07 | M6: =TEXTJOIN(", ",TRUE(),IF($D6="A faire","CV",""),IF($E6="A faire","CIN",""),IF($F6="A faire","6 dossiers admin",""),IF($G6="A faire","Convocation examen",""))
A7: =APPRENANTS!A7 -> Proforma Institut | B7: =APPRENANTS!B7 -> DOUMENC Christophe | C7: =APPRENANTS!C7 -> Nedjma | D7: Fait | E7: Fait | F7: Fait | G7: Fait | H7: 16 ans effage grutier qualif 270 CHEF D EQUPE ( voir parcours ) | I7: =APPRENANTS!H7 -> 16 RUE Nicolas copernic, 13013 MARSEILLE | J7: =APPRENANTS!I7 -> christophedoumenc13@gmail.com | K7: =APPRENANTS!J7 -> 681540974 | L7: =APPRENANTS!K7 -> 30/12/1972 | M7: =TEXTJOIN(", ",TRUE(),IF($D7="A faire","CV",""),IF($E7="A faire","CIN",""),IF($F7="A faire","6 dossiers admin",""),IF($G7="A faire","Convocation examen",""))
A8: =APPRENANTS!A8 -> Proforma Institut | B8: =APPRENANTS!B8 -> AHAMADA BOURHANE Soilihi | C8: =APPRENANTS!C8 -> Nedjma | D8: Fait | E8: Fait | F8: Fait | G8: Fait | H8: 8 ANS EIFFAGE GRUTIER AVANT COFFREUR TRAVEAUX DU MIDI | I8: =APPRENANTS!H8 -> 257 AV Saint antoine, 13015 MARSEILLE | J8: =APPRENANTS!I8 -> ahamada.s@live.fr | K8: =APPRENANTS!J8 -> 652632912 | L8: =APPRENANTS!K8 -> 22/06/1991 | M8: =TEXTJOIN(", ",TRUE(),IF($D8="A faire","CV",""),IF($E8="A faire","CIN",""),IF($F8="A faire","6 dossiers admin",""),IF($G8="A faire","Convocation examen",""))
