Workbook

Sheet Ordre de passage
A1: Grille d'évaluation - "Réaliser les opération courantes d'une TPE" - RS6485
C3: Nom et prénom évaluateur | F3: Tom FOURNAISE | G3: Djody BENCHADI
C4: Date du Jury | D4: 46178
A5: Renseigner selon l'ordre de passage, ainsi le nom et prénom est renseigné dans chaque feuille
A7: Remplir les cellules jaunes ainsi que les deux cellules grises ci-dessus (évaluateur et date)
A8: NB | B8: Heure de passage | C8: NOM | D8: Prénom | E8: Note finale / 20 | F8: Commentaires évaluateur 1 | G8: Commentaires évaluateur 2 | H8: Commentaires évaluateur 3
A9: 1 | B9: 09:00 - 10:00 | C9: AHAMADA BOURHANE | D9: Soilihihe | E9: ='Participant 1'!F16 -> 16.25 | F9: Projet de sous-traitance BTP bien structuré, s'appuyant sur une double compétence levage/coffrage valorisée avec pertinence. Les indicateurs de pilotage sont cohérents avec l'activité. La maîtrise des spécificités réglementaires (autoliquidation TVA, VGP) est un point fort. Des efforts attendus sur la conformité de la facturation et l'approfondissement du processus de recouvrement. | G9: Dossier financier globalement maîtrisé. Le calcul du BFR est correctement évalué au regard des délais de paiement. Le modèle économique est viable. Des marges de progression identifiées sur la valorisation des stocks et le pilotage de la marge brute en temps réel.
A10: 2 | B10: 10:30 - 11:30 | C10: BENGUEDIH | D10: Kader | E10: ='Participant 2'!F16 -> 13.75 | F10: Projet de mobilité VTC avec un positionnement premium cohérent. Les outils numériques retenus sont adaptés. Des lacunes significatives sur la conformité de la facturation et la robustesse du BFR initial. L'analyse financière manque de profondeur sur certains points clés attendus d'un dirigeant de TPE. | G10: Le suivi de la flotte et la gestion des charges fixes sont présents. Le prévisionnel financier est atteignable mais le BFR semble sous-estimé. Des efforts sont attendus sur la rigueur documentaire de la facturation et la complétude du processus de recouvrement B2B.
A11: 3 | B11: 12:00 - 13:00 | C11: DELGADO DA CRUZ | D11: Francisco | E11: ='Participant 3'!F16 -> 15 | F11: Dossier solide porté par 20 ans d'expérience terrain. L'organisation administrative est bien pensée. Des améliorations à apporter sur la conformité de la facturation et la capacité à projeter et défendre les hypothèses financières à moyen terme lors de la soutenance. | G11: Les équilibres financiers sont réalistes. La progression du CA sur trois mois réels est encourageante. Des efforts de formalisation supplémentaires sont attendus sur la maîtrise des documents comptables et l'approfondissement de l'analyse des écarts par rapport au prévisionnel.
A12: 4 | B12: 13:30 - 14:30 | C12: DOUMENC | D12: Christophe | E12: ='Participant 4'!F16 -> 16.25 | F12: Excellente soutenance portée par 16 ans d'expertise et une posture de chef d'entreprise affirmée. Maîtrise des spécificités de la sous-traitance. Le principal point d'amélioration porte sur la conformité complète de la facturation, indispensable pour les relations avec les grands donneurs d'ordres. | G12: Le candidat démontre une parfaite compréhension de la sous-traitance et du mécanisme d'autoliquidation de la TVA. Le BFR est provisionné avec prudence. La rigueur documentaire de la facturation doit être renforcée pour être irréprochable face aux exigences des majors du BTP.
A13: 5 | B13: 15:00 - 16:00 | C13: ROCHE | D13: Frederic | E13: ='Participant 5'!F16 -> 17 | F13: Soutenance de très haut niveau alliant expertise technique et maîtrise financière. L'écosystème numérique est parfaitement intégré. La rigueur dans l'analyse des écarts est exemplaire. Seul point à corriger : la complétude des mentions légales de facturation, avant toute mise en activité. | G13: L'analyse de la marge brute et les tableaux de bord sont d'une précision remarquable. Les écarts sur achats de matériaux sont parfaitement justifiés. La qualité du prévisionnel et la cohérence globale du dossier témoignent d'une préparation sérieuse et d'une maturité financière réelle.

Sheet Participant 1
A1: Grille d'évaluation
A2: "Réaliser les opération courantes d'une TPE" - RS6485
B3: Nom du candidat : | D3: =IF('Ordre de passage'!C9="","",'Ordre de passage'!C9) -> AHAMADA BOURHANE | F3: Date : | H3: =IF('Ordre de passage'!D4="","",'Ordre de passage'!D4) -> 46178 | J3: Important : renseigner les cellules de couleurs grises
B4: Prénom du candidat : | D4: =IF('Ordre de passage'!D9="","",'Ordre de passage'!D9) -> Soilihihe | J4: Commentaire obligatoire pour les critères que le candidat ne valide pas
B5: Heure de passage : | D5: =IF('Ordre de passage'!B9="","",'Ordre de passage'!B9) -> 09:00 - 10:00
B6: Compétences | D6: Critères | F6: Pts Max. | G6: Note Jury 1 | H6: Commentaires Jury 1 | I6: Note Jury 2 | J6: Commentaires Jury 2 | K6: Note Jury 3 | L6: Commentaires Jury 3
A7: C1 | B7: Mettre en place l’organisation comptable de l’entreprise en déterminant les indicateurs de contrôle (chiffre d’affaires, état de trésorerie, rentabilité, tableaux de bord) afin de piloter la gestion quotidienne comptable. | D7: Cr1. Le candidat démontre une organisation claire et concise. Il choisit des indicateurs cohérents selon son secteur d’activité et son projet professionnel. | F7: 2 | G7: 2 | H7: Le tableau de bord présenté s'appuie sur des indicateurs métier pertinents (CA HT, taux de marge, jours de production). L'intégration de Batappli comme outil de pilotage est cohérente avec l'activité BTP. L'organisation administrative en trois étapes est structurée. Il conviendrait toutefois de préciser les fréquences de mise à jour des indicateurs pour garantir un pilotage réellement opérationnel. | I7: 2 | J7: L'organisation comptable repose sur des outils adaptés et une logique de suivi régulière. Les indicateurs retenus couvrent les dimensions essentielles de l'activité. Cependant, l'indicateur de taux de reprises, bien qu'excellent (0 %), mériterait d'être davantage mis en valeur comme levier de rentabilité dans la soutenance.
A8: C2 | B8: Etablir un plan financier prévisionnel en calculant les recettes et dépenses de la TPE en lien avec l’activité réelle et souhaitée, en évaluant les éventuels besoins en fonds de roulement afin d’assurer une gestion maîtrisée de la trésorerie. | D8: Cr2. Le candidat fait apparaitre correctement les différents calculs des recettes et dépenses. Il met en avant les besoins en fonds de roulement de son activité. | F8: 2 | G8: 1.5 | H8: Les hypothèses de CA sur trois ans (168 400 € → 221 900 €) sont progressives et cohérentes. Le calcul du BFR à 11 600 € en N1 intègre correctement les délais clients et fournisseurs. Il manque cependant une analyse de sensibilité sur un scénario défavorable, qui renforcerait la solidité du dossier. | I8: 1.5 | J8: La trésorerie nette positive dès N1 (+13 400 €) témoigne d'un dimensionnement réaliste. Le modèle FR/BFR est globalement maîtrisé. Un effort de formalisation sur les hypothèses de charges variables permettrait de renforcer la crédibilité du prévisionnel.
A9: C3 | B9: Traiter les opérations comptables courantes (factures clients, factures fournisseurs, salaires, charges, frais, éléments banque...), en sécurisant les actions par les différentes tâches de contrôle (rapprochement bancaire...) pour répondre aux obligations de déclarations (TVA...). | D9: Cr3. Le candidat réalise des documents conformes aux législations financières et à la mesure de son activité. | F9: 2 | G9: 2 | H9: La facture intègre les mentions spécifiques au BTP sous-traitant : autoliquidation de la TVA (Art. 283-2 nonies du CGI), numéro de police RC Pro et décennale. C'est une maîtrise réglementaire notable. Veiller à ce que le numéro séquentiel de facturation soit rigoureusement respecté pour éviter tout litige fiscal. | I9: 1.5 | J9: Les mentions légales obligatoires sont globalement présentes. La distinction entre facturation HT en sous-traitance et application de la TVA pour les clients particuliers devrait être davantage explicitée pour démontrer la maîtrise complète des deux cas de figure.
A10: C4 | B10: Appliquer les processus liés aux opérations particulières de gestion en lien avec les clients (impayés, méthodologie de recouvrement...) en respectant les règles législatives afin de gérer, en toute conformité, les évènements de la vie de l’entreprise. | D10: Cr4. Le processus proposé par le candidat est formalisé avec des étapes palliatives permettant d’atteindre le résultat attendu. | F10: 2 | G10: 1.5 | H10: Le processus de recouvrement en quatre étapes (J+2 à J+45) est formalisé et progressif. Cependant, le délai avant mise en demeure (J+20) paraît long dans un contexte de sous-traitance BTP où les délais légaux sont de 30 jours. Une révision de ce calendrier s'impose. | I10: 1.5 | J10: La procédure d'injonction de payer est identifiée comme recours ultime. Le candidat gagnerait à préciser explicitement les montants des pénalités applicables et la condition de suspension des travaux, qui constituent des leviers de pression essentiels non suffisamment mis en avant.
A11: C5 | B11: Gérer les stocks et/ ou offres de services afin de piloter et d’optimiser les ressources mobilisables tout en évitant les ruptures de stocks ou les retards de délais de livraison. | D11: Cr5. Le candidat met correctement en avant les différentes rubriques relatives à son activité : type de produits et/ou offres de services, notion de volume, indicateur de disponibilités. Le tableau proposé permet de vérifier le flux d’activité et d’identifier les risques de rupture ou de surcharge. | F11: 2 | G11: 1.5 | H11: Le tableau de gestion des stocks couvre les matériaux essentiels. L'alerte sur les élingues de levage démontre une vigilance sur les obligations de vérification périodique. Il manque une valorisation financière des stocks pour l'intégrer au calcul du BFR de façon dynamique. | I11: 1.5 | J11: Le suivi des EPI est rigoureux. Cependant, l'absence d'un stock tampon sur les élingues représente un risque opérationnel réel en cas de retard fournisseur. Ce point devrait faire l'objet d'une action corrective explicite dans le dossier.
A12: C6 | B12: Superviser et contrôler les risques d’écarts entre le prévisionnel et le réalisé, en s’appuyant sur un outil de suivi des recettes et des dépenses en enregistrant au fil de l’eau les informations liées aux achats et ventes de l’entreprise pour vérifier le respect du prévisionnel envisagé et permettre d’anticiper au plus vite les actions correctives. | D12: Cr6. Le tableau de supervision des opérations courantes permet d’identifier les anomalies dans la gestion et de prévoir les actions correctives de façon anticipée. | F12: 2 | G12: 1.5 | H12: L'analyse des écarts du mois 1 identifie correctement le dépassement sur le poste carburant et propose une action corrective concrète. Il serait pertinent d'intégrer un suivi cumulé sur plusieurs mois pour détecter les tendances de fond et anticiper les dérives. | I12: 1.5 | J12: Le tableau des écarts est lisible et opérationnel. Néanmoins, l'absence d'un indicateur de suivi de la marge brute réelle versus prévisionnelle constitue une lacune : c'est l'indicateur central de la rentabilité d'une TPE de sous-traitance BTP.
A13: C7 | B13: Interagir avec les différents acteurs intervenant sur les opérations comptables de l’entreprise, en s’appuyant sur une lecture éclairée des documents comptables (bilans, compte de résultats, tableau budgétaire, plans comptables, plans de trésorerie, déclarations sociales et fiscales...) pour représenter au mieux la TPE et défendre ses intérêts. | D13: Cr7. La présentation du candidat sur lesdits tableaux doit montrer sa compréhension des documents et des mécanismes financiers. Ses commentaires sont pertinents par rapport aux résultats financiers inscrits sur ces documents. Le candidat comprend les incidences des résultats constatés et identifie les progrès à devoir atteindre. | F13: 5 | G13: 4 | H13: La soutenance est structurée et le candidat démontre une maîtrise convaincante de son projet. La double compétence levage/coffrage est bien valorisée. Pour progresser vers l'excellence, le candidat devrait approfondir l'analyse des tendances sur les mois réels présentés et en tirer des conclusions prospectives explicites. | I13: 3 | J13: La lecture des documents financiers est globalement satisfaisante. Des marges de progression existent sur la capacité à relier les résultats comptables à des décisions de gestion concrètes (quand investir, quand recruter). Ces interactions doivent figurer dans le discours du dirigeant.
A14: C8 | B14: QCM portant sur les connaissances théoriques de la gestion des opérations comptables courantes d’une TPE. | D14: Cr8. Si le score obtenu est de +70%, les 3 points sont attribués | F14: 3 | G14: 3 | H14: Le QCM est validé avec un score satisfaisant. Les connaissances théoriques sur les opérations comptables courantes d'une TPE sont acquises. | I14: 3 | J14: Les notions théoriques sont maîtrisées. Le résultat du QCM confirme une bonne assimilation des fondamentaux de la gestion comptable d'une TPE.
A15: TOTAL (note sur 60) | F15: =SUM(F7:F14) -> 20 | G15: =SUM(G7:G14) -> 17 | I15: =SUM(I7:I14) -> 15.5
B16: L’obtention d’une note minimale de 10/20 permet la validation du parcours (attention, la moyenne est calculée pour 3 jurés, à changer si uniquement 2 membres) | F16: =(G15+I15+K15)/2 -> 16.25
F17: Note finale
B18: Nom et prénom évaluateur
B19: ='Ordre de passage'!F3 -> Tom FOURNAISE | D19: ='Ordre de passage'!G3 -> Djody BENCHADI | F19: ='Ordre de passage'!H3 -> 0
B21: Appréciation générale Jury 1 | D21: Appréciation générale Jury 2 | F21: Appréciation générale Jury 3 | J21: Date et signature des évaluateurs
B22: Soutenance sérieuse et bien préparée. M. Ahamada présente un projet crédible, ancré dans une réalité terrain solide (8 ans d'expérience, CACES R487). La maîtrise des outils numériques et des spécificités réglementaires BTP est un point fort indéniable. Des efforts sur l'analyse de sensibilité du prévisionnel et le calendrier de recouvrement permettraient d'atteindre l'excellence. Admis. | D22: Dossier structuré et cohérent avec l'activité de sous-traitance BTP. Le candidat maîtrise les équilibres financiers de base et comprend les enjeux du BFR dans son secteur. Quelques points techniques restent à consolider, notamment la valorisation des stocks et le pilotage de la marge brute en temps réel. Admis. | J22: =IF('Ordre de passage'!D4="","",'Ordre de passage'!D4) -> 46178

Sheet Participant 2
A1: Grille d'évaluation
B3: Nom du candidat : | D3: =IF('Ordre de passage'!C10="","",'Ordre de passage'!C10) -> BENGUEDIH | F3: Date : | H3: =IF('Ordre de passage'!D4="","",'Ordre de passage'!D4) -> 46178 | J3: Important : renseigner les cellules de couleurs grises
B4: Prénom du candidat : | D4: =IF('Ordre de passage'!D10="","",'Ordre de passage'!D10) -> Kader | J4: Commentaire obligatoire pour les critères que le candidat ne valide pas
B5: Heure de passage : | D5: =IF('Ordre de passage'!B10="","",'Ordre de passage'!B10) -> 10:30 - 11:30
B6: Compétences | D6: Critères | F6: Pts Max. | G6: Note Jury 1 | H6: Commentaires Jury 1 | I6: Note Jury 2 | J6: Commentaires Jury 2 | K6: Note Jury 3 | L6: Commentaires Jury 3
A7: C1 | B7: Mettre en place l’organisation comptable de l’entreprise en déterminant les indicateurs de contrôle (chiffre d’affaires, état de trésorerie, rentabilité, tableaux de bord) afin de piloter la gestion quotidienne comptable. | D7: Cr1. Le candidat démontre une organisation claire et concise. Il choisit des indicateurs cohérents selon son secteur d’activité et son projet professionnel. | F7: 2 | G7: 1 | H7: Le projet VTC haut de gamme repose sur des indicateurs adaptés. L'outil Way-Plan est pertinent pour centraliser les réservations. Cependant, l'indicateur de taux de remplissage kilométrique n'est pas relié à un objectif de rentabilité chiffré dans la soutenance. Ce lien est indispensable pour démontrer la maîtrise du pilotage de l'activité. | I7: 1.5 | J7: L'utilisation de Pennylane pour centraliser la comptabilité est cohérente. Il manque toutefois un indicateur de coût d'acquisition client B2B, qui constitue un poste stratégique dans un modèle dépendant des hôtels et entreprises. Cet angle mort doit être comblé pour valider la complétude du tableau de bord.
A8: C2 | B8: Etablir un plan financier prévisionnel en calculant les recettes et dépenses de la TPE en lien avec l’activité réelle et souhaitée, en évaluant les éventuels besoins en fonds de roulement afin d’assurer une gestion maîtrisée de la trésorerie. | D8: Cr2. Le candidat fait apparaitre correctement les différents calculs des recettes et dépenses. Il met en avant les besoins en fonds de roulement de son activité. | F8: 2 | G8: 1.5 | H8: Le prévisionnel de CA est atteignable. Néanmoins, le BFR apparaît sous-estimé : les créances hôtelières à 30 jours génèrent un décalage de trésorerie non négligeable. La trésorerie initiale négative expose la TPE à un risque réel si l'emprunt n'est pas obtenu dans les délais. Ce point aurait dû être davantage développé et chiffré. | I8: 1.5 | J8: La structure du FR/BFR est présente. Cependant, la fragilité du fonds de roulement initial, liée au poids de l'immobilisation du van, n'est pas suffisamment analysée. Le candidat doit démontrer sa capacité à gérer cette contrainte de trésorerie dès le démarrage, notamment en identifiant des solutions alternatives (crédit-bail, location longue durée).
A9: C3 | B9: Traiter les opérations comptables courantes (factures clients, factures fournisseurs, salaires, charges, frais, éléments banque...), en sécurisant les actions par les différentes tâches de contrôle (rapprochement bancaire...) pour répondre aux obligations de déclarations (TVA...). | D9: Cr3. Le candidat réalise des documents conformes aux législations financières et à la mesure de son activité. | F9: 2 | G9: 1 | H9: La facture présente des éléments de détail corrects. Cependant, le bloc d'identification de l'entreprise prestataire est absent : SIRET, forme juridique, numéro de TVA et coordonnées complètes sont des mentions obligatoires. Sans ces éléments, le document est sans valeur juridique. Cette lacune doit être corrigée impérativement avant toute émission réelle. | I9: 1 | J9: Le calcul de la TVA à 10 % est correct. Néanmoins, l'absence des mentions légales d'identification de l'émetteur rend ce document non conforme. La facturation est la première ligne de défense contre les impayés et doit être irréprochable dès le premier jour d'activité. Il n'est pas acceptable de présenter ce type de document en évaluation sans les mentions obligatoires.
A10: C4 | B10: Appliquer les processus liés aux opérations particulières de gestion en lien avec les clients (impayés, méthodologie de recouvrement...) en respectant les règles législatives afin de gérer, en toute conformité, les évènements de la vie de l’entreprise. | D10: Cr4. Le processus proposé par le candidat est formalisé avec des étapes palliatives permettant d’atteindre le résultat attendu. | F10: 2 | G10: 1 | H10: Le processus de recouvrement est réactif. La suspension des nouvelles courses à J+15 est un levier pertinent. Il manque cependant une mention explicite du calcul des pénalités de retard et de l'indemnité forfaitaire de 40 €, pourtant obligatoires et attendus dans ce type de dossier. | I10: 1.5 | J10: La gradation du processus est cohérente. Cependant, le candidat n'aborde pas la nécessité d'un contrat écrit avec les hôtels partenaires, qui constitue le premier niveau de protection contre les impayés. Cette dimension contractuelle aurait dû figurer dans la soutenance pour démontrer une vision complète de la gestion des risques clients.
A11: C5 | B11: Gérer les stocks et/ ou offres de services afin de piloter et d’optimiser les ressources mobilisables tout en évitant les ruptures de stocks ou les retards de délais de livraison. | D11: Cr5. Le candidat met correctement en avant les différentes rubriques relatives à son activité : type de produits et/ou offres de services, notion de volume, indicateur de disponibilités. Le tableau proposé permet de vérifier le flux d’activité et d’identifier les risques de rupture ou de surcharge. | F11: 2 | G11: 1.5 | H11: La gestion logistique du véhicule est sérieuse et les coûts sont budgétés avec réalisme. Il serait néanmoins nécessaire d'intégrer un tableau de suivi formalisé des entrées/sorties de stocks consommables avec des seuils de réapprovisionnement définis pour répondre pleinement aux exigences du critère. | I11: 1.5 | J11: Le suivi de l'entretien est rigoureux. Cependant, la notion de gestion des stocks dans un contexte de service nécessite également de couvrir les consommables clients avec des seuils explicites. Ce niveau de détail est attendu et son absence fragilise la démonstration.
A12: C6 | B12: Superviser et contrôler les risques d’écarts entre le prévisionnel et le réalisé, en s’appuyant sur un outil de suivi des recettes et des dépenses en enregistrant au fil de l’eau les informations liées aux achats et ventes de l’entreprise pour vérifier le respect du prévisionnel envisagé et permettre d’anticiper au plus vite les actions correctives. | D12: Cr6. Le tableau de supervision des opérations courantes permet d’identifier les anomalies dans la gestion et de prévoir les actions correctives de façon anticipée. | F12: 2 | G12: 1.5 | H12: Le tableau des écarts identifie les principaux postes variables. L'action corrective sur le carburant est pertinente mais insuffisamment chiffrée : quel gain attendu en pourcentage ? Sans cette quantification, l'action corrective reste un vœu pieux et non un plan de pilotage réel. | I12: 1 | J12: L'absence d'un suivi du CA réel versus prévisionnel dans le tableau des écarts est une lacune majeure. Un dirigeant VTC doit être capable de contrôler, semaine par semaine, si son activité est en ligne avec son plan de charge. Ce niveau de pilotage n'est pas démontré et doit être intégré au dispositif de suivi.
A13: C7 | B13: Interagir avec les différents acteurs intervenant sur les opérations comptables de l’entreprise, en s’appuyant sur une lecture éclairée des documents comptables (bilans, compte de résultats, tableau budgétaire, plans comptables, plans de trésorerie, déclarations sociales et fiscales...) pour représenter au mieux la TPE et défendre ses intérêts. | D13: Cr7. La présentation du candidat sur lesdits tableaux doit montrer sa compréhension des documents et des mécanismes financiers. Ses commentaires sont pertinents par rapport aux résultats financiers inscrits sur ces documents. Le candidat comprend les incidences des résultats constatés et identifie les progrès à devoir atteindre. | F13: 5 | G13: 3 | H13: Le candidat présente son projet avec conviction. Toutefois, certaines questions financières n'ont pas reçu de réponses suffisamment précises lors de la soutenance. La maîtrise des documents comptables doit dépasser le seul prévisionnel de CA pour couvrir l'ensemble des états financiers du dirigeant de TPE. | I13: 3 | J13: La compréhension du modèle économique est réelle. Cependant, la capacité à lire et commenter un compte de résultat ou un tableau de trésorerie doit être renforcée. Le candidat doit être en mesure d'anticiper les impacts d'une baisse d'activité sur sa trésorerie et d'expliquer les décisions correctives à prendre.
A14: C8 | B14: QCM portant sur les connaissances théoriques de la gestion des opérations comptables courantes d’une TPE. | D14: Cr8. Si le score obtenu est de +70%, les 3 points sont attribués | F14: 3 | G14: 3 | H14: Le QCM est validé. Les connaissances théoriques sur les fondamentaux de la gestion comptable d'une TPE sont acquises. | I14: 3 | J14: Le résultat du QCM est satisfaisant. Les bases théoriques sont présentes. Leur application concrète dans les situations de gestion présentées doit cependant être plus systématique.
A15: TOTAL (note sur 60) | F15: =SUM(F7:F14) -> 20 | G15: =SUM(G7:G14) -> 13.5 | I15: =SUM(I7:I14) -> 14 | K15: =SUM(K7:K14) -> 0
B16: L’obtention d’une note minimale de 10/20 permet la validation du parcours (attention, la moyenne est calculée pour 3 jurés, à changer si uniquement 2 membres) | F16: =(G15+I15+K15)/2 -> 13.75
F17: Note finale
B18: Nom et prénom évaluateur
B19: ='Ordre de passage'!F3 -> Tom FOURNAISE | D19: ='Ordre de passage'!G3 -> Djody BENCHADI | F19: ='Ordre de passage'!H3 -> 0
B21: Appréciation générale Jury 1 | D21: Appréciation générale Jury 2 | F21: Appréciation générale Jury 3 | J21: Date et signature des évaluateurs
B22: Projet de transport VTC premium crédible, porté par une expérience terrain avérée. Les outils numériques choisis sont adaptés. Des lacunes subsistent sur la conformité de la facturation, la robustesse du BFR initial et la profondeur de l'analyse financière. Ces points doivent être travaillés avant la mise en activité pour sécuriser la pérennité de l'entreprise. Admis. | D22: Dossier présentant un projet cohérent avec le profil du candidat. La maîtrise opérationnelle est réelle, mais la rigueur administrative et comptable doit être renforcée. Ces compétences sont non négociables pour la survie d'une TPE de service. Des efforts concrets sont attendus. Admis. | J22: =IF('Ordre de passage'!D4="","",'Ordre de passage'!D4) -> 46178

Sheet Participant 3
A1: Grille d'évaluation
A2: "Réaliser les opération courantes d'une TPE" - RS6485
B3: Nom du candidat : | D3: =IF('Ordre de passage'!C11="","",'Ordre de passage'!C11) -> DELGADO DA CRUZ | F3: Date : | H3: =IF('Ordre de passage'!D4="","",'Ordre de passage'!D4) -> 46178 | J3: Important : renseigner les cellules de couleurs grises
B4: Prénom du candidat : | D4: =IF('Ordre de passage'!D11="","",'Ordre de passage'!D11) -> Francisco | J4: Commentaire obligatoire pour les critères que le candidat ne valide pas
B5: Heure de passage : | D5: =IF('Ordre de passage'!B11="","",'Ordre de passage'!B11) -> 12:00 - 13:00
B6: Compétences | D6: Critères | F6: Pts Max. | G6: Note Jury 1 | H6: Commentaires Jury 1 | I6: Note Jury 2 | J6: Commentaires Jury 2 | K6: Note Jury 3 | L6: Commentaires Jury 3
A7: C1 | B7: Mettre en place l’organisation comptable de l’entreprise en déterminant les indicateurs de contrôle (chiffre d’affaires, état de trésorerie, rentabilité, tableaux de bord) afin de piloter la gestion quotidienne comptable. | D7: Cr1. Le candidat démontre une organisation claire et concise. Il choisit des indicateurs cohérents selon son secteur d’activité et son projet professionnel. | F7: 2 | G7: 1.5 | H7: L'organisation administrative en trois phases est logique et opérationnelle. Les indicateurs retenus couvrent bien les dimensions de pilotage d'une TPE BTP. Il serait attendu que le candidat explique comment ces indicateurs orientent concrètement ses décisions de gestion : c'est ce lien entre mesure et action qui distingue le pilotage de la simple observation. | I7: 1.5 | J7: Le choix d'un archivage structuré par type de document est une approche professionnelle. Les indicateurs sélectionnés sont pertinents. Il manque cependant une explication claire sur la fréquence de mise à jour et le processus de révision mensuelle de ces indicateurs pour démontrer leur utilisation active dans le pilotage.
A8: C2 | B8: Etablir un plan financier prévisionnel en calculant les recettes et dépenses de la TPE en lien avec l’activité réelle et souhaitée, en évaluant les éventuels besoins en fonds de roulement afin d’assurer une gestion maîtrisée de la trésorerie. | D8: Cr2. Le candidat fait apparaitre correctement les différents calculs des recettes et dépenses. Il met en avant les besoins en fonds de roulement de son activité. | F8: 2 | G8: 1.5 | H8: Le plan financier sur trois ans affiche une progression ambitieuse (+144 %). Le passage de 14 à 29 chantiers annuels suppose des ressources supplémentaires non prévues dans le prévisionnel. L'absence d'analyse des charges fixes de structure fragilise la projection et doit être comblée pour crédibiliser l'ensemble du modèle. | I8: 1.5 | J8: La structure FR/BFR est correctement construite. Cependant, le candidat devrait être en mesure de justifier l'évolution du BFR entre N1 et N3 au regard de la croissance du CA : cette dynamique doit être expliquée et anticipée explicitement, car elle impacte directement les besoins de financement.
A9: C3 | B9: Traiter les opérations comptables courantes (factures clients, factures fournisseurs, salaires, charges, frais, éléments banque...), en sécurisant les actions par les différentes tâches de contrôle (rapprochement bancaire...) pour répondre aux obligations de déclarations (TVA...). | D9: Cr3. Le candidat réalise des documents conformes aux législations financières et à la mesure de son activité. | F9: 2 | G9: 1.5 | H9: La facture comporte les éléments de prestation mais plusieurs mentions légales obligatoires sont absentes : numéro de facture séquentiel, date d'émission précise, coordonnées complètes du client, récapitulatif HT/TTC. En l'état, ce document ne satisfait pas aux exigences légales. Ces lacunes doivent être corrigées avant toute émission réelle. | I9: 1.5 | J9: La logique de facturation est présente mais une facture sans numéro unique, sans date d'émission et sans identification complète du client est juridiquement invalide. Il est indispensable que le candidat intègre systématiquement ces mentions dans son modèle définitif. Ce niveau d'exigence est non négociable.
A10: C4 | B10: Appliquer les processus liés aux opérations particulières de gestion en lien avec les clients (impayés, méthodologie de recouvrement...) en respectant les règles législatives afin de gérer, en toute conformité, les évènements de la vie de l’entreprise. | D10: Cr4. Le processus proposé par le candidat est formalisé avec des étapes palliatives permettant d’atteindre le résultat attendu. | F10: 2 | G10: 1.5 | H10: Le processus de recouvrement est bien adapté à une clientèle mixte. La gradation en quatre étapes est cohérente. Il conviendrait toutefois d'ajouter explicitement la mention du taux de pénalité applicable et la condition de suspension des travaux, qui constitue le levier de pression le plus efficace dans le BTP. | I10: 1.5 | J10: La mise en demeure à J+15 est appropriée et l'indemnité forfaitaire de 40 € est identifiée. Pour compléter le processus, le candidat devrait mentionner la nécessité d'un PV de réception signé dès la fin des travaux, document essentiel pour donner une assise juridique solide à toute procédure de recouvrement.
A11: C5 | B11: Gérer les stocks et/ ou offres de services afin de piloter et d’optimiser les ressources mobilisables tout en évitant les ruptures de stocks ou les retards de délais de livraison. | D11: Cr5. Le candidat met correctement en avant les différentes rubriques relatives à son activité : type de produits et/ou offres de services, notion de volume, indicateur de disponibilités. Le tableau proposé permet de vérifier le flux d’activité et d’identifier les risques de rupture ou de surcharge. | F11: 2 | G11: 1.5 | H11: Le tableau de gestion des stocks couvre les matériaux essentiels. L'alerte sur le sable est bien identifiée avec une action corrective. Il manque une valorisation financière des stocks pour alimenter le calcul du BFR de façon dynamique et démontrer la maîtrise du lien entre gestion physique et gestion financière. | I11: 1.5 | J11: La gestion en flux tendu du béton est pertinente. L'alerte sur le stock de sable est traitée avec réactivité. Il serait attendu que le candidat formalise également un processus de réception et de contrôle qualitatif des matériaux à la livraison, enjeu majeur pour une activité de gros œuvre et pour la protection de la garantie décennale.
A12: C6 | B12: Superviser et contrôler les risques d’écarts entre le prévisionnel et le réalisé, en s’appuyant sur un outil de suivi des recettes et des dépenses en enregistrant au fil de l’eau les informations liées aux achats et ventes de l’entreprise pour vérifier le respect du prévisionnel envisagé et permettre d’anticiper au plus vite les actions correctives. | D12: Cr6. Le tableau de supervision des opérations courantes permet d’identifier les anomalies dans la gestion et de prévoir les actions correctives de façon anticipée. | F12: 2 | G12: 1.5 | H12: Le tableau d'écarts identifie correctement les principaux postes variables avec des actions correctives concrètes. La proposition de négocier un contrat-cadre avec le fournisseur acier est une décision de gestion mature. Il serait attendu que le candidat quantifie l'impact de ces actions sur la marge prévisionnelle des mois suivants. | I12: 1.5 | J12: L'analyse des écarts est pertinente et orientée action. Il manque cependant une projection de l'impact des mesures correctives sur la rentabilité future. Démontrer que les actions prises permettent d'atteindre les objectifs de marge initialement prévus est la finalité attendue de ce type d'exercice.
A13: C7 | B13: Interagir avec les différents acteurs intervenant sur les opérations comptables de l’entreprise, en s’appuyant sur une lecture éclairée des documents comptables (bilans, compte de résultats, tableau budgétaire, plans comptables, plans de trésorerie, déclarations sociales et fiscales...) pour représenter au mieux la TPE et défendre ses intérêts. | D13: Cr7. La présentation du candidat sur lesdits tableaux doit montrer sa compréhension des documents et des mécanismes financiers. Ses commentaires sont pertinents par rapport aux résultats financiers inscrits sur ces documents. Le candidat comprend les incidences des résultats constatés et identifie les progrès à devoir atteindre. | F13: 5 | G13: 3 | H13: La soutenance démontre une bonne connaissance du terrain BTP. Pour atteindre un niveau supérieur, le candidat devrait renforcer sa capacité à relier les résultats financiers à des décisions stratégiques et à défendre ses hypothèses face aux questions du jury avec plus d'assurance et de précision. | I13: 3 | J13: La maîtrise technique du métier transparaît dans les commentaires. Cependant, la lecture des documents financiers doit être plus fluide. Le candidat doit être capable de commenter l'évolution de sa trésorerie nette de N1 à N3 et d'en expliquer les leviers sans hésitation ni approximation.
A14: C8 | B14: QCM portant sur les connaissances théoriques de la gestion des opérations comptables courantes d’une TPE. | D14: Cr8. Si le score obtenu est de +70%, les 3 points sont attribués | F14: 3 | G14: 3 | H14: Le QCM est validé avec succès. Les connaissances théoriques sur la gestion des opérations comptables d'une TPE sont acquises et constituent un socle solide. | I14: 3 | J14: Bonne performance au QCM. Les bases théoriques sont maîtrisées. Il convient maintenant de les ancrer davantage dans la pratique quotidienne de la gestion de l'entreprise pour en tirer tout le bénéfice.
A15: TOTAL (note sur 60) | F15: =SUM(F7:F14) -> 20 | G15: =SUM(G7:G14) -> 15 | I15: =SUM(I7:I14) -> 15 | K15: =SUM(K7:K14) -> 0
B16: L’obtention d’une note minimale de 10/20 permet la validation du parcours (attention, la moyenne est calculée pour 3 jurés, à changer si uniquement 2 membres) | F16: =(G15+I15+K15)/2 -> 15
F17: Note finale
B18: Nom et prénom évaluateur
B19: ='Ordre de passage'!F3 -> Tom FOURNAISE | D19: ='Ordre de passage'!G3 -> Djody BENCHADI | F19: ='Ordre de passage'!H3 -> 0
B21: Appréciation générale Jury 1 | D21: Appréciation générale Jury 2 | F21: Appréciation générale Jury 3 | J21: Date et signature des évaluateurs
B22: Dossier bien construit, porté par 20 ans d'expertise chez Eiffage. Le projet de SASU gros œuvre est réaliste et le positionnement est cohérent. Des marges de progression identifiées sur la conformité de la facturation, la profondeur de l'analyse prévisionnelle et la maîtrise des documents financiers lors de la soutenance. Admis. | D22: Projet solide ancré dans une réalité métier convaincante. La compréhension des fondamentaux comptables est présente. Des efforts concrets sont attendus sur la rigueur de la facturation et la capacité à projeter et défendre les hypothèses financières à moyen terme. Admis. | J22: =IF('Ordre de passage'!D4="","",'Ordre de passage'!D4) -> 46178

Sheet Participant 4
A1: Grille d'évaluation
A2: "Réaliser les opération courantes d'une TPE" - RS6485
B3: Nom du candidat : | D3: =IF('Ordre de passage'!C12="","",'Ordre de passage'!C12) -> DOUMENC | F3: Date : | H3: =IF('Ordre de passage'!D4="","",'Ordre de passage'!D4) -> 46178 | J3: Important : renseigner les cellules de couleurs grises
B4: Prénom du candidat : | D4: =IF('Ordre de passage'!D12="","",'Ordre de passage'!D12) -> Christophe | J4: Commentaire obligatoire pour les critères que le candidat ne valide pas
B5: Heure de passage : | D5: =IF('Ordre de passage'!B12="","",'Ordre de passage'!B12) -> 13:30 - 14:30
B6: Compétences | D6: Critères | F6: Pts Max. | G6: Note Jury 1 | H6: Commentaires Jury 1 | I6: Note Jury 2 | J6: Commentaires Jury 2 | K6: Note Jury 3 | L6: Commentaires Jury 3
A7: C1 | B7: Mettre en place l’organisation comptable de l’entreprise en déterminant les indicateurs de contrôle (chiffre d’affaires, état de trésorerie, rentabilité, tableaux de bord) afin de piloter la gestion quotidienne comptable. | D7: Cr1. Le candidat démontre une organisation claire et concise. Il choisit des indicateurs cohérents selon son secteur d’activité et son projet professionnel. | F7: 2 | G7: 2 | H7: L'organisation administrative est rigoureuse et numérique. Les indicateurs retenus sont précisément adaptés à l'activité de grutier sous-traitant (CA HT, jours facturés, frais de déplacement, incidents sécurité). Le zéro incident sécurité sur trois mois est un indicateur non financier à fort impact commercial. Il conviendrait de préciser comment ces indicateurs orientent les décisions commerciales mensuelles. | I7: 2 | J7: La validation hebdomadaire des bons d'attachement constitue un verrou administratif efficace pour sécuriser les encaissements. Il conviendrait cependant de préciser comment ces indicateurs sont analysés en fin de mois pour ajuster la stratégie commerciale : la démarche de pilotage doit être explicitée, pas seulement les outils.
A8: C2 | B8: Etablir un plan financier prévisionnel en calculant les recettes et dépenses de la TPE en lien avec l’activité réelle et souhaitée, en évaluant les éventuels besoins en fonds de roulement afin d’assurer une gestion maîtrisée de la trésorerie. | D8: Cr2. Le candidat fait apparaitre correctement les différents calculs des recettes et dépenses. Il met en avant les besoins en fonds de roulement de son activité. | F8: 2 | G8: 1.5 | H8: Le prévisionnel de CA sur trois ans est réaliste. Le délai de paiement à 45 jours des majors du BTP est bien identifié et provisionné dans le BFR. La trésorerie nette de +1 900 € en N1 reste cependant très limitée : un impayé d'un client majeur sur 30 jours suffirait à déséquilibrer la trésorerie. Ce risque de concentration devait être traité explicitement. | I8: 2 | J8: La marge nette élevée liée à la nature de la prestation technique est bien expliquée. Cependant, la dépendance à un nombre limité de clients grands comptes crée un risque de concentration non couvert dans le dossier. La diversification du portefeuille client dès l'année 1 aurait dû figurer comme axe stratégique.
A9: C3 | B9: Traiter les opérations comptables courantes (factures clients, factures fournisseurs, salaires, charges, frais, éléments banque...), en sécurisant les actions par les différentes tâches de contrôle (rapprochement bancaire...) pour répondre aux obligations de déclarations (TVA...). | D9: Cr3. Le candidat réalise des documents conformes aux législations financières et à la mesure de son activité. | F9: 2 | G9: 1 | H9: La mention d'autoliquidation de TVA est maîtrisée et le relevé des heures attachées est mentionné. Cependant, plusieurs mentions légales obligatoires sont absentes : numéro de TVA intracommunautaire, forme juridique complète, conditions de règlement avec délai et pénalités explicitement indiqués. Ce manque expose l'entreprise à des risques en cas de litige avec les grands donneurs d'ordres. | I9: 1 | J9: La logique de facturation sous-traitance est présente. Néanmoins, une facture destinée à des majors du BTP doit être irréprochable sur la forme. Toute omission de mention légale peut entraîner un retard de paiement ou un rejet comptable. La rigueur documentaire est aussi importante que la rigueur technique sur chantier.
A10: C4 | B10: Appliquer les processus liés aux opérations particulières de gestion en lien avec les clients (impayés, méthodologie de recouvrement...) en respectant les règles législatives afin de gérer, en toute conformité, les évènements de la vie de l’entreprise. | D10: Cr4. Le processus proposé par le candidat est formalisé avec des étapes palliatives permettant d’atteindre le résultat attendu. | F10: 2 | G10: 2 | H10: Le processus de recouvrement est bien adapté aux grands donneurs d'ordres BTP. L'arrêt de la grue sur chantier à J+30 est un levier de pression fort et légalement fondé. Le processus est cohérent et opérationnel. | I10: 2 | J10: La procédure est bien calibrée pour les clients grands comptes. Il serait pertinent de préciser dans la soutenance les conditions contractuelles préalables (contrat de sous-traitance signé, agrément, bons d'attachement validés) qui conditionnent l'efficacité de ce processus et donnent une assise juridique solide au candidat.
A11: C5 | B11: Gérer les stocks et/ ou offres de services afin de piloter et d’optimiser les ressources mobilisables tout en évitant les ruptures de stocks ou les retards de délais de livraison. | D11: Cr5. Le candidat met correctement en avant les différentes rubriques relatives à son activité : type de produits et/ou offres de services, notion de volume, indicateur de disponibilités. Le tableau proposé permet de vérifier le flux d’activité et d’identifier les risques de rupture ou de surcharge. | F11: 2 | G11: 1.5 | H11: Le tableau de gestion des équipements techniques est adapté. L'alerte sur le harnais antichute (stock final < stock minimum, norme EN 361) est identifiée mais doit déclencher une commande immédiate : il s'agit d'une obligation réglementaire. Le suivi des VGP semestrielles est bien intégré. La valorisation financière de ces équipements dans le BFR reste à préciser. | I11: 1.5 | J11: Le suivi de l'équipement de levage est rigoureux. Cependant, la situation du harnais antichute représente un risque réglementaire et opérationnel immédiat. Ce point devait être traité comme priorité absolue dans la soutenance, avec un délai d'approvisionnement précis et un fournisseur identifié.
A12: C6 | B12: Superviser et contrôler les risques d’écarts entre le prévisionnel et le réalisé, en s’appuyant sur un outil de suivi des recettes et des dépenses en enregistrant au fil de l’eau les informations liées aux achats et ventes de l’entreprise pour vérifier le respect du prévisionnel envisagé et permettre d’anticiper au plus vite les actions correctives. | D12: Cr6. Le tableau de supervision des opérations courantes permet d’identifier les anomalies dans la gestion et de prévoir les actions correctives de façon anticipée. | F12: 2 | G12: 2 | H12: L'analyse des écarts est claire et bien contextualisée (dépassement kilométrique lié à un chantier dans le Var). L'action corrective de négociation d'une indemnité de grand déplacement est pertinente et démontre une connaissance des usages du BTP. Ce type d'anticipation contractuelle est une démarche de gestion mature. | I12: 1.5 | J12: La maîtrise des charges fixes est correcte. Il manque cependant un suivi de l'écart sur le CA facturable : le nombre de jours facturés versus prévus est un indicateur essentiel pour un indépendant, car toute journée non facturée est une perte sèche. Cet angle doit figurer dans le tableau de bord mensuel.
A13: C7 | B13: Interagir avec les différents acteurs intervenant sur les opérations comptables de l’entreprise, en s’appuyant sur une lecture éclairée des documents comptables (bilans, compte de résultats, tableau budgétaire, plans comptables, plans de trésorerie, déclarations sociales et fiscales...) pour représenter au mieux la TPE et défendre ses intérêts. | D13: Cr7. La présentation du candidat sur lesdits tableaux doit montrer sa compréhension des documents et des mécanismes financiers. Ses commentaires sont pertinents par rapport aux résultats financiers inscrits sur ces documents. Le candidat comprend les incidences des résultats constatés et identifie les progrès à devoir atteindre. | F13: 5 | G13: 4 | H13: Soutenance de haut niveau portée par une expertise terrain indéniable. Le candidat défend son projet avec autorité et précision. Pour atteindre la note maximale, une approfondissement de la capacité à lire un bilan simplifié et à expliquer l'impact de la variation du BFR sur la capacité d'autofinancement est attendu. | I13: 3 | J13: La maîtrise des indicateurs opérationnels est remarquable. La capacité à relier les résultats financiers à des actions commerciales concrètes démontre un vrai esprit de dirigeant. Quelques imprécisions sur les mécanismes comptables profonds sont à combler pour atteindre un niveau pleinement complet.
A14: C8 | B14: QCM portant sur les connaissances théoriques de la gestion des opérations comptables courantes d’une TPE. | D14: Cr8. Si le score obtenu est de +70%, les 3 points sont attribués | F14: 3 | G14: 3 | H14: Le QCM est validé avec un excellent niveau. Les connaissances théoriques sont solides et bien maîtrisées. | I14: 2.5 | J14: Très bonne performance au QCM. Les connaissances théoriques confirment la solidité du socle de gestion comptable du candidat.
A15: TOTAL (note sur 60) | F15: =SUM(F7:F14) -> 20 | G15: =SUM(G7:G14) -> 17 | I15: =SUM(I7:I14) -> 15.5 | K15: =SUM(K7:K14) -> 0
B16: L’obtention d’une note minimale de 10/20 permet la validation du parcours (attention, la moyenne est calculée pour 3 jurés, à changer si uniquement 2 membres) | F16: =(G15+I15+K15)/2 -> 16.25
F17: Note finale
B18: Nom et prénom évaluateur
B19: ='Ordre de passage'!F3 -> Tom FOURNAISE | D19: ='Ordre de passage'!G3 -> Djody BENCHADI | F19: ='Ordre de passage'!H3 -> 0
B21: Appréciation générale Jury 1 | D21: Appréciation générale Jury 2 | F21: Appréciation générale Jury 3 | J21: Date et signature des évaluateurs
B22: Soutenance de très bon niveau portée par une expertise technique reconnue et une posture de chef d'entreprise affirmée. Le principal point d'amélioration porte sur la rigueur documentaire de la facturation, qui doit être impeccable vis-à-vis des clients grands comptes. Les équilibres financiers sont globalement maîtrisés. Admis. | D22: Dossier solide et bien argumenté. La maîtrise des spécificités réglementaires de la sous-traitance BTP est un point fort. Des efforts sont attendus sur la conformité complète de la facturation et la gestion proactive du risque de concentration client. Admis. | J22: =IF('Ordre de passage'!D4="","",'Ordre de passage'!D4) -> 46178

Sheet Participant 5
A1: Grille d'évaluation
A2: "Réaliser les opération courantes d'une TPE" - RS6485
B3: Nom du candidat : | D3: =IF('Ordre de passage'!C13="","",'Ordre de passage'!C13) -> ROCHE | F3: Date : | H3: =IF('Ordre de passage'!D4="","",'Ordre de passage'!D4) -> 46178 | J3: Important : renseigner les cellules de couleurs grises
B4: Prénom du candidat : | D4: =IF('Ordre de passage'!D13="","",'Ordre de passage'!D13) -> Frederic | J4: Commentaire obligatoire pour les critères que le candidat ne valide pas
B5: Heure de passage : | D5: =IF('Ordre de passage'!B13="","",'Ordre de passage'!B13) -> 15:00 - 16:00
B6: Compétences | D6: Critères | F6: Pts Max. | G6: Note Jury 1 | H6: Commentaires Jury 1 | I6: Note Jury 2 | J6: Commentaires Jury 2 | K6: Note Jury 3 | L6: Commentaires Jury 3
A7: C1 | B7: Mettre en place l’organisation comptable de l’entreprise en déterminant les indicateurs de contrôle (chiffre d’affaires, état de trésorerie, rentabilité, tableaux de bord) afin de piloter la gestion quotidienne comptable. | D7: Cr1. Le candidat démontre une organisation claire et concise. Il choisit des indicateurs cohérents selon son secteur d’activité et son projet professionnel. | F7: 2 | G7: 2 | H7: L'écosystème numérique mis en place (Batappli / QuickBooks TPE) assure une chaîne administrative fluide. Les indicateurs retenus sont précis et directement actionnables. Le workflow dématérialisé est un exemple de bonne organisation pour une TPE gros œuvre. Il conviendrait de préciser comment le candidat gère le suivi simultané de plusieurs chantiers (situations par chantier, retenues de garantie) pour valider la scalabilité du système. | I7: 2 | J7: L'organisation administrative est exemplaire dans sa conception. La synchronisation Batappli/QuickBooks constitue une chaîne de traitement efficace. L'objectif de moins de 2h/semaine d'administratif démontre une maîtrise des outils numériques au service de la productivité. Ce niveau d'organisation est un avantage concurrentiel réel à mettre en avant.
A8: C2 | B8: Etablir un plan financier prévisionnel en calculant les recettes et dépenses de la TPE en lien avec l’activité réelle et souhaitée, en évaluant les éventuels besoins en fonds de roulement afin d’assurer une gestion maîtrisée de la trésorerie. | D8: Cr2. Le candidat fait apparaitre correctement les différents calculs des recettes et dépenses. Il met en avant les besoins en fonds de roulement de son activité. | F8: 2 | G8: 2 | H8: Le prévisionnel est construit avec rigueur. L'hypothèse de taux de présence de 85 % intégrant le risque hivernal démonure une approche mature. La trésorerie nette de +2 800 € en N1 est cependant limitée : un retard d'encaissement de 15 jours sur un chantier majeur pourrait créer une tension. Une analyse du point mort aurait complété utilement la démonstration. | I8: 1.5 | J8: La qualité du prévisionnel financier est remarquable. Le calcul du BFR est rigoureux. La progression de la trésorerie nette de N1 à N3 témoigne d'une montée en puissance maîtrisée. Pour parfaire le dossier, une analyse du seuil de rentabilité mensuel aurait renforcé la démonstration de viabilité dès les premiers mois d'activité.
A9: C3 | B9: Traiter les opérations comptables courantes (factures clients, factures fournisseurs, salaires, charges, frais, éléments banque...), en sécurisant les actions par les différentes tâches de contrôle (rapprochement bancaire...) pour répondre aux obligations de déclarations (TVA...). | D9: Cr3. Le candidat réalise des documents conformes aux législations financières et à la mesure de son activité. | F9: 2 | G9: 2 | H9: Les calculs HT, TVA et TTC sont corrects et la mention de l'autoliquidation est maîtrisée. Cependant, des mentions légales d'identification essentielles sont absentes : numéro SIRET clairement visible, forme juridique et numéro de TVA intracommunautaire. Sans ces éléments, la facture est juridiquement invalide. Ce point de vigilance est d'autant plus important que la facturation aux entreprises générales exige une rigueur documentaire irréprochable. | I9: 2 | J9: La présentation commerciale et la structure de calcul sont de qualité. Il est néanmoins impératif de compléter systématiquement l'en-tête de chaque facture avec l'identité légale complète de l'entreprise. Cette omission est le premier motif de rejet comptable et de retard de paiement : elle doit être corrigée avant la mise en activité, sans exception.
A10: C4 | B10: Appliquer les processus liés aux opérations particulières de gestion en lien avec les clients (impayés, méthodologie de recouvrement...) en respectant les règles législatives afin de gérer, en toute conformité, les évènements de la vie de l’entreprise. | D10: Cr4. Le processus proposé par le candidat est formalisé avec des étapes palliatives permettant d’atteindre le résultat attendu. | F10: 2 | G10: 1.5 | H10: Le processus de recouvrement en quatre étapes est bien graduée et adapté aux pratiques du BTP. L'appel amiable pour vérifier l'absence de litige sur les attachements est une précaution pertinente. La graduation jusqu'au référé commercial est cohérente. L'arrêt des prestations est clairement identifié comme levier de pression ultime. | I10: 2 | J10: La procédure est complète et bien articulée. Le calcul des pénalités légales est correctement intégré. Il conviendrait de préciser que l'efficacité de cette procédure repose sur la qualité des pièces justificatives conservées dès le début du chantier (bons d'attachement signés, PV de réception). Sans ces documents, la procédure est difficile à faire valoir.
A11: C5 | B11: Gérer les stocks et/ ou offres de services afin de piloter et d’optimiser les ressources mobilisables tout en évitant les ruptures de stocks ou les retards de délais de livraison. | D11: Cr5. Le candidat met correctement en avant les différentes rubriques relatives à son activité : type de produits et/ou offres de services, notion de volume, indicateur de disponibilités. Le tableau proposé permet de vérifier le flux d’activité et d’identifier les risques de rupture ou de surcharge. | F11: 2 | G11: 1.5 | H11: Le tableau de gestion des stocks chantier est complet. L'alerte sur les armatures est identifiée avec une commande urgente à déclencher. La gestion en flux tendu du béton est justifiée et économiquement pertinente. L'alerte sur les armatures devait être accompagnée d'un délai d'approvisionnement précis et d'un fournisseur de substitution identifié. | I11: 1.5 | J11: La gestion des stocks de coffrage est rigoureuse. L'externalisation des banches métalliques par location est un choix stratégique pertinent. Il manque cependant une formalisation du processus de réception des matériaux à la livraison, qui conditionne la qualité des ouvrages et la protection de la garantie décennale.
A12: C6 | B12: Superviser et contrôler les risques d’écarts entre le prévisionnel et le réalisé, en s’appuyant sur un outil de suivi des recettes et des dépenses en enregistrant au fil de l’eau les informations liées aux achats et ventes de l’entreprise pour vérifier le respect du prévisionnel envisagé et permettre d’anticiper au plus vite les actions correctives. | D12: Cr6. Le tableau de supervision des opérations courantes permet d’identifier les anomalies dans la gestion et de prévoir les actions correctives de façon anticipée. | F12: 2 | G12: 2 | H12: L'analyse des écarts est précise et démontre un réel sens de la gestion : le gain sur la location de banches compense partiellement la hausse des armatures. Les actions correctives sont concrètes et chiffrées. La démarche est structurée et actionnée avec cohérence. | I12: 2 | J12: Le tableau d'écarts est exploité avec rigueur et les actions correctives sont réalistes. Il manque un indicateur de suivi de l'impact cumulé de ces actions sur la marge brute mensuelle, pour boucler le pilotage de la performance et démontrer l'atteinte des objectifs initiaux.
A13: C7 | B13: Interagir avec les différents acteurs intervenant sur les opérations comptables de l’entreprise, en s’appuyant sur une lecture éclairée des documents comptables (bilans, compte de résultats, tableau budgétaire, plans comptables, plans de trésorerie, déclarations sociales et fiscales...) pour représenter au mieux la TPE et défendre ses intérêts. | D13: Cr7. La présentation du candidat sur lesdits tableaux doit montrer sa compréhension des documents et des mécanismes financiers. Ses commentaires sont pertinents par rapport aux résultats financiers inscrits sur ces documents. Le candidat comprend les incidences des résultats constatés et identifie les progrès à devoir atteindre. | F13: 5 | G13: 4 | H13: Soutenance de très haut niveau combinant maîtrise technique et compréhension approfondie des mécanismes financiers. Le candidat commente ses indicateurs avec précision et anticipe les questions du jury. Pour atteindre l'excellence absolue, la capacité à simuler en direct l'impact d'une variation du CA sur la trésorerie nette renforcerait encore la démonstration. | I13: 4 | J13: Excellente soutenance sur l'ensemble des volets. La lecture des états financiers est fluide et les ratios de rentabilité sont correctement interprétés. Ce niveau de maturité financière est rare pour un profil en reconversion et témoigne d'un investissement personnel notable dans la préparation du projet.
A14: C8 | B14: QCM portant sur les connaissances théoriques de la gestion des opérations comptables courantes d’une TPE. | D14: Cr8. Si le score obtenu est de +70%, les 3 points sont attribués | F14: 3 | G14: 2 | H14: Très bonne performance au QCM. La maîtrise théorique est solide et confirme le niveau général de la soutenance. | I14: 2 | J14: Excellent résultat au QCM. Les connaissances théoriques sont assimilées et restituées avec précision, en cohérence avec la qualité globale du dossier.
A15: TOTAL (note sur 60) | F15: =SUM(F7:F14) -> 20 | G15: =SUM(G7:G14) -> 17 | I15: =SUM(I7:I14) -> 17 | K15: =SUM(K7:K14) -> 0
B16: L’obtention d’une note minimale de 10/20 permet la validation du parcours (attention, la moyenne est calculée pour 3 jurés, à changer si uniquement 2 membres) | F16: =(G15+I15+K15)/2 -> 17
F17: Note finale
B18: Nom et prénom évaluateur
B19: ='Ordre de passage'!F3 -> Tom FOURNAISE | D19: ='Ordre de passage'!G3 -> Djody BENCHADI | F19: ='Ordre de passage'!H3 -> 0
B21: Appréciation générale Jury 1 | D21: Appréciation générale Jury 2 | F21: Appréciation générale Jury 3 | J21: Date et signature des évaluateurs
B22: Soutenance remarquable, portée par 21 ans d'expertise et une préparation visiblement très sérieuse. Le projet est crédible, bien financé et s'appuie sur un écosystème numérique cohérent. La rigueur dans l'analyse des écarts et la maîtrise des spécificités réglementaires BTP sont des atouts majeurs. Le seul point d'amélioration concerne la complétude des mentions légales de facturation, à corriger impérativement. Admis avec mention. | D22: Dossier de très bonne facture, démontrant une compréhension fine des enjeux comptables et financiers. Les outils de gestion sont judicieusement choisis et les tableaux de bord sont opérationnels. Une attention renforcée sur la conformité de la facturation est le seul point à corriger avant la mise en activité. Admis. | J22: =IF('Ordre de passage'!D4="","",'Ordre de passage'!D4) -> 46178

Sheet Feuil1
B1: Référentiel de compétences et de certification
B2: Concevoir et animer une formation avec une pédagogie active
B4: ACTIVITÉS | C4: COMPÉTENCES PROFESSIONNELLES | D4: MODALITÉS D’ÉVALUATION | E4: CRITÈRES D’ÉVALUATION
B5: Activité 1. Conception et préparation d’une formation avec une pédagogie active | G5: N° | H5: Critères
G6: Activité 1 | H6: Conception et préparation d’une formation avec une pédagogie active
B7: Conception d’une action de formation | C7: A1C1. Recueillir les informations nécessaires à la préparation optimale de l’action de formation pour répondre au mieux aux besoins du client et à ses attentes en termes de retours sur investissement. | E7: A1Cr1. La démarche proposée de recueil des besoins de formation permet d’obtenir des informations suffisantes à l’élaboration d’une action adaptée au besoin du commanditaire. | G7: A1Cr1 | H7: La démarche proposée de recueil des besoins de formation permet d’obtenir des informations suffisantes à l’élaboration d’une action adaptée au besoin du commanditaire. | I7: A1Cr1. Points 3
